Workbook

Sheet MAD
A1: Exp | B1: Site | C1: Hole | D1: Core | E1: Type | F1: Section | G1: Sample Top, cm | H1: Sample Bottom, cm | I1: Combined id | J1: Sample Label | K1: Sample Top Depth, mbsf | L1: Sample Bot Depth, mbsf | M1: Beaker Number | N1: Beaker Weight, g | O1: WET Weight (Sample + Beaker), g | P1: OVEN Date/Time IN | Q1: DRY Weight (Sample + Beaker), g | R1: Scientist | S1: Pycnometer Cell | T1: DRY Volume, cc | V1: WEIGHT WET Sample, g | W1: WEIGHT DRY Sample, g | X1: WEIGHT Pore Water, g | Y1: WEIGHT Salt, g | Z1: WEIGHT Grains, g | AA1: VOLUME Pore Water, cc | AB1: VOLUME Salt, cc | AC1: VOLUME Dry Sample, cc | AD1: VOLUME Wet Sample, cc | AE1: VOLUME Grains, cc | AF1: Water Content, (wet) v/v | AG1: Water Content (dry), v/v | AH1: Bulk Density, g/cc | AI1: Dry Density, g/cc | AJ1: Grain Density, g/cc | AK1: Porosity, v/v | AL1: Void Ratio, v/v | AM1: Lithology
A2: 501 | B2: M0112 | C2: B | D2: 2 | E2: H | F2: 1 | G2: 38 | H2: 40 | I2: =_xlfn.CONCAT(B2, "-", C2,"-", D2,"-", F2) -> M0112-B-2-1 | J2: =_xlfn.CONCAT(A2, "-", I2, ",",G2, "-",H2) -> 501-M0112-B-2-1,38-40 | K2: =VLOOKUP(I2, 'Depth vlookup'!$G$2:$I$997,2,FALSE)+(G2/100) -> 28.6 | L2: =K2+2/100 -> 28.62 | M2: 230 | N2: =VLOOKUP(M2, Beakers!$A$2:$B$151, 2, 0) -> 9.805 | O2: 18.9761 | P2: 46052.906 | Q2: 17.3141 | R2: TS | S2: 5 | T2: 7.2118 | V2: =O2-N2 -> 9.1711 | W2: =Q2-N2 -> 7.5091 | X2: =(V2-W2)/(1-35/1000) -> 1.7222798 | Y2: =X2-(V2-W2) -> 0.060279793 | Z2: =W2-Y2 -> 7.4488202 | AA2: =X2/1.024 -> 1.6819139 | AB2: =Y2/2.22 -> 0.02715306 | AC2: =T2-VLOOKUP(M2, Beakers!$A$2:$C$151, 3, 0) -> 2.814939 | AD2: =AC2-AB2+AA2 -> 4.4696998 | AE2: =AC2-AB2 -> 2.787786 | AF2: =X2/V2 -> 0.18779424 | AG2: =X2/Z2 -> 0.23121511 | AH2: =V2/AD2 -> 2.051838 | AI2: =Z2/AD2 -> 1.6665146 | AJ2: =Z2/AE2 -> 2.6719484 | AK2: =AA2/AD2 -> 0.37629235 | AL2: =AA2/AE2 -> 0.60331528 | AM2: sand | AN2: 3 runs
A3: 501 | B3: M0112 | C3: B | D3: 3 | E3: H | F3: 1 | G3: 68 | H3: 70 | I3: =_xlfn.CONCAT(B3, "-", C3,"-", D3,"-", F3) -> M0112-B-3-1 | J3: =_xlfn.CONCAT(A3, "-", I3, ",",G3, "-",H3) -> 501-M0112-B-3-1,68-70 | K3: =VLOOKUP(I3, 'Depth vlookup'!$G$2:$I$997,2,FALSE)+(G3/100) -> 31.07 | L3: =K3+2/100 -> 31.09 | M3: 231 | N3: =VLOOKUP(M3, Beakers!$A$2:$B$151, 2, 0) -> 9.8868 | O3: 20.0022 | P3: 46052.906 | Q3: 18.4698 | R3: TS | S3: 3 | T3: 7.709 | V3: =O3-N3 -> 10.1154 | W3: =Q3-N3 -> 8.583 | X3: =(V3-W3)/(1-35/1000) -> 1.5879793 | Y3: =X3-(V3-W3) -> 0.055579275 | Z3: =W3-Y3 -> 8.5274207 | AA3: =X3/1.024 -> 1.550761 | AB3: =Y3/2.22 -> 0.025035709 | AC3: =T3-VLOOKUP(M3, Beakers!$A$2:$C$151, 3, 0) -> 3.2754574 | AD3: =AC3-AB3+AA3 -> 4.8011827 | AE3: =AC3-AB3 -> 3.2504217 | AF3: =X3/V3 -> 0.15698631 | AG3: =X3/Z3 -> 0.18622035 | AH3: =V3/AD3 -> 2.1068559 | AI3: =Z3/AD3 -> 1.7761084 | AJ3: =Z3/AE3 -> 2.6234814 | AK3: =AA3/AD3 -> 0.32299563 | AL3: =AA3/AE3 -> 0.47709533 | AM3: sand | AN3: 3 runs
A4: 501 | B4: M0112 | C4: B | D4: 5 | E4: H | F4: 1 | G4: 38 | H4: 40 | I4: =_xlfn.CONCAT(B4, "-", C4,"-", D4,"-", F4) -> M0112-B-5-1 | J4: =_xlfn.CONCAT(A4, "-", I4, ",",G4, "-",H4) -> 501-M0112-B-5-1,38-40 | K4: =VLOOKUP(I4, 'Depth vlookup'!$G$2:$I$997,2,FALSE)+(G4/100) -> 54.38 | L4: =K4+2/100 -> 54.4 | M4: 232 | N4: =VLOOKUP(M4, Beakers!$A$2:$B$151, 2, 0) -> 9.8775 | O4: 21.4373 | P4: 46052.906 | Q4: 19.7025 | R4: TS | S4: 5 | T4: 8.0928 | V4: =O4-N4 -> 11.5598 | W4: =Q4-N4 -> 9.825 | X4: =(V4-W4)/(1-35/1000) -> 1.7977202 | Y4: =X4-(V4-W4) -> 0.062920207 | Z4: =W4-Y4 -> 9.7620798 | AA4: =X4/1.024 -> 1.7555861 | AB4: =Y4/2.22 -> 0.028342436 | AC4: =T4-VLOOKUP(M4, Beakers!$A$2:$C$151, 3, 0) -> 3.6634278 | AD4: =AC4-AB4+AA4 -> 5.3906715 | AE4: =AC4-AB4 -> 3.6350854 | AF4: =X4/V4 -> 0.15551482 | AG4: =X4/Z4 -> 0.1841534 | AH4: =V4/AD4 -> 2.1444082 | AI4: =Z4/AD4 -> 1.8109209 | AJ4: =Z4/AE4 -> 2.685516 | AK4: =AA4/AD4 -> 0.32567114 | AL4: =AA4/AE4 -> 0.48295596 | AM4: sand | AN4: 3 runs
A5: 501 | B5: M0112 | C5: B | D5: 6 | E5: H | F5: 1 | G5: 38 | H5: 40 | I5: =_xlfn.CONCAT(B5, "-", C5,"-", D5,"-", F5) -> M0112-B-6-1 | J5: =_xlfn.CONCAT(A5, "-", I5, ",",G5, "-",H5) -> 501-M0112-B-6-1,38-40 | K5: =VLOOKUP(I5, 'Depth vlookup'!$G$2:$I$997,2,FALSE)+(G5/100) -> 55.9 | L5: =K5+2/100 -> 55.92 | M5: 233 | N5: =VLOOKUP(M5, Beakers!$A$2:$B$151, 2, 0) -> 9.9605 | O5: 18.1446 | P5: 46052.906 | Q5: 16.718 | R5: TS | S5: 1 | T5: 7.0529 | V5: =O5-N5 -> 8.1841 | W5: =Q5-N5 -> 6.7575 | X5: =(V5-W5)/(1-35/1000) -> 1.478342 | Y5: =X5-(V5-W5) -> 0.051741969 | Z5: =W5-Y5 -> 6.705758 | AA5: =X5/1.024 -> 1.4436933 | AB5: =Y5/2.22 -> 0.023307193 | AC5: =T5-VLOOKUP(M5, Beakers!$A$2:$C$151, 3, 0) -> 2.5863081 | AD5: =AC5-AB5+AA5 -> 4.0066942 | AE5: =AC5-AB5 -> 2.5630009 | AF5: =X5/V5 -> 0.18063586 | AG5: =X5/Z5 -> 0.22045859 | AH5: =V5/AD5 -> 2.0426066 | AI5: =Z5/AD5 -> 1.6736386 | AJ5: =Z5/AE5 -> 2.6163698 | AK5: =AA5/AD5 -> 0.36032032 | AL5: =AA5/AE5 -> 0.56328242 | AM5: sand | AN5: 3 runs
A6: 501 | B6: M0112 | C6: B | D6: 7 | E6: R | F6: 1 | G6: 39.5 | H6: 41.5 | I6: =_xlfn.CONCAT(B6, "-", C6,"-", D6,"-", F6) -> M0112-B-7-1 | J6: =_xlfn.CONCAT(A6, "-", I6, ",",G6, "-",H6) -> 501-M0112-B-7-1,39.5-41.5 | K6: =VLOOKUP(I6, 'Depth vlookup'!$G$2:$I$997,2,FALSE)+(G6/100) -> 57.215 | L6: =K6+2/100 -> 57.235 | M6: 234 | N6: =VLOOKUP(M6, Beakers!$A$2:$B$151, 2, 0) -> 10.0063 | O6: 21.9702 | P6: 46053.382 | Q6: 19.5789 | R6: TS | S6: 5 | T6: 8.0014 | V6: =O6-N6 -> 11.9639 | W6: =Q6-N6 -> 9.5726 | X6: =(V6-W6)/(1-35/1000) -> 2.4780311 | Y6: =X6-(V6-W6) -> 0.086731088 | Z6: =W6-Y6 -> 9.4858689 | AA6: =X6/1.024 -> 2.4199522 | AB6: =Y6/2.22 -> 0.039068058 | AC6: =T6-VLOOKUP(M6, Beakers!$A$2:$C$151, 3, 0) -> 3.51427 | AD6: =AC6-AB6+AA6 -> 5.8951541 | AE6: =AC6-AB6 -> 3.4752019 | AF6: =X6/V6 -> 0.20712569 | AG6: =X6/Z6 -> 0.26123396 | AH6: =V6/AD6 -> 2.0294465 | AI6: =Z6/AD6 -> 1.609096 | AJ6: =Z6/AE6 -> 2.7295879 | AK6: =AA6/AD6 -> 0.41049855 | AL6: =AA6/AE6 -> 0.69634867 | AM6: clay | AN6: 3 runs
A7: 501 | B7: M0112 | C7: B | D7: 8 | E7: R | F7: 1 | G7: 28 | H7: 30 | I7: =_xlfn.CONCAT(B7, "-", C7,"-", D7,"-", F7) -> M0112-B-8-1 | J7: =_xlfn.CONCAT(A7, "-", I7, ",",G7, "-",H7) -> 501-M0112-B-8-1,28-30 | K7: =VLOOKUP(I7, 'Depth vlookup'!$G$2:$I$997,2,FALSE)+(G7/100) -> 58.6 | L7: =K7+2/100 -> 58.62 | M7: 235 | N7: =VLOOKUP(M7, Beakers!$A$2:$B$151, 2, 0) -> 9.9943 | O7: 22.2731 | P7: 46053.382 | Q7: 20.1433 | R7: TS | S7: 1 | T7: 8.286 | V7: =O7-N7 -> 12.2788 | W7: =Q7-N7 -> 10.149 | X7: =(V7-W7)/(1-35/1000) -> 2.2070466 | Y7: =X7-(V7-W7) -> 0.077246632 | Z7: =W7-Y7 -> 10.071753 | AA7: =X7/1.024 -> 2.155319 | AB7: =Y7/2.22 -> 0.03479578 | AC7: =T7-VLOOKUP(M7, Beakers!$A$2:$C$151, 3, 0) -> 3.8042511 | AD7: =AC7-AB7+AA7 -> 5.9247743 | AE7: =AC7-AB7 -> 3.7694553 | AF7: =X7/V7 -> 0.17974449 | AG7: =X7/Z7 -> 0.21913232 | AH7: =V7/AD7 -> 2.0724502 | AI7: =Z7/AD7 -> 1.6999387 | AJ7: =Z7/AE7 -> 2.6719386 | AK7: =AA7/AD7 -> 0.36378077 | AL7: =AA7/AE7 -> 0.57178525 | AM7: clay | AN7: 3 runs
A8: 501 | B8: M0112 | C8: B | D8: 9 | E8: R | F8: 1 | G8: 34 | H8: 36 | I8: =_xlfn.CONCAT(B8, "-", C8,"-", D8,"-", F8) -> M0112-B-9-1 | J8: =_xlfn.CONCAT(A8, "-", I8, ",",G8, "-",H8) -> 501-M0112-B-9-1,34-36 | K8: =VLOOKUP(I8, 'Depth vlookup'!$G$2:$I$997,2,FALSE)+(G8/100) -> 60.16 | L8: =K8+2/100 -> 60.18 | M8: 236 | N8: =VLOOKUP(M8, Beakers!$A$2:$B$151, 2, 0) -> 9.8712 | O8: 20.9235 | P8: 46053.382 | Q8: 18.5158 | R8: TS | S8: 2 | T8: 7.6277 | V8: =O8-N8 -> 11.0523 | W8: =Q8-N8 -> 8.6446 | X8: =(V8-W8)/(1-35/1000) -> 2.4950259 | Y8: =X8-(V8-W8) -> 0.087325907 | Z8: =W8-Y8 -> 8.5572741 | AA8: =X8/1.024 -> 2.4365487 | AB8: =Y8/2.22 -> 0.039335994 | AC8: =T8-VLOOKUP(M8, Beakers!$A$2:$C$151, 3, 0) -> 3.2011529 | AD8: =AC8-AB8+AA8 -> 5.5983657 | AE8: =AC8-AB8 -> 3.1618169 | AF8: =X8/V8 -> 0.22574721 | AG8: =X8/Z8 -> 0.29156784 | AH8: =V8/AD8 -> 1.9742012 | AI8: =Z8/AD8 -> 1.5285308 | AJ8: =Z8/AE8 -> 2.706442 | AK8: =AA8/AD8 -> 0.43522501 | AL8: =AA8/AE8 -> 0.77061664 | AM8: clay | AN8: 3 runs
A9: 501 | B9: M0112 | C9: B | D9: 10 | E9: R | F9: 1 | G9: 39 | H9: 41 | I9: =_xlfn.CONCAT(B9, "-", C9,"-", D9,"-", F9) -> M0112-B-10-1 | J9: =_xlfn.CONCAT(A9, "-", I9, ",",G9, "-",H9) -> 501-M0112-B-10-1,39-41 | K9: =VLOOKUP(I9, 'Depth vlookup'!$G$2:$I$997,2,FALSE)+(G9/100) -> 61.71 | L9: =K9+2/100 -> 61.73 | M9: 237 | N9: =VLOOKUP(M9, Beakers!$A$2:$B$151, 2, 0) -> 9.8347 | O9: 23.0324 | P9: 46053.58 | Q9: 19.0514 | R9: TS | S9: 1 | T9: 7.8554 | V9: =O9-N9 -> 13.1977 | W9: =Q9-N9 -> 9.2167 | X9: =(V9-W9)/(1-35/1000) -> 4.1253886 | Y9: =X9-(V9-W9) -> 0.1443886 | Z9: =W9-Y9 -> 9.0723114 | AA9: =X9/1.024 -> 4.0286998 | AB9: =Y9/2.22 -> 0.06503991 | AC9: =T9-VLOOKUP(M9, Beakers!$A$2:$C$151, 3, 0) -> 3.4452206 | AD9: =AC9-AB9+AA9 -> 7.4088805 | AE9: =AC9-AB9 -> 3.3801807 | AF9: =X9/V9 -> 0.3125839 | AG9: =X9/Z9 -> 0.45472299 | AH9: =V9/AD9 -> 1.7813352 | AI9: =Z9/AD9 -> 1.2245185 | AJ9: =Z9/AE9 -> 2.6839723 | AK9: =AA9/AD9 -> 0.54376633 | AL9: =AA9/AE9 -> 1.1918593 | AM9: clay | AN9: 3 runs
A10: 501 | B10: M0112 | C10: B | D10: 12 | E10: R | F10: 1 | G10: 36 | H10: 38 | I10: =_xlfn.CONCAT(B10, "-", C10,"-", D10,"-", F10) -> M0112-B-12-1 | J10: =_xlfn.CONCAT(A10, "-", I10, ",",G10, "-",H10) -> 501-M0112-B-12-1,36-38 | K10: =VLOOKUP(I10, 'Depth vlookup'!$G$2:$I$997,2,FALSE)+(G10/100) -> 82.36 | L10: =K10+2/100 -> 82.38 | M10: 238 | N10: =VLOOKUP(M10, Beakers!$A$2:$B$151, 2, 0) -> 9.924 | O10: 20.532 | P10: 46053.58 | Q10: 17.0359 | R10: TS | S10: 2 | T10: 7.0567 | V10: =O10-N10 -> 10.608 | W10: =Q10-N10 -> 7.1119 | X10: =(V10-W10)/(1-35/1000) -> 3.6229016 | Y10: =X10-(V10-W10) -> 0.12680155 | Z10: =W10-Y10 -> 6.9850984 | AA10: =X10/1.024 -> 3.5379898 | AB10: =Y10/2.22 -> 0.057117817 | AC10: =T10-VLOOKUP(M10, Beakers!$A$2:$C$151, 3, 0) -> 2.6064758 | AD10: =AC10-AB10+AA10 -> 6.0873478 | AE10: =AC10-AB10 -> 2.549358 | AF10: =X10/V10 -> 0.34152541 | AG10: =X10/Z10 -> 0.51866149 | AH10: =V10/AD10 -> 1.7426308 | AI10: =Z10/AD10 -> 1.1474781 | AJ10: =Z10/AE10 -> 2.7399441 | AK10: =AA10/AD10 -> 0.58120382 | AL10: =AA10/AE10 -> 1.3877964 | AM10: clay | AN10: 3 runs
A11: 501 | B11: M0112 | C11: B | D11: 13 | E11: R | F11: 1 | G11: 38 | H11: 40 | I11: =_xlfn.CONCAT(B11, "-", C11,"-", D11,"-", F11) -> M0112-B-13-1 | J11: =_xlfn.CONCAT(A11, "-", I11, ",",G11, "-",H11) -> 501-M0112-B-13-1,38-40 | K11: =VLOOKUP(I11, 'Depth vlookup'!$G$2:$I$997,2,FALSE)+(G11/100) -> 83.88 | L11: =K11+2/100 -> 83.9 | M11: 239 | N11: =VLOOKUP(M11, Beakers!$A$2:$B$151, 2, 0) -> 10.0279 | O11: 21.6257 | P11: 46053.58 | Q11: 18.1127 | R11: TS | S11: 3 | T11: 7.4793 | V11: =O11-N11 -> 11.5978 | W11: =Q11-N11 -> 8.0848 | X11: =(V11-W11)/(1-35/1000) -> 3.6404145 | Y11: =X11-(V11-W11) -> 0.12741451 | Z11: =W11-Y11 -> 7.9573855 | AA11: =X11/1.024 -> 3.5550923 | AB11: =Y11/2.22 -> 0.057393922 | AC11: =T11-VLOOKUP(M11, Beakers!$A$2:$C$151, 3, 0) -> 2.9824839 | AD11: =AC11-AB11+AA11 -> 6.4801822 | AE11: =AC11-AB11 -> 2.9250899 | AF11: =X11/V11 -> 0.31388837 | AG11: =X11/Z11 -> 0.45748877 | AH11: =V11/AD11 -> 1.7897336 | AI11: =Z11/AD11 -> 1.2279571 | AJ11: =Z11/AE11 -> 2.72039 | AK11: =AA11/AD11 -> 0.54860993 | AL11: =AA11/AE11 -> 1.2153788 | AM11: clay | AN11: 3 runs
A12: 501 | B12: M0112 | C12: B | D12: 14 | E12: R | F12: 1 | G12: 66 | H12: 68 | I12: =_xlfn.CONCAT(B12, "-", C12,"-", D12,"-", F12) -> M0112-B-14-1 | J12: =_xlfn.CONCAT(A12, "-", I12, ",",G12, "-",H12) -> 501-M0112-B-14-1,66-68 | K12: =VLOOKUP(I12, 'Depth vlookup'!$G$2:$I$997,2,FALSE)+(G12/100) -> 87.16 | L12: =K12+2/100 -> 87.18 | M12: 171 | N12: =VLOOKUP(M12, Beakers!$A$2:$B$151, 2, 0) -> 9.4852 | O12: 20.0489 | P12: 46053.58 | Q12: 16.9553 | R12: TS | S12: 2 | T12: 7.0012 | V12: =O12-N12 -> 10.5637 | W12: =Q12-N12 -> 7.4701 | X12: =(V12-W12)/(1-35/1000) -> 3.2058031 | Y12: =X12-(V12-W12) -> 0.11220311 | Z12: =W12-Y12 -> 7.3578969 | AA12: =X12/1.024 -> 3.1306671 | AB12: =Y12/2.22 -> 0.050541941 | AC12: =T12-VLOOKUP(M12, Beakers!$A$2:$C$151, 3, 0) -> 2.7477471 | AD12: =AC12-AB12+AA12 -> 5.8278722 | AE12: =AC12-AB12 -> 2.6972051 | AF12: =X12/V12 -> 0.30347351 | AG12: =X12/Z12 -> 0.43569557 | AH12: =V12/AD12 -> 1.8126169 | AI12: =Z12/AD12 -> 1.2625357 | AJ12: =Z12/AE12 -> 2.7279708 | AK12: =AA12/AD12 -> 0.5371887 | AL12: =AA12/AE12 -> 1.1607078 | AM12: clay | AN12: 3 runs
A13: 501 | B13: M0112 | C13: B | D13: 15 | E13: R | F13: 1 | G13: 42 | H13: 44 | I13: =_xlfn.CONCAT(B13, "-", C13,"-", D13,"-", F13) -> M0112-B-15-1 | J13: =_xlfn.CONCAT(A13, "-", I13, ",",G13, "-",H13) -> 501-M0112-B-15-1,42-44 | K13: =VLOOKUP(I13, 'Depth vlookup'!$G$2:$I$997,2,FALSE)+(G13/100) -> 89.92 | L13: =K13+2/100 -> 89.94 | M13: 172 | N13: =VLOOKUP(M13, Beakers!$A$2:$B$151, 2, 0) -> 9.5744 | O13: 19.12 | P13: 46053.58 | Q13: 16.0782 | R13: TS | S13: 3 | T13: 6.7348 | V13: =O13-N13 -> 9.5456 | W13: =Q13-N13 -> 6.5038 | X13: =(V13-W13)/(1-35/1000) -> 3.1521244 | Y13: =X13-(V13-W13) -> 0.11032435 | Z13: =W13-Y13 -> 6.3934756 | AA13: =X13/1.024 -> 3.0782464 | AB13: =Y13/2.22 -> 0.049695654 | AC13: =T13-VLOOKUP(M13, Beakers!$A$2:$C$151, 3, 0) -> 2.4413471 | AD13: =AC13-AB13+AA13 -> 5.4698979 | AE13: =AC13-AB13 -> 2.3916514 | AF13: =X13/V13 -> 0.33021752 | AG13: =X13/Z13 -> 0.49302203 | AH13: =V13/AD13 -> 1.7451149 | AI13: =Z13/AD13 -> 1.1688474 | AJ13: =Z13/AE13 -> 2.6732473 | AK13: =AA13/AD13 -> 0.56276123 | AL13: =AA13/AE13 -> 1.2870799 | AM13: clay | AN13: 3 runs
... A51: 501 | B51: M0112 | C51: B | D51: 65 | E51: R | F51: 1 | G51: 38 | H51: 40 | I51: =_xlfn.CONCAT(B51, "-", C51,"-", D51,"-", F51) -> M0112-B-65-1 | J51: =_xlfn.CONCAT(A51, "-", I51, ",",G51, "-",H51) -> 501-M0112-B-65-1,38-40 | K51: =VLOOKUP(I51, 'Depth vlookup'!$G$2:$I$997,2,FALSE)+(G51/100) -> 337.2 | L51: =K51+2/100 -> 337.22 | M51: 200 | N51: =VLOOKUP(M51, Beakers!$A$2:$B$151, 2, 0) -> 9.6303 | O51: 20.3312 | P51: 46055.773 | Q51: 18.5485 | R51: MS | S51: 3 | T51: 7.7501 | V51: =O51-N51 -> 10.7009 | W51: =Q51-N51 -> 8.9182 | X51: =(V51-W51)/(1-35/1000) -> 1.8473575 | Y51: =X51-(V51-W51) -> 0.064657513 | Z51: =W51-Y51 -> 8.8535425 | AA51: =X51/1.024 -> 1.8040601 | AB51: =Y51/2.22 -> 0.029125006 | AC51: =T51-VLOOKUP(M51, Beakers!$A$2:$C$151, 3, 0) -> 3.4315798 | AD51: =AC51-AB51+AA51 -> 5.2065149 | AE51: =AC51-AB51 -> 3.4024548 | AF51: =X51/V51 -> 0.17263571 | AG51: =X51/Z51 -> 0.20865744 | AH51: =V51/AD51 -> 2.0552904 | AI51: =Z51/AD51 -> 1.7004739 | AJ51: =Z51/AE51 -> 2.6021044 | AK51: =AA51/AD51 -> 0.34650051 | AL51: =AA51/AE51 -> 0.53022308 | AM51: sand | AN51: 3 runs

Sheet STD
A1: Run Number | B1: Pyc Cell | C1: Volume of Std | D1: Offset | E1: date and time | G1: Comments | H1: Volume of Std | I1: 9.2149
A2: 1 | B2: 5 | C2: 9.2015 | D2: =$I$1-C2 -> 0.0134 | E2: 17.01.2026 | F2: 0.64236111
A3: 2 | B3: 1 | C3: 9.2176 | D3: =$I$1-C3 -> -0.0027 | E3: 17.01.2026 | F3: 0.76041667
A4: 3 | B4: 2 | C4: 9.2133 | D4: =$I$1-C4 -> 0.0016 | E4: 17.01.2026 | F4: 0.875
A5: 4 | B5: 3 | C5: 9.2299 | D5: =$I$1-C5 -> -0.015 | E5: 19.01.2026 | F5: 0.37847222
A6: 5 | B6: 4 | C6: 9.1656 | D6: =$I$1-C6 -> 0.0493 | E6: 19.01.2025 | F6: 0.44236111
A7: Calibration Cell | B7: 4 | C7: 9.2059 | D7: =$I$1-C7 -> 0.009 | E7: 19.01.2026 | F7: 0.50972222 | G7: Cell 4 was recalibrated
A8: 6 | B8: 4 | C8: 9.1879 | D8: =$I$1-C8 -> 0.027 | E8: 19.01.2026 | F8: 0.5875
A9: Calibration Cell | B9: 4 | C9: Unstable Pressure | G9: Cell 4 not to be used - use 3 samples and 1 std
A10: Recalibration of all cells | C10: From 19:17 on 19.01 - the threshold for standard and recalibration is >0.04 | K10: 19.01 | L10: Recalibration of Cells
A11: 7 | B11: 5 | C11: 9.2127 | D11: =$I$1-C11 -> 0.0022 | E11: 19.01.2026 | F11: 0.85138889 | K11: Cell 1 | L11: 9.1835 | M11: =$I$1-L11 -> 0.0314
A12: 8 | B12: 1 | C12: 9.1865 | D12: =$I$1-C12 -> 0.0284 | E12: 20.01.2026 | F12: 0.33888889 | K12: Cell 2 | L12: 9.2368 | M12: =$I$1-L12 -> -0.0219
A13: Calibration Cell | B13: 1 | C13: 9.2188 | D13: =$I$1-C13 -> -0.0039 | E13: 20.01.2026 | F13: 0.40277778 | G13: Cell 1 was recalibrated | K13: Cell 3 | L13: 9.2228 | M13: =$I$1-L13 -> -0.0079
A14: 9 | B14: 1 | C14: 9.2164 | D14: =$I$1-C14 -> -0.0015 | E14: 20.01.2026 | F14: 0.46805556 | K14: Cell 5 | L14: 9.2215 | M14: =$I$1-L14 -> -0.0066
A15: Calibration Cell | B15: 4 | C15: 9.2189 | D15: =$I$1-C15 -> -0.004 | E15: 20.01.2026 | F15: 0.52083333 | G15: Calibration after Stefan repaired Cell 4 (maybe gasket),
A16: 10 | B16: 2 | C16: 9.2397 | D16: =$I$1-C16 -> -0.0248 | E16: 20.01.2026 | F16: 0.53263889 | K16: 20.01 | L16: Cell1 check
A17: Calibration Cell | B17: 2 | C17: 9.2111 | D17: =$I$1-C17 -> 0.0038 | E17: 20.01.2026 | F17: 0.59027778 | G17: Cell 1 was recalibrated | K17: Cell 1 | L17: 9.2189 | M17: =$I$1-L17 -> -0.004
A18: 11 | B18: 3 | C18: 9.2187 | D18: =$I$1-C18 -> -0.0038 | E18: 20.01.2026 | F18: 0.65208333 | L18: 9.2224 | M18: =$I$1-L18 -> -0.0075
A19: 12 | B19: 5 | C19: 9.2231 | D19: =$I$1-C19 -> -0.0082 | E19: 20.01.2026 | F19: 0.70138889 | L19: 9.2199 | M19: =$I$1-L19 -> -0.005
A20: 13 | B20: 1 | C20: 9.2205 | D20: =$I$1-C20 -> -0.0056 | E20: 20.01.2026 | F20: 0.74930556 | L20: 9.2179 | M20: =$I$1-L20 -> -0.003
A21: 14 | B21: 2 | C21: 9.2141 | D21: =$I$1-C21 -> 0.0008 | E21: 20.01.2026 | F21: 0.79027778 | L21: 9.2187 | M21: =$I$1-L21 -> -0.0038
A22: 15 | B22: 3 | C22: 9.1812 | D22: =$I$1-C22 -> 0.0337 | E22: 20.01.2026 | F22: 0.83333333 | L22: Cell4 check
A23: 16 | B23: 5 | C23: 9.2207 | D23: =$I$1-C23 -> -0.0058 | E23: 20.01.2026 | F23: 0.875 | K23: Cell4 | L23: 9.2225 | M23: =$I$1-L23 -> -0.0076
A24: 17 | B24: 1 | C24: 9.2045 | D24: =$I$1-C24 -> 0.0104 | E24: 21.01.2027 | F24: 0.35902778 | L24: 9.2213 | M24: =$I$1-L24 -> -0.0064
A25: 18 | B25: 2 | C25: 9.2031 | D25: =$I$1-C25 -> 0.0118 | E25: 21.01.2027 | F25: 0.40208333 | L25: 9.2135 | M25: =$I$1-L25 -> 0.0014
A26: 19 | B26: 3 | C26: 9.2131 | D26: =$I$1-C26 -> 0.0018 | E26: 21.01.2027 | F26: 0.48472222 | L26: 9.2189 | M26: =$I$1-L26 -> -0.004
A27: 20 | B27: 5 | C27: 9.215 | D27: =$I$1-C27 -> -0.0001 | E27: 21.01.2027 | F27: 0.63333333 | L27: 9.2243 | M27: =$I$1-L27 -> -0.0094
A28: 21 | B28: 1 | C28: 9.2215 | D28: =$I$1-C28 -> -0.0066 | E28: 21.01.2027 | F28: 0.71527778
A29: 22 | B29: 2 | C29: 9.2305 | D29: =$I$1-C29 -> -0.0156 | E29: 21.01.2027 | F29: 0.75763889 | K29: 27.01 | L29: Cell2 check
A30: 23 | B30: 3 | C30: 9.2051 | D30: =$I$1-C30 -> 0.0098 | E30: 21.01.2027 | F30: 0.79583333 | K30: Cell 2 | L30: 9.2134 | M30: =$I$1-L30 -> 0.0015
A31: 24 | B31: 5 | C31: 9.2266 | D31: =$I$1-C31 -> -0.0117 | E31: 21.01.2027 | F31: 0.85833333 | L31: 9.2197 | M31: =$I$1-L31 -> -0.0048
A32: 25 | B32: 1 | C32: 9.2237 | D32: =$I$1-C32 -> -0.0088 | E32: 22.01.2026 | F32: 0.35555556 | L32: 9.2051 | M32: =$I$1-L32 -> 0.0098
A33: 26 | B33: 2 | C33: 9.2153 | D33: =$I$1-C33 -> -0.0004 | E33: 22.01.2026 | F33: 0.51180556 | L33: 9.2089 | M33: =$I$1-L33 -> 0.006
A34: 27 | B34: 3 | C34: 9.226 | D34: =$I$1-C34 -> -0.0111 | E34: 22.01.2026 | F34: 0.65347222 | L34: 9.2163 | M34: =$I$1-L34 -> -0.0014
A35: 28 | B35: 5 | C35: 9.2235 | D35: =$I$1-C35 -> -0.0086 | E35: 22.01.2026 | F35: 0.75763889
A36: 29 | B36: 1 | C36: 9.2304 | D36: =$I$1-C36 -> -0.0155 | E36: 22.01.2026 | F36: 0.80902778
A37: 30 | B37: 2 | C37: 9.1928 | D37: =$I$1-C37 -> 0.0221 | E37: 22.01.2026 | F37: 0.86805556
A38: 31 | B38: 3 | C38: 9.2201 | D38: =$I$1-C38 -> -0.0052 | E38: 22.01.2026 | F38: 0.90694444
A39: 32 | B39: 5 | C39: 9.2217 | D39: =$I$1-C39 -> -0.0068 | E39: 23.01.2026 | F39: 0.36041667
A40: 33 | B40: 1 | C40: 9.2265 | D40: =$I$1-C40 -> -0.0116 | E40: 23.01.2026 | F40: 0.48194444
...

Sheet Depth vlookup
A1: Expedition | B1: Site | C1: Hole | D1: Core | E1: Type | F1: Section | G1: Combined | H1: top_depth | I1: bottom_depth
A2: 501 | B2: M0111 | C2: A | D2: 1 | E2: H | F2: 1 | G2: =CONCATENATE(B2, "-",C2, "-", D2, "-", F2) -> M0111-A-1-1 | H2: 0 | I2: 1.5
A3: 501 | B3: M0111 | C3: A | D3: 1 | E3: H | F3: 2 | G3: =CONCATENATE(B3, "-",C3, "-", D3, "-", F3) -> M0111-A-1-2 | H3: 1.5 | I3: 2.9
A4: 501 | B4: M0111 | C4: A | D4: 2 | E4: H | F4: 1 | G4: =CONCATENATE(B4, "-",C4, "-", D4, "-", F4) -> M0111-A-2-1 | H4: 2.4 | I4: 3.91
A5: 501 | B5: M0111 | C5: A | D5: 2 | E5: H | F5: 2 | G5: =CONCATENATE(B5, "-",C5, "-", D5, "-", F5) -> M0111-A-2-2 | H5: 3.91 | I5: 4.99
A6: 501 | B6: M0111 | C6: A | D6: 3 | E6: H | F6: 1 | G6: =CONCATENATE(B6, "-",C6, "-", D6, "-", F6) -> M0111-A-3-1 | H6: 4.46 | I6: 5.97
A7: 501 | B7: M0111 | C7: A | D7: 3 | E7: H | F7: 2 | G7: =CONCATENATE(B7, "-",C7, "-", D7, "-", F7) -> M0111-A-3-2 | H7: 5.97 | I7: 7.1
A8: 501 | B8: M0111 | C8: A | D8: 4 | E8: H | F8: 1 | G8: =CONCATENATE(B8, "-",C8, "-", D8, "-", F8) -> M0111-A-4-1 | H8: 6.89 | I8: 8.4
A9: 501 | B9: M0111 | C9: A | D9: 4 | E9: H | F9: 2 | G9: =CONCATENATE(B9, "-",C9, "-", D9, "-", F9) -> M0111-A-4-2 | H9: 8.4 | I9: 9.6
A10: 501 | B10: M0111 | C10: A | D10: 5 | E10: H | F10: 1 | G10: =CONCATENATE(B10, "-",C10, "-", D10, "-", F10) -> M0111-A-5-1 | H10: 9.6 | I10: 11.1
A11: 501 | B11: M0111 | C11: A | D11: 5 | E11: H | F11: 2 | G11: =CONCATENATE(B11, "-",C11, "-", D11, "-", F11) -> M0111-A-5-2 | H11: 11.1 | I11: 12.05
A12: 501 | B12: M0111 | C12: A | D12: 6 | E12: H | F12: 1 | G12: =CONCATENATE(B12, "-",C12, "-", D12, "-", F12) -> M0111-A-6-1 | H12: 11.7 | I12: 13.2
A13: 501 | B13: M0111 | C13: A | D13: 6 | E13: H | F13: 2 | G13: =CONCATENATE(B13, "-",C13, "-", D13, "-", F13) -> M0111-A-6-2 | H13: 13.2 | I13: 13.94
... A1049: 501 | B1049: M0113 | C1049: A | D1049: 210 | E1049: R | F1049: 2 | G1049: =CONCATENATE(B1049, "-",C1049, "-", D1049, "-", F1049) -> M0113-A-210-2 | H1049: 324.01 | I1049: 325.1

Sheet Beakers
A1: Number | B1: Weight, g | C1: Volume, cc
A2: 91 | B2: 9.5239 | C2: =B2/2.23 -> 4.2708072 | F2: Need editing with values for X501
A3: 92 | B3: 9.1041 | C3: =B3/2.23 -> 4.0825561
A4: 93 | B4: 9.4765 | C4: =B4/2.23 -> 4.2495516
A5: 94 | B5: 9.6205 | C5: =B5/2.23 -> 4.3141256
A6: 95 | B6: 9.3813 | C6: =B6/2.23 -> 4.206861
A7: 97 | B7: 9.4983 | C7: =B7/2.23 -> 4.2593274
A8: 98 | B8: 9.3954 | C8: =B8/2.23 -> 4.2131839
A9: 99 | B9: 9.327 | C9: =B9/2.23 -> 4.1825112
A10: 100 | B10: 9.6332 | C10: =B10/2.23 -> 4.3198206
A11: 151 | B11: 9.7264 | C11: =B11/2.23 -> 4.3616143
A12: 152 | B12: 9.7155 | C12: =B12/2.23 -> 4.3567265
A13: 153 | B13: 9.6697 | C13: =B13/2.23 -> 4.3361883
A14: 154 | B14: 9.7118 | C14: =B14/2.23 -> 4.3550673
... A138: 10 | B138: 9.9909 | C138: =B138/2.23 -> 4.4802242

Sheet Sample List
A1: Site | B1: Hole | C1: Core | D1: Type | E1: Section | F1: Half | G1: Top Interval | H1: Bot Interval | I1: Curators Top Depth (mbsf) | J1: Curators Bot Depth (mbsf) | K1: Lithology Comments | L1: Suggested depth flexibility | M1: Res (m)
A2: M0111 | B2: A | C2: 1 | D2: H | E2: 1 | F2: W | G2: 38 | H2: 40 | I2: =VLOOKUP(C2,[1]M0111A!$A$1:$Z$30,24,TRUE)+(G2/100) -> 0.38 | J2: =I2+0.02 -> 0.4 | K2: sand with shells | L2: ± 10 cm | M2: n/a
A3: M0111 | B3: A | C3: 2 | D3: H | E3: 2 | F3: W | G3: 38 | H3: 40 | I3: 4.29 | J3: =I3+0.02 -> 4.31 | K3: shells in sand | L3: ± 10 cm | M3: =I3-I2 -> 3.91
A4: M0111 | B4: A | C4: 3 | D4: H | E4: 1 | F4: W | G4: 38 | H4: 40 | I4: =VLOOKUP(C4,[1]M0111A!$A$1:$Z$30,24,TRUE)+(G4/100) -> 4.84 | J4: =I4+0.02 -> 4.86 | K4: shells in sand | L4: ± 10 cm | M4: =I4-I3 -> 0.55
A5: M0111 | B5: A | C5: 4 | D5: H | E5: 1 | F5: W | G5: 88 | H5: 90 | I5: =VLOOKUP(C5,[1]M0111A!$A$1:$Z$30,24,TRUE)+(G5/100) -> 7.77 | J5: =I5+0.02 -> 7.79 | K5: Sand | L5: ± 10 cm | M5: =I5-I4 -> 2.93
A6: M0111 | B6: A | C6: 5 | D6: H | E6: 1 | F6: W | G6: 98 | H6: 100 | I6: =VLOOKUP(C6,[1]M0111A!$A$1:$Z$30,24,TRUE)+(G6/100) -> 10.58 | J6: =I6+0.02 -> 10.6 | K6: Sand | L6: ± 10 cm | M6: =I6-I5 -> 2.81
A7: M0111 | B7: A | C7: 6 | D7: H | E7: 1 | F7: W | G7: 118 | H7: 120 | I7: =VLOOKUP(C7,[1]M0111A!$A$1:$Z$30,24,TRUE)+(G7/100) -> 12.88 | J7: =I7+0.02 -> 12.9 | K7: Sand | L7: ± 10 cm | M7: =I7-I6 -> 2.3
A8: M0111 | B8: A | C8: 7 | D8: H | E8: 1 | F8: W | G8: 14 | H8: 16 | I8: =VLOOKUP(C8,[1]M0111A!$A$1:$Z$30,24,TRUE)+(G8/100) -> 14.08 | J8: =I8+0.02 -> 14.1 | K8: slushy sand | L8: ± 10 cm | M8: =I8-I7 -> 1.2
A9: M0111 | B9: A | C9: 9 | D9: X | E9: 1 | F9: W | G9: 18 | H9: 20 | I9: =VLOOKUP(C9,[1]M0111A!$A$1:$Z$30,24,TRUE)+(G9/100) -> 14.95 | J9: =I9+0.02 -> 14.97 | K9: slushy sand | L9: ± 5 cm | M9: =I9-I8 -> 0.87
A10: M0111 | B10: A | C10: 10 | D10: R | E10: 1 | F10: W | G10: 38 | H10: 40 | I10: =VLOOKUP(C10,[1]M0111A!$A$1:$Z$30,24,TRUE)+(G10/100) -> 15.59 | J10: =I10+0.02 -> 15.61 | K10: slushy sand | L10: ± 10 cm | M10: =I10-I9 -> 0.64
A11: M0111 | B11: A | C11: 11 | D11: R | E11: 1 | F11: W | G11: 38 | H11: 40 | I11: =VLOOKUP(C11,[1]M0111A!$A$1:$Z$30,24,TRUE)+(G11/100) -> 16.74 | J11: =I11+0.02 -> 16.76 | K11: slushy sand | L11: ± 10 cm | M11: =I11-I10 -> 1.15
A12: M0111 | B12: A | C12: 12 | D12: R | E12: 1 | F12: W | G12: 48 | H12: 50 | I12: =VLOOKUP(C12,[1]M0111A!$A$1:$Z$30,24,TRUE)+(G12/100) -> 32.73 | J12: =I12+0.02 -> 32.75 | K12: sand | L12: ± 10 cm
A13: M0111 | B13: A | C13: 13 | D13: H | E13: 1 | F13: W | G13: 38 | H13: 40 | I13: =VLOOKUP(C13,[1]M0111A!$A$1:$Z$30,24,TRUE)+(G13/100) -> 34.18 | J13: =I13+0.02 -> 34.2 | K13: very fine slushy sand | L13: ± 10 cm | M13: =I13-I12 -> 1.45
A14: M0111 | B14: A | C14: 15 | D14: H | E14: 1 | F14: W | G14: 38 | H14: 40 | I14: =VLOOKUP(C14,[1]M0111A!$A$1:$Z$30,24,TRUE)+(G14/100) -> 38.5 | J14: =I14+0.02 -> 38.52 | K14: Light grey mix of medium coarse to fine sand | L14: ± 10 cm | M14: =I14-I13 -> 4.32
A15: M0111 | B15: A | C15: 16 | D15: H | E15: 1 | F15: W | G15: 38 | H15: 40 | I15: =VLOOKUP(C15,[1]M0111A!$A$1:$Z$30,24,TRUE)+(G15/100) -> 40.83 | J15: =I15+0.02 -> 40.85 | K15: light grey coarse sand | L15: ± 10 cm | M15: =I15-I14 -> 2.33
A16: M0111 | B16: A | C16: 17 | D16: H | E16: 1 | F16: W | G16: 38 | H16: 40 | I16: =VLOOKUP(C16,[1]M0111A!$A$1:$Z$30,24,TRUE)+(G16/100) -> 41.57 | J16: =I16+0.02 -> 41.59 | K16: light grey medium coarse sand | L16: ± 10 cm | M16: =I16-I15 -> 0.74
A17: M0111 | B17: A | C17: 18 | D17: H | E17: 1 | F17: W | G17: 38 | H17: 40 | I17: =VLOOKUP(C17,[1]M0111A!$A$1:$Z$30,24,TRUE)+(G17/100) -> 43.7 | J17: =I17+0.02 -> 43.72 | K17: Coarse to medium corase sand | L17: ± 10 cm | M17: =I17-I16 -> 2.13
A18: M0111 | B18: A | C18: 19 | D18: H | E18: 1 | F18: W | G18: 38 | H18: 40 | I18: =VLOOKUP(C18,[1]M0111A!$A$1:$Z$30,24,TRUE)+(G18/100) -> 44.21 | J18: =I18+0.02 -> 44.23 | K18: medium coarse sand | L18: ± 10 cm | M18: =I18-I17 -> 0.51
A19: M0111 | B19: A | C19: 20 | D19: H | E19: 1 | F19: W | G19: 38 | H19: 40 | I19: =VLOOKUP(C19,[1]M0111A!$A$1:$Z$30,24,TRUE)+(G19/100) -> 46.58 | J19: =I19+0.02 -> 46.6 | K19: Coarse to medium coarse sand, | L19: ± 10 cm | M19: =I19-I18 -> 2.37
A20: M0111 | B20: A | C20: 21 | D20: H | E20: 2 | F20: W | G20: 38 | H20: 40 | I20: 49.15 | J20: =I20+0.02 -> 49.17 | K20: very fine dark grey sand | L20: ± 10 cm | M20: =I20-I19 -> 2.57
A21: M0111 | B21: A | C21: 22 | D21: H | E21: 1 | F21: W | G21: 38 | H21: 40 | I21: =VLOOKUP(C21,[1]M0111A!$A$1:$Z$30,24,TRUE)+(G21/100) -> 51.28 | J21: =I21+0.02 -> 51.3 | K21: very fine dark grey sand | L21: ± 10 cm | M21: =I21-I20 -> 2.13
A22: M0111 | B22: A | C22: 23 | D22: H | E22: 1 | F22: W | G22: 38 | H22: 40 | I22: =VLOOKUP(C22,[1]M0111A!$A$1:$Z$30,24,TRUE)+(G22/100) -> 52.8 | J22: =I22+0.02 -> 52.82 | K22: very fine sand | L22: ± 10 cm | M22: =I22-I21 -> 1.52
A23: M0111 | B23: A | C23: 24 | D23: H | E23: 1 | F23: W | G23: 38 | H23: 40 | I23: =VLOOKUP(C23,[1]M0111A!$A$1:$Z$30,24,TRUE)+(G23/100) -> 55.3 | J23: =I23+0.02 -> 55.32 | K23: fine grain dark gray sand | L23: ± 10 cm | M23: =I23-I22 -> 2.5
A24: M0111 | B24: A | C24: 25 | D24: H | E24: 1 | F24: W | G24: 38 | H24: 40 | I24: =VLOOKUP(C24,[1]M0111A!$A$1:$Z$30,24,TRUE)+(G24/100) -> 57.04 | J24: =I24+0.02 -> 57.06 | K24: fine grain dark sand | L24: ± 10 cm | M24: =I24-I23 -> 1.74
A25: M0111 | B25: A | C25: 26 | D25: H | E25: 1 | F25: W | G25: 38 | H25: 40 | I25: =VLOOKUP(C25,[1]M0111A!$A$1:$Z$30,24,TRUE)+(G25/100) -> 59.26 | J25: =I25+0.02 -> 59.28 | K25: medium to fine dark grey sand | L25: ± 10 cm | M25: =I25-I24 -> 2.22
A26: M0111 | B26: A | C26: 27 | D26: H | E26: 1 | F26: W | G26: 38 | H26: 40 | I26: =VLOOKUP(C26,[1]M0111A!$A$1:$Z$30,24,TRUE)+(G26/100) -> 61.58 | J26: =I26+0.02 -> 61.6 | K26: lightish gray medium grain sand | L26: ± 10 cm | M26: =I26-I25 -> 2.32
A27: M0111 | B27: A | C27: 29 | D27: H | E27: 1 | F27: W | G27: 18 | H27: 20 | I27: =VLOOKUP(C27,[1]M0111A!$A$1:$Z$30,24,TRUE)+(G27/100) -> 63.56 | J27: =I27+0.02 -> 63.58 | K27: soupy dark-ish gray sand | L27: ± 5 cm | M27: =I27-I26 -> 1.98
A29: M0111 | B29: B | C29: 1 | D29: H | E29: 2 | F29: W | G29: 48 | H29: 50 | I29: 63.98 | J29: 64 | K29: medium coarse light grey sand | L29: ± 10 cm | M29: n/a
A30: M0111 | B30: B | C30: 2 | D30: H | E30: 2 | F30: W | G30: 78 | H30: 80 | I30: 65.92 | J30: 65.94 | K30: dark grey coarse to medium coarse sand | L30: ± 10 cm | M30: =I30-I29 -> 1.94
A31: M0111 | B31: B | C31: 3 | D31: H | E31: 2 | F31: W | G31: 38 | H31: 40 | I31: 67.94 | J31: 67.96 | K31: light grey medium coarse sand | L31: ± 10 cm | M31: =I31-I30 -> 2.02
A32: M0111 | B32: B | C32: 4 | D32: H | E32: 1 | F32: W | G32: 98 | H32: 100 | I32: 69.18 | J32: 69.2 | K32: medium grain dark sand with shells inside | L32: ± 10 cm | M32: =I32-I31 -> 1.24
A33: M0111 | B33: B | C33: 5 | D33: H | E33: 2 | F33: W | G33: 58 | H33: 60 | I33: 71.12 | J33: 71.14 | K33: coarse sand with shells | L33: ± 10 cm | M33: =I33-I32 -> 1.94
A34: M0111 | B34: B | C34: 6 | D34: H | E34: 1 | F34: W | G34: 60 | H34: 62 | I34: 72.14 | J34: 72.16 | K34: medium coarse sand | L34: ± 10 cm | M34: =I34-I33 -> 1.02
A35: M0111 | B35: B | C35: 9 | D35: R | E35: 1 | F35: W | G35: 100 | H35: 102 | I35: 73.76 | J35: 73.78 | K35: sand and clay mix, silty clay, grey | L35: ± 10 cm | M35: =I35-I34 -> 1.62
A36: M0111 | B36: B | C36: 12 | D36: R | E36: 1 | F36: W | G36: 11 | H36: 13 | I36: 76.8 | J36: 76.82 | K36: silty clay | L36: ± 10 cm | M36: =I36-I35 -> 3.04
A37: M0111 | B37: B | C37: 13 | D37: R | E37: 1 | F37: W | G37: 18 | H37: 20 | I37: 79.78 | J37: 79.8 | K37: silty mud | L37: ± 10 cm | M37: =I37-I36 -> 2.98
A38: M0111 | B38: B | C38: 14 | D38: R | E38: 1 | F38: W | G38: 18 | H38: 20 | I38: 82.78 | J38: 82.8 | K38: silty mud | L38: ± 10 cm | M38: =I38-I37 -> 3
A39: M0111 | B39: B | C39: 15 | D39: R | E39: 1 | F39: W | G39: 38 | H39: 40 | I39: 84.98 | J39: 85 | K39: silty mud? | L39: ± 10 cm | M39: =I39-I38 -> 2.2
A40: M0111 | B40: B | C40: 16 | D40: R | E40: 1 | F40: W | G40: 18 | H40: 20 | I40: 86.78 | J40: 86.8 | K40: silty clay | L40: ± 10 cm | M40: =I40-I39 -> 1.8
A41: M0111 | B41: B | C41: 17 | D41: R | E41: 1 | F41: W | G41: 38 | H41: 40 | I41: 88.78 | J41: 88.8 | K41: silty clay | L41: ± 10 cm | M41: =I41-I40 -> 2
...

Sheet PRINT
A1: MOISTURE and DENSITY (MAD)
A2: Site | B2: Hole | C2: Core | D2: Type | E2: Section | F2: Sample Top, cm | G2: Sample Base, cm | H2: Beaker Number | I2: WET WEIGHT (Sample + Beaker), g | J2: IN OVEN (date/time) | K2: Scientist | L2: OUT OF OVEN (date/time) | M2: Scientist | N2: IN DSCTR (time/date) | O2: OUT OF DSCTR (time/date) | P2: DRY WEIGHT (Sample + Beaker), g | Q2: PYCNOMTR (date/time) | R2: P Cell | S2: DRY VOLUME (Sample + Beaker), cc

Sheet Plots_M0111
A1: mbsf | B1: porosity | E1: mbsf (top) | F1: porosity | S1: Run Number | T1: Volume of Std | U1: Offset | V1: Pyc Cell | X1: Pyc Cell | Y1: Run Number | Z1: Volume of Std | AA1: Offset | AC1: Pyc Cell | AD1: Run Number | AE1: Volume of Std | AF1: Offset | AH1: Pyc Cell | AI1: Run Number | AJ1: Volume of Std | AK1: Offset | AM1: Pyc Cell | AN1: Volume of Std | AO1: Offset | AP1: Run Number
A2: 52.8 | B2: 0.40890733 | C2: clay | E2: 0.635 | F2: 0.34086152 | G2: sand | S2: 2 | T2: 9.2176 | U2: -0.0027 | V2: 1 | X2: 3 | Y2: 2 | Z2: 9.2133 | AA2: 0.0016 | AC2: 4 | AD2: 3 | AE2: 9.2299 | AF2: -0.015 | AH2: 1 | AI2: 5 | AJ2: 9.2015 | AK2: 0.0134 | AM2: 5 | AN2: 9.1656 | AO2: 0.0493 | AP2: 4
A3: 79.78 | B3: 0.41858324 | C3: clay | E3: 4.29 | F3: 0.39716197 | G3: sand | S3: 8 | T3: 9.1865 | U3: 0.0284 | V3: 1 | X3: 10 | Y3: 2 | Z3: 9.2397 | AA3: -0.0248 | AC3: 11 | AD3: 3 | AE3: 9.2187 | AF3: -0.0038 | AH3: 7 | AI3: 5 | AJ3: 9.2127 | AK3: 0.0022 | AM3: Calibration Cell | AN3: 9.2059 | AO3: 0.009 | AP3: 4
A4: 82.8 | B4: 0.42851343 | C4: clay | E4: 4.84 | F4: 0.39021315 | G4: sand | S4: Calibration Cell | T4: 9.2188 | U4: -0.0039 | V4: 1 | X4: Calibration Cell | Y4: 2 | Z4: 9.2111 | AA4: 0.0038 | AC4: 15 | AD4: 3 | AE4: 9.1812 | AF4: 0.0337 | AH4: 12 | AI4: 5 | AJ4: 9.2231 | AK4: -0.0082 | AM4: 6 | AN4: 9.1879 | AO4: 0.027 | AP4: 4
A5: 84.98 | B5: 0.47481257 | C5: clay | E5: 7.77 | F5: 0.39333309 | G5: sand | S5: 9 | T5: 9.2164 | U5: -0.0015 | V5: 1 | X5: 14 | Y5: 2 | Z5: 9.2141 | AA5: 0.0008 | AC5: 19 | AD5: 3 | AE5: 9.2131 | AF5: 0.0018 | AH5: 16 | AI5: 5 | AJ5: 9.2207 | AK5: -0.0058 | AM5: Calibration Cell | AN5: Unstable Pressure | AP5: 4
A6: 86.78 | B6: 0.49347354 | C6: clay | E6: 10.6 | F6: 0.37049993 | G6: sand | S6: 13 | T6: 9.2205 | U6: -0.0056 | V6: 1 | X6: 18 | Y6: 2 | Z6: 9.2031 | AA6: 0.0118 | AC6: 23 | AD6: 3 | AE6: 9.2051 | AF6: 0.0098 | AH6: 20 | AI6: 5 | AJ6: 9.215 | AK6: -0.0001 | AM6: Calibration Cell | AN6: 9.2189 | AO6: -0.004 | AP6: 4
A7: 88.78 | B7: 0.53979174 | C7: clay | E7: 12.9 | F7: 0.4036421 | G7: sand | S7: 17 | T7: 9.2045 | U7: 0.0104 | V7: 1 | X7: 22 | Y7: 2 | Z7: 9.2305 | AA7: -0.0156 | AC7: 27 | AD7: 3 | AE7: 9.226 | AF7: -0.0111 | AH7: 24 | AI7: 5 | AJ7: 9.2266 | AK7: -0.0117
A8: 91.26 | B8: 0.48663105 | C8: clay | E8: 14.08 | F8: 0.38500764 | G8: sand | S8: 21 | T8: 9.2215 | U8: -0.0066 | V8: 1 | X8: 26 | Y8: 2 | Z8: 9.2153 | AA8: -0.0004 | AC8: 31 | AD8: 3 | AE8: 9.2201 | AF8: -0.0052 | AH8: 28 | AI8: 5 | AJ8: 9.2235 | AK8: -0.0086
A9: 100.67 | B9: 0.50234588 | C9: clay | E9: 14.95 | F9: 0.39294953 | G9: sand | S9: 25 | T9: 9.2237 | U9: -0.0088 | V9: 1 | X9: 30 | Y9: 2 | Z9: 9.1928 | AA9: 0.0221 | AC9: 35 | AD9: 3 | AE9: 9.1984 | AF9: 0.0165 | AH9: 32 | AI9: 5 | AJ9: 9.2217 | AK9: -0.0068
A10: 106.79 | B10: 0.48400682 | C10: clay | E10: 15.61 | F10: 0.35089957 | G10: sand | S10: 29 | T10: 9.2304 | U10: -0.0155 | V10: 1 | X10: 34 | Y10: 2 | Z10: 9.2164 | AA10: -0.0015 | AC10: 39 | AD10: 3 | AE10: 9.2056 | AF10: 0.0093 | AH10: 36 | AI10: 5 | AJ10: 9.2076 | AK10: 0.0073
A11: 103.79 | B11: 0.43670293 | C11: clay | E11: 16.74 | F11: 0.33345857 | G11: sand | S11: 33 | T11: 9.2265 | U11: -0.0116 | V11: 1 | X11: 38 | Y11: 2 | Z11: 9.2096 | AA11: 0.0053 | AC11: 43 | AD11: 3 | AE11: 9.2077 | AF11: 0.0072 | AH11: 44 | AI11: 5 | AJ11: 9.2193 | AK11: -0.0044
A12: 109.8 | B12: 0.54841101 | C12: clay | E12: 32.73 | F12: 0.35296852 | G12: sand | S12: 37 | T12: 9.2242 | U12: -0.0093 | V12: 1 | X12: 46 | Y12: 2 | Z12: 9.2095 | AA12: 0.0054 | AC12: 50 | AD12: 3 | AE12: 9.1775 | AF12: 0.0374 | AH12: 48 | AI12: 5 | AJ12: 9.2251 | AK12: -0.0102
A13: 112.54 | B13: 0.45311273 | C13: clay | E13: 34.18 | F13: 0.4238545 | G13: sand | S13: 45 | T13: 9.209 | U13: 0.0059 | V13: 1 | X13: 53 | Y13: 2 | Z13: 9.1921 | AA13: 0.0228 | AC13: 54 | AD13: 3 | AE13: 9.2041 | AF13: 0.0108 | AH13: 51 | AI13: 5 | AJ13: 9.1937 | AK13: 0.0212
A14: 115.52 | B14: 0.46121965 | C14: clay | E14: 38.5 | F14: 0.37954219 | G14: sand | S14: 49 | T14: 9.2176 | U14: -0.0027 | V14: 1 | X14: 57 | Y14: 2 | Z14: 9.194 | AA14: 0.0209 | AC14: 58 | AD14: 3 | AE14: 9.1979 | AF14: 0.017 | AH14: 55 | AI14: 5 | AJ14: 9.2051 | AK14: 0.0098
A15: 118.48 | B15: 0.46005746 | C15: clay | E15: 40.83 | F15: 0.34863609 | G15: sand | S15: 52 | T15: 9.2288 | U15: -0.0139 | V15: 1 | X15: 61 | Y15: 2 | Z15: 9.1569 | AA15: 0.058 | AC15: 62 | AD15: 3 | AE15: 9.1915 | AF15: 0.0234 | AH15: 59 | AI15: 5 | AJ15: 9.2135 | AK15: 0.0014
A16: 121.43 | B16: 0.5058793 | C16: clay | E16: 41.57 | F16: 0.38337633 | G16: sand | S16: 56 | T16: 9.2271 | U16: -0.0122 | V16: 1 | X16: Calibration Cell | Y16: 2 | Z16: 9.2101 | AA16: 0.0048 | AC16: 66 | AD16: 3 | AE16: 9.1849 | AF16: 0.03 | AH16: 63 | AI16: 5 | AJ16: 9.2006 | AK16: 0.0143
A17: 124.48 | B17: 0.44592802 | C17: clay | E17: 43.39 | F17: 0.43956129 | G17: sand | S17: 60 | T17: 9.2086 | U17: 0.0063 | V17: 1 | X17: 65 | Y17: 2 | Z17: 9.225 | AA17: -0.0101 | AH17: 67 | AI17: 5 | AJ17: 9.2134 | AK17: 0.0015
A18: 127.39 | B18: 0.5013061 | C18: clay | E18: 44.21 | F18: 0.35780857 | G18: sand | S18: 64 | T18: 9.2267 | U18: -0.0118 | V18: 1 | X18: 69 | Y18: 2 | Z18: 9.2108 | AA18: 0.0041
A19: 121.7 | B19: 0.57123734 | C19: clay | E19: 46.58 | F19: 0.34324646 | G19: sand | S19: 68 | T19: 9.2367 | U19: -0.0218 | V19: 1
A20: 124.2 | B20: 0.42808259 | C20: clay | E20: 49.08 | F20: 0.41810049 | G20: sand
A21: 126.75 | B21: 0.44508373 | C21: clay | E21: 51.05 | F21: 0.44100834 | G21: sand
A22: 127.82 | B22: 0.41169765 | C22: clay | E22: 55.3 | F22: 0.3657116 | G22: sand
A23: 129.57 | B23: 0.3703242 | C23: clay | E23: 57.04 | F23: 0.40453147 | G23: sand
A24: 131.85 | B24: 0.45054828 | C24: clay | E24: 59.78 | F24: 0.38774971 | G24: sand
A25: 172.94 | B25: 0.58343856 | C25: clay | E25: 61.9 | F25: 0.31920303 | G25: sand
A26: 176.15 | B26: 0.49619429 | C26: clay | E26: 63.98 | F26: 0.36432402 | G26: sand
A27: 179.04 | B27: 0.51929471 | C27: clay | E27: 65.91 | F27: 0.33351632 | G27: sand
A28: 182.06 | B28: 0.47507783 | C28: clay | E28: 67.94 | F28: 0.38560857 | G28: sand
A29: 185.17 | B29: 0.51494341 | C29: clay | E29: 69.2 | F29: 0.34891202 | G29: sand
A30: 204.22 | B30: 0.48231687 | C30: clay | E30: 71.06 | F30: 0.24128172 | G30: sand
A31: 206.59 | B31: 0.5 | C31: clay | E31: 72.14 | F31: 0.40369404 | G31: sand
... A78: 207.84 | B78: 0.4957512 | C78: clay | E78: 296.01 | F78: 0.41952951 | G78: sand
E79: 306.71 | F79: 0.33861762 | G79: sand
E80: 319.65 | F80: 0.43242029 | G80: sand
E81: 326.51 | F81: 0.50109373 | G81: sand
E82: 329.28 | F82: 0.34126229 | G82: sand
E83: 331.24 | F83: 0.34996317 | G83: sand
E84: 332.96 | F84: 0.39540207 | G84: sand
E85: 335.36 | F85: 0.41659262 | G85: sand
E86: 336.71 | F86: 0.41876323 | G86: sand
...

Sheet Plots_M0112
A1: mbsf | B1: porosity | E1: mbsf (top) | F1: porosity | S1: Run Number | T1: Pyc Cell | U1: Volume of Std | V1: Offset | X1: Run Number | Y1: Pyc Cell | Z1: Volume of Std | AA1: Offset | AC1: Run Number | AD1: Pyc Cell | AE1: Volume of Std | AF1: Offset | AH1: Run Number | AI1: Pyc Cell | AJ1: Volume of Std | AK1: Offset
A2: 39.03 | B2: 0.52254782 | C2: clay | E2: 0.55 | F2: 0.43649314 | G2: sand | S2: 64 | T2: 1 | U2: 9.2267 | V2: -0.0118 | X2: 65 | Y2: 2 | Z2: 9.225 | AA2: -0.0101 | AC2: 62 | AD2: 3 | AE2: 9.1915 | AF2: 0.0234 | AH2: 63 | AI2: 5 | AJ2: 9.2006 | AK2: 0.0143
A3: 55.59 | B3: 0.43934976 | C3: clay | E3: 2.59 | F3: 0.42294289 | G3: sand | S3: 68 | T3: 1 | U3: 9.2367 | V3: -0.0218 | X3: 69 | Y3: 2 | Z3: 9.2108 | AA3: 0.0041 | AC3: 66 | AD3: 3 | AE3: 9.1849 | AF3: 0.03 | AH3: 67 | AI3: 5 | AJ3: 9.2134 | AK3: 0.0015
A4: 56.68 | B4: 0.46691546 | C4: clay | E4: 5.45 | F4: 0.358287 | G4: sand | S4: 73 | T4: 1 | U4: 9.228 | V4: -0.0131 | X4: 74 | Y4: 2 | Z4: 9.2103 | AA4: 0.0046 | AC4: 75 | AD4: 3 | AE4: 9.2397 | AF4: -0.0248 | AH4: 76 | AI4: 5 | AJ4: 9.2072 | AK4: 0.0077
A5: 59.89 | B5: 0.42965403 | C5: clay | E5: 7.53 | F5: 0.38102489 | G5: sand | S5: 77 | T5: 1 | U5: 9.2116 | V5: 0.0033 | X5: 78 | Y5: 2 | Z5: 9.2335 | AA5: -0.0186 | AC5: 79 | AD5: 3 | AE5: 9.1947 | AF5: 0.0202 | AH5: 80 | AI5: 5 | AJ5: 9.2171 | AK5: -0.0022
A6: 60.89 | B6: 0.5023074 | C6: clay | E6: 9.65 | F6: 0.41205251 | G6: sand | S6: 81 | T6: 1 | U6: 9.2059 | V6: 0.009 | X6: 82 | Y6: 2 | Z6: 9.2438 | AA6: -0.0289 | AC6: 83 | AD6: 3 | AE6: 9.2786 | AF6: -0.0637
A7: 62.59 | B7: 0.4960634 | C7: clay | E7: 11.83 | F7: 0.37817454 | G7: sand | S7: 72 | T7: 5 | U7: 9.2107 | V7: 0.0042
A8: 65.845 | B8: 0.53512813 | C8: clay | E8: 12.59 | F8: 0.43157729 | G8: sand
A9: 67.945 | B9: 0.48890676 | C9: clay | E9: 14.96 | F9: 0.44033747 | G9: sand
A10: 68.67 | B10: 0.43252587 | C10: clay | E10: 17.61 | F10: 0.40693485 | G10: sand
A11: 69.49 | B11: 0.53974805 | C11: clay | E11: 20.47 | F11: 0.39069927 | G11: sand
A12: 71.51 | B12: 0.51346904 | C12: clay | E12: 21.39 | F12: 0.34059235 | G12: sand
A13: 73.425 | B13: 0.43658072 | C13: clay | E13: 24.16 | F13: 0.3062573 | G13: sand
A14: 75.76 | B14: 0.50118955 | C14: clay | E14: 24.59 | F14: 0.32071351 | G14: sand
A15: 77.65 | B15: 0.5109173 | C15: clay | E15: 26.27 | F15: 0.35831974 | G15: sand
A16: 80.56 | B16: 0.51109752 | C16: clay | E16: 28.05 | F16: 0.36514553 | G16: sand
A17: 83.61 | B17: 0.55709779 | C17: clay | E17: 33.51 | F17: 0.50165329 | G17: sand
A18: 86.91 | B18: 0.50320125 | C18: clay | E18: 35.19 | F18: 0.40048447 | G18: sand
A19: 88.14 | B19: 0.56842348 | C19: clay | E19: 37.17 | F19: 0.41893206 | G19: sand
... A28: 150.62 | B28: 0.46649001 | C28: clay | E28: 97.79 | F28: 0.31398827 | G28: sand
E29: 98.94 | F29: 0.27487397 | G29: sand
E30: 102.71 | F30: 0.28818329 | G30: sand
E31: 103.32 | F31: 0.32296614 | G31: sand
E32: 104.66 | F32: 0.32142583 | G32: sand
E33: 107.33 | F33: 0.34054947
E34: 110.39 | F34: 0.42643978 | G34: sand
E35: 113.29 | F35: 0.32327396 | G35: sand
E36: 115.59 | F36: 0.3886603 | G36: sand
E37: 117.28 | F37: 0.28190461 | G37: sand
E38: 119.59 | F38: -0.74918801 | G38: sand
E39: 121.95 | F39: 0.55494242 | G39: sand
E40: 92.73 | F40: 0.35477069
E41: 120.74 | F41: 0.38399565
E42: 122.5 | F42: 0.36597595
E43: 124.92 | F43: 0.82084187
E44: 124.23 | F44: 0.33096943
E45: 126.27 | F45: 0.439781
E46: 126.86 | F46: 0.53941857 | G46: sand
E47: 128.51 | F47: 0.45499451 | G47: sand
E48: 131.11 | F48: 0.49567609 | G48: sand
...
