Workbook

Sheet Calibration
A1: Date | B1: Time | C1: Solution | D1: T, deg | E1: Conductivity | F1: unit | G1: Comment
A2: 01/16/2026 | B2: 0.33680556 | C2: 1.48 | D2: 20.9 | E2: 3.918 | F2: mS | G2: data captured by Vera B.
A3: 01/16/2026 | B3: 0.34513889 | C3: 4.71 | D3: 20.9 | E3: 8.899 | F3: mS | G3: data captured by Vera B.
A4: 01/16/2026 | B4: 0.34722222 | C4: 9.9 | D4: 20.9 | E4: 16.8 | F4: mS | G4: data captured by Vera B.
A5: 01/16/2026 | B5: 0.35 | C5: 24.4 | D5: 20.9 | E5: 38.01 | F5: mS | G5: data captured by Vera B.
A6: 01/16/2026 | B6: 0.35416667 | C6: 34.7 | D6: 21 | E6: 50.85 | F6: mS | G6: data captured by Vera B.

Sheet Data Entry
V1: F = χsw/χsed.
A2: Expedition | B2: Site | C2: Hole | D2: Core | E2: Type | F2: Sec | G2: Sample [cm] | H2: Combined | I2: Depth of core (mbsf) | J2: Electrode | K2: Seawater reference Conductivity | L2: Seawater Reference Temperature | M2: Sediment Conductivity µS/cm | N2: Sediment Conductivity mS/cm | O2: Sediment T | P2: Interpolated salinity or Cl | Q2: T corr Conductivity Reference | R2: T corr Conductivity Sediment | S2: salinity corr ref | T2: T & Salinity Corrected Conductivity Sediment | U2: Formation Factor | V2: Note
A3: 501 | B3: 111 | C3: A | D3: 1 | E3: H | F3: 1 | G3: 68 | H3: =CONCATENATE("M0",B3,"-",C3, "-",D3, "-",F3) -> M0111-A-1-1 | I3: =VLOOKUP(H3,'Depth vlookup'!G2:I1049,2,FALSE)+G3/100 -> 0.68 | J3: 2 | K3: 50.6 | L3: 21.3 | M3: =N3*1000 -> 11450 | N3: 11.45 | O3: 19.3 | P3: ='salinity data'!C2 -> 32 | Q3: =K3*('Temperature Corrections'!$D$9+'Temperature Corrections'!$D$10*'Data Entry'!$L3+('Temperature Corrections'!$D$11*('Data Entry'!$L3^2))+('Temperature Corrections'!$D$12*('Data Entry'!$L3^3))+('Temperature Corrections'!$D$13*('Data Entry'!$L3^4))+('Temperature Corrections'!$D$14*('Data Entry'!$L3^5)))/'Temperature Corrections'!$G$6 -> 52.00388 | R3: =N3*('Temperature Corrections'!$D$9+'Temperature Corrections'!$D$10*'Data Entry'!$O3+('Temperature Corrections'!$D$11*('Data Entry'!$O3^2))+('Temperature Corrections'!$D$12*('Data Entry'!$O3^3))+('Temperature Corrections'!$D$13*('Data Entry'!$O3^4))+('Temperature Corrections'!$D$14*('Data Entry'!$O3^5)))/'Temperature Corrections'!$G$6 -> 11.279918 | S3: =Q3*(34.9994*'Salinity Corrections'!$I$22+'Salinity Corrections'!$I$23)/'Salinity Corrections'!$K$23 -> 52.00388 | T3: =R3*(P3*'Salinity Corrections'!$I$22+'Salinity Corrections'!$I$23)/'Salinity Corrections'!$K$23 -> 10.356373 | U3: =S3/T3 -> 5.0214377 | V3: undiluted reference solution
A4: 501 | B4: 111 | C4: A | D4: 21 | E4: H | F4: 2 | G4: 24 | H4: =CONCATENATE("M0",B4,"-",C4, "-",D4, "-",F4) -> M0111-A-21-2 | I4: =VLOOKUP(H4,'Depth vlookup'!G3:I1050,2,FALSE)+G4/100 -> 49.01 | J4: 2 | K4: 50.3 | L4: 21.5 | M4: =N4*1000 -> 12250 | N4: 12.25 | O4: 18.7 | P4: 32 | Q4: =K4*('Temperature Corrections'!$D$9+'Temperature Corrections'!$D$10*'Data Entry'!$L4+('Temperature Corrections'!$D$11*('Data Entry'!$L4^2))+('Temperature Corrections'!$D$12*('Data Entry'!$L4^3))+('Temperature Corrections'!$D$13*('Data Entry'!$L4^4))+('Temperature Corrections'!$D$14*('Data Entry'!$L4^5)))/'Temperature Corrections'!$G$6 -> 51.911122 | R4: =N4*('Temperature Corrections'!$D$9+'Temperature Corrections'!$D$10*'Data Entry'!$O4+('Temperature Corrections'!$D$11*('Data Entry'!$O4^2))+('Temperature Corrections'!$D$12*('Data Entry'!$O4^3))+('Temperature Corrections'!$D$13*('Data Entry'!$O4^4))+('Temperature Corrections'!$D$14*('Data Entry'!$O4^5)))/'Temperature Corrections'!$G$6 -> 11.912686 | S4: =Q4*(34.9994*'Salinity Corrections'!$I$22+'Salinity Corrections'!$I$23)/'Salinity Corrections'!$K$23 -> 51.911122 | T4: =R4*(P4*'Salinity Corrections'!$I$22+'Salinity Corrections'!$I$23)/'Salinity Corrections'!$K$23 -> 10.937333 | U4: =S4/T4 -> 4.7462323 | V4: undiluted reference solution
A5: 501 | B5: 111 | C5: A | D5: 21 | E5: H | F5: 2 | G5: 32 | H5: =CONCATENATE("M0",B5,"-",C5, "-",D5, "-",F5) -> M0111-A-21-2 | I5: =VLOOKUP(H5,'Depth vlookup'!G4:I1051,2,FALSE)+G5/100 -> 49.09 | J5: 2 | K5: 50.3 | L5: 21.5 | M5: =N5*1000 -> 10200 | N5: 10.2 | O5: 18.9 | P5: 32 | Q5: =K5*('Temperature Corrections'!$D$9+'Temperature Corrections'!$D$10*'Data Entry'!$L5+('Temperature Corrections'!$D$11*('Data Entry'!$L5^2))+('Temperature Corrections'!$D$12*('Data Entry'!$L5^3))+('Temperature Corrections'!$D$13*('Data Entry'!$L5^4))+('Temperature Corrections'!$D$14*('Data Entry'!$L5^5)))/'Temperature Corrections'!$G$6 -> 51.911122 | R5: =N5*('Temperature Corrections'!$D$9+'Temperature Corrections'!$D$10*'Data Entry'!$O5+('Temperature Corrections'!$D$11*('Data Entry'!$O5^2))+('Temperature Corrections'!$D$12*('Data Entry'!$O5^3))+('Temperature Corrections'!$D$13*('Data Entry'!$O5^4))+('Temperature Corrections'!$D$14*('Data Entry'!$O5^5)))/'Temperature Corrections'!$G$6 -> 9.9621973 | S5: =Q5*(34.9994*'Salinity Corrections'!$I$22+'Salinity Corrections'!$I$23)/'Salinity Corrections'!$K$23 -> 51.911122 | T5: =R5*(P5*'Salinity Corrections'!$I$22+'Salinity Corrections'!$I$23)/'Salinity Corrections'!$K$23 -> 9.1465404 | U5: =S5/T5 -> 5.6754925 | V5: undiluted reference solution
A6: 501 | B6: 111 | C6: B | D6: 14 | E6: R | F6: 1 | G6: 12 | H6: =CONCATENATE("M0",B6,"-",C6, "-",D6, "-",F6) -> M0111-B-14-1 | I6: =VLOOKUP(H6,'Depth vlookup'!G5:I1052,2,FALSE)+G6/100 -> 82.72 | J6: 2 | K6: 50.3 | L6: 21.5 | M6: =N6*1000 -> 6064 | N6: 6.064 | O6: 20.1 | P6: 30 | Q6: =K6*('Temperature Corrections'!$D$9+'Temperature Corrections'!$D$10*'Data Entry'!$L6+('Temperature Corrections'!$D$11*('Data Entry'!$L6^2))+('Temperature Corrections'!$D$12*('Data Entry'!$L6^3))+('Temperature Corrections'!$D$13*('Data Entry'!$L6^4))+('Temperature Corrections'!$D$14*('Data Entry'!$L6^5)))/'Temperature Corrections'!$G$6 -> 51.911122 | R6: =N6*('Temperature Corrections'!$D$9+'Temperature Corrections'!$D$10*'Data Entry'!$O6+('Temperature Corrections'!$D$11*('Data Entry'!$O6^2))+('Temperature Corrections'!$D$12*('Data Entry'!$O6^3))+('Temperature Corrections'!$D$13*('Data Entry'!$O6^4))+('Temperature Corrections'!$D$14*('Data Entry'!$O6^5)))/'Temperature Corrections'!$G$6 -> 6.0768985 | S6: =Q6*(34.9994*'Salinity Corrections'!$I$22+'Salinity Corrections'!$I$23)/'Salinity Corrections'!$K$23 -> 51.911122 | T6: =R6*(P6*'Salinity Corrections'!$I$22+'Salinity Corrections'!$I$23)/'Salinity Corrections'!$K$23 -> 5.2475867 | U6: =S6/T6 -> 9.89238 | V6: undiluted reference solution
A7: 501 | B7: 111 | C7: B | D7: 14 | E7: R | F7: 1 | G7: 13 | H7: =CONCATENATE("M0",B7,"-",C7, "-",D7, "-",F7) -> M0111-B-14-1 | I7: =VLOOKUP(H7,'Depth vlookup'!G6:I1053,2,FALSE)+G7/100 -> 82.73 | J7: 2 | K7: 50.3 | L7: 21.5 | M7: =N7*1000 -> 6448 | N7: 6.448 | O7: 20.1 | P7: 30 | Q7: =K7*('Temperature Corrections'!$D$9+'Temperature Corrections'!$D$10*'Data Entry'!$L7+('Temperature Corrections'!$D$11*('Data Entry'!$L7^2))+('Temperature Corrections'!$D$12*('Data Entry'!$L7^3))+('Temperature Corrections'!$D$13*('Data Entry'!$L7^4))+('Temperature Corrections'!$D$14*('Data Entry'!$L7^5)))/'Temperature Corrections'!$G$6 -> 51.911122 | R7: =N7*('Temperature Corrections'!$D$9+'Temperature Corrections'!$D$10*'Data Entry'!$O7+('Temperature Corrections'!$D$11*('Data Entry'!$O7^2))+('Temperature Corrections'!$D$12*('Data Entry'!$O7^3))+('Temperature Corrections'!$D$13*('Data Entry'!$O7^4))+('Temperature Corrections'!$D$14*('Data Entry'!$O7^5)))/'Temperature Corrections'!$G$6 -> 6.4617153 | S7: =Q7*(34.9994*'Salinity Corrections'!$I$22+'Salinity Corrections'!$I$23)/'Salinity Corrections'!$K$23 -> 51.911122 | T7: =R7*(P7*'Salinity Corrections'!$I$22+'Salinity Corrections'!$I$23)/'Salinity Corrections'!$K$23 -> 5.5798877 | U7: =S7/T7 -> 9.3032556 | V7: undiluted reference solution
A8: 501 | B8: 111 | C8: B | D8: 18 | E8: R | F8: 1 | G8: 18.5 | H8: =CONCATENATE("M0",B8,"-",C8, "-",D8, "-",F8) -> M0111-B-18-1 | I8: =VLOOKUP(H8,'Depth vlookup'!G7:I1054,2,FALSE)+G8/100 -> 91.285 | J8: 2 | K8: 44.48 | L8: 20.6 | M8: =N8*1000 -> 9250 | N8: 9.25 | O8: 17.2 | P8: 30 | Q8: =K8*('Temperature Corrections'!$D$9+'Temperature Corrections'!$D$10*'Data Entry'!$L8+('Temperature Corrections'!$D$11*('Data Entry'!$L8^2))+('Temperature Corrections'!$D$12*('Data Entry'!$L8^3))+('Temperature Corrections'!$D$13*('Data Entry'!$L8^4))+('Temperature Corrections'!$D$14*('Data Entry'!$L8^5)))/'Temperature Corrections'!$G$6 -> 45.04848 | R8: =N8*('Temperature Corrections'!$D$9+'Temperature Corrections'!$D$10*'Data Entry'!$O8+('Temperature Corrections'!$D$11*('Data Entry'!$O8^2))+('Temperature Corrections'!$D$12*('Data Entry'!$O8^3))+('Temperature Corrections'!$D$13*('Data Entry'!$O8^4))+('Temperature Corrections'!$D$14*('Data Entry'!$O8^5)))/'Temperature Corrections'!$G$6 -> 8.704064 | S8: =Q8*(34.9994*'Salinity Corrections'!$I$22+'Salinity Corrections'!$I$23)/'Salinity Corrections'!$K$23 -> 45.04848 | T8: =R8*(P8*'Salinity Corrections'!$I$22+'Salinity Corrections'!$I$23)/'Salinity Corrections'!$K$23 -> 7.516224 | U8: =S8/T8 -> 5.9934988 | V8: diluted reference solution
A9: 501 | B9: 111 | C9: B | D9: 18 | E9: R | F9: 1 | G9: 21 | H9: =CONCATENATE("M0",B9,"-",C9, "-",D9, "-",F9) -> M0111-B-18-1 | I9: =VLOOKUP(H9,'Depth vlookup'!G8:I1055,2,FALSE)+G9/100 -> 91.31 | J9: 2 | K9: 43.76 | L9: 20.6 | M9: =N9*1000 -> 9260 | N9: 9.26 | O9: 17.2 | P9: 30 | Q9: =K9*('Temperature Corrections'!$D$9+'Temperature Corrections'!$D$10*'Data Entry'!$L9+('Temperature Corrections'!$D$11*('Data Entry'!$L9^2))+('Temperature Corrections'!$D$12*('Data Entry'!$L9^3))+('Temperature Corrections'!$D$13*('Data Entry'!$L9^4))+('Temperature Corrections'!$D$14*('Data Entry'!$L9^5)))/'Temperature Corrections'!$G$6 -> 44.319278 | R9: =N9*('Temperature Corrections'!$D$9+'Temperature Corrections'!$D$10*'Data Entry'!$O9+('Temperature Corrections'!$D$11*('Data Entry'!$O9^2))+('Temperature Corrections'!$D$12*('Data Entry'!$O9^3))+('Temperature Corrections'!$D$13*('Data Entry'!$O9^4))+('Temperature Corrections'!$D$14*('Data Entry'!$O9^5)))/'Temperature Corrections'!$G$6 -> 8.7134738 | S9: =Q9*(34.9994*'Salinity Corrections'!$I$22+'Salinity Corrections'!$I$23)/'Salinity Corrections'!$K$23 -> 44.319278 | T9: =R9*(P9*'Salinity Corrections'!$I$22+'Salinity Corrections'!$I$23)/'Salinity Corrections'!$K$23 -> 7.5243497 | U9: =S9/T9 -> 5.8901141 | V9: diluted reference solution
A10: 501 | B10: 111 | C10: B | D10: 24 | E10: R | F10: 2 | G10: 88 | H10: =CONCATENATE("M0",B10,"-",C10, "-",D10, "-",F10) -> M0111-B-24-2 | I10: =VLOOKUP(H10,'Depth vlookup'!G9:I1056,2,FALSE)+G10/100 -> 103.79 | J10: 2 | K10: 44.8 | L10: 20.9 | M10: =N10*1000 -> 6476 | N10: 6.476 | O10: 20.5 | P10: 30 | Q10: =K10*('Temperature Corrections'!$D$9+'Temperature Corrections'!$D$10*'Data Entry'!$L10+('Temperature Corrections'!$D$11*('Data Entry'!$L10^2))+('Temperature Corrections'!$D$12*('Data Entry'!$L10^3))+('Temperature Corrections'!$D$13*('Data Entry'!$L10^4))+('Temperature Corrections'!$D$14*('Data Entry'!$L10^5)))/'Temperature Corrections'!$G$6 -> 45.659572 | R10: =N10*('Temperature Corrections'!$D$9+'Temperature Corrections'!$D$10*'Data Entry'!$O10+('Temperature Corrections'!$D$11*('Data Entry'!$O10^2))+('Temperature Corrections'!$D$12*('Data Entry'!$O10^3))+('Temperature Corrections'!$D$13*('Data Entry'!$O10^4))+('Temperature Corrections'!$D$14*('Data Entry'!$O10^5)))/'Temperature Corrections'!$G$6 -> 6.5449531 | S10: =Q10*(34.9994*'Salinity Corrections'!$I$22+'Salinity Corrections'!$I$23)/'Salinity Corrections'!$K$23 -> 45.659572 | T10: =R10*(P10*'Salinity Corrections'!$I$22+'Salinity Corrections'!$I$23)/'Salinity Corrections'!$K$23 -> 5.6517661 | U10: =S10/T10 -> 8.078815 | V10: diluted reference solution
A11: 501 | B11: 111 | C11: B | D11: 24 | E11: R | F11: 2 | G11: 85.5 | H11: =CONCATENATE("M0",B11,"-",C11, "-",D11, "-",F11) -> M0111-B-24-2 | I11: =VLOOKUP(H11,'Depth vlookup'!G10:I1057,2,FALSE)+G11/100 -> 103.765 | J11: 2 | K11: 44.11 | L11: 20.9 | M11: =N11*1000 -> 6125 | N11: 6.125 | O11: 20.5 | P11: 30 | Q11: =K11*('Temperature Corrections'!$D$9+'Temperature Corrections'!$D$10*'Data Entry'!$L11+('Temperature Corrections'!$D$11*('Data Entry'!$L11^2))+('Temperature Corrections'!$D$12*('Data Entry'!$L11^3))+('Temperature Corrections'!$D$13*('Data Entry'!$L11^4))+('Temperature Corrections'!$D$14*('Data Entry'!$L11^5)))/'Temperature Corrections'!$G$6 -> 44.956333 | R11: =N11*('Temperature Corrections'!$D$9+'Temperature Corrections'!$D$10*'Data Entry'!$O11+('Temperature Corrections'!$D$11*('Data Entry'!$O11^2))+('Temperature Corrections'!$D$12*('Data Entry'!$O11^3))+('Temperature Corrections'!$D$13*('Data Entry'!$O11^4))+('Temperature Corrections'!$D$14*('Data Entry'!$O11^5)))/'Temperature Corrections'!$G$6 -> 6.1902158 | S11: =Q11*(34.9994*'Salinity Corrections'!$I$22+'Salinity Corrections'!$I$23)/'Salinity Corrections'!$K$23 -> 44.956333 | T11: =R11*(P11*'Salinity Corrections'!$I$22+'Salinity Corrections'!$I$23)/'Salinity Corrections'!$K$23 -> 5.3454397 | U11: =S11/T11 -> 8.4102218 | V11: diluted reference solution | Y11: Reference Solution 30% | AA11: 01/19/26 16:00
A12: 501 | B12: 111 | C12: B | D12: 28 | E12: R | F12: 1 | G12: 7.5 | H12: =CONCATENATE("M0",B12,"-",C12, "-",D12, "-",F12) -> M0111-B-28-1 | I12: =VLOOKUP(H12,'Depth vlookup'!G11:I1058,2,FALSE)+G12/100 -> 112.375 | J12: 2 | K12: 45.12 | L12: 20.9 | M12: =N12*1000 -> 6757 | N12: 6.757 | O12: 19.6 | P12: 12 | Q12: =K12*('Temperature Corrections'!$D$9+'Temperature Corrections'!$D$10*'Data Entry'!$L12+('Temperature Corrections'!$D$11*('Data Entry'!$L12^2))+('Temperature Corrections'!$D$12*('Data Entry'!$L12^3))+('Temperature Corrections'!$D$13*('Data Entry'!$L12^4))+('Temperature Corrections'!$D$14*('Data Entry'!$L12^5)))/'Temperature Corrections'!$G$6 -> 45.985712 | R12: =N12*('Temperature Corrections'!$D$9+'Temperature Corrections'!$D$10*'Data Entry'!$O12+('Temperature Corrections'!$D$11*('Data Entry'!$O12^2))+('Temperature Corrections'!$D$12*('Data Entry'!$O12^3))+('Temperature Corrections'!$D$13*('Data Entry'!$O12^4))+('Temperature Corrections'!$D$14*('Data Entry'!$O12^5)))/'Temperature Corrections'!$G$6 -> 6.6995939 | S12: =Q12*(34.9994*'Salinity Corrections'!$I$22+'Salinity Corrections'!$I$23)/'Salinity Corrections'!$K$23 -> 45.985712 | T12: =R12*(P12*'Salinity Corrections'!$I$22+'Salinity Corrections'!$I$23)/'Salinity Corrections'!$K$23 -> 2.4934613 | U12: =S12/T12 -> 18.442521 | V12: diluted reference solution | Y12: Eletcr 2 | Z12: 44.7 mS/cm | AA12: @21.1 degC
A13: 501 | B13: 111 | C13: B | D13: 28 | E13: R | F13: 1 | G13: 10 | H13: =CONCATENATE("M0",B13,"-",C13, "-",D13, "-",F13) -> M0111-B-28-1 | I13: =VLOOKUP(H13,'Depth vlookup'!G12:I1059,2,FALSE)+G13/100 -> 112.4 | J13: 2 | K13: 44.13 | L13: 19.6 | M13: =N13*1000 -> 6694 | N13: 6.694 | O13: 19.6 | P13: 12 | Q13: =K13*('Temperature Corrections'!$D$9+'Temperature Corrections'!$D$10*'Data Entry'!$L13+('Temperature Corrections'!$D$11*('Data Entry'!$L13^2))+('Temperature Corrections'!$D$12*('Data Entry'!$L13^3))+('Temperature Corrections'!$D$13*('Data Entry'!$L13^4))+('Temperature Corrections'!$D$14*('Data Entry'!$L13^5)))/'Temperature Corrections'!$G$6 -> 43.75508 | R13: =N13*('Temperature Corrections'!$D$9+'Temperature Corrections'!$D$10*'Data Entry'!$O13+('Temperature Corrections'!$D$11*('Data Entry'!$O13^2))+('Temperature Corrections'!$D$12*('Data Entry'!$O13^3))+('Temperature Corrections'!$D$13*('Data Entry'!$O13^4))+('Temperature Corrections'!$D$14*('Data Entry'!$O13^5)))/'Temperature Corrections'!$G$6 -> 6.6371291 | S13: =Q13*(34.9994*'Salinity Corrections'!$I$22+'Salinity Corrections'!$I$23)/'Salinity Corrections'!$K$23 -> 43.75508 | T13: =R13*(P13*'Salinity Corrections'!$I$22+'Salinity Corrections'!$I$23)/'Salinity Corrections'!$K$23 -> 2.4702131 | U13: =S13/T13 -> 17.713079 | V13: diluted reference solution | Y13: Electr 1 | Z13: 43.9 mS/cm | AA13: @21.1 degC
A14: 501 | B14: 111 | C14: B | D14: 31 | E14: R | F14: 1 | G14: 4 | H14: =CONCATENATE("M0",B14,"-",C14, "-",D14, "-",F14) -> M0111-B-31-1 | I14: =VLOOKUP(H14,'Depth vlookup'!G13:I1060,2,FALSE)+G14/100 -> 121.34 | J14: 1 | K14: 43.63 | L14: 21.1 | M14: =N14*1000 -> 6920 | N14: 6.92 | O14: 20.8 | P14: 12 | Q14: =K14*('Temperature Corrections'!$D$9+'Temperature Corrections'!$D$10*'Data Entry'!$L14+('Temperature Corrections'!$D$11*('Data Entry'!$L14^2))+('Temperature Corrections'!$D$12*('Data Entry'!$L14^3))+('Temperature Corrections'!$D$13*('Data Entry'!$L14^4))+('Temperature Corrections'!$D$14*('Data Entry'!$L14^5)))/'Temperature Corrections'!$G$6 -> 44.653713 | R14: =N14*('Temperature Corrections'!$D$9+'Temperature Corrections'!$D$10*'Data Entry'!$O14+('Temperature Corrections'!$D$11*('Data Entry'!$O14^2))+('Temperature Corrections'!$D$12*('Data Entry'!$O14^3))+('Temperature Corrections'!$D$13*('Data Entry'!$O14^4))+('Temperature Corrections'!$D$14*('Data Entry'!$O14^5)))/'Temperature Corrections'!$G$6 -> 7.037988 | S14: =Q14*(34.9994*'Salinity Corrections'!$I$22+'Salinity Corrections'!$I$23)/'Salinity Corrections'!$K$23 -> 44.653713 | T14: =R14*(P14*'Salinity Corrections'!$I$22+'Salinity Corrections'!$I$23)/'Salinity Corrections'!$K$23 -> 2.6194052 | U14: =S14/T14 -> 17.047272 | V14: diluted reference solution
A15: 501 | B15: 111 | C15: B | D15: 31 | E15: R | F15: 1 | G15: 8 | H15: =CONCATENATE("M0",B15,"-",C15, "-",D15, "-",F15) -> M0111-B-31-1 | I15: =VLOOKUP(H15,'Depth vlookup'!G14:I1061,2,FALSE)+G15/100 -> 121.38 | J15: 1 | K15: 43.6 | L15: 21.1 | M15: =N15*1000 -> 5636 | N15: 5.636 | O15: 20.3 | P15: 12 | Q15: =K15*('Temperature Corrections'!$D$9+'Temperature Corrections'!$D$10*'Data Entry'!$L15+('Temperature Corrections'!$D$11*('Data Entry'!$L15^2))+('Temperature Corrections'!$D$12*('Data Entry'!$L15^3))+('Temperature Corrections'!$D$13*('Data Entry'!$L15^4))+('Temperature Corrections'!$D$14*('Data Entry'!$L15^5)))/'Temperature Corrections'!$G$6 -> 44.623009 | R15: =N15*('Temperature Corrections'!$D$9+'Temperature Corrections'!$D$10*'Data Entry'!$O15+('Temperature Corrections'!$D$11*('Data Entry'!$O15^2))+('Temperature Corrections'!$D$12*('Data Entry'!$O15^3))+('Temperature Corrections'!$D$13*('Data Entry'!$O15^4))+('Temperature Corrections'!$D$14*('Data Entry'!$O15^5)))/'Temperature Corrections'!$G$6 -> 5.6719851 | S15: =Q15*(34.9994*'Salinity Corrections'!$I$22+'Salinity Corrections'!$I$23)/'Salinity Corrections'!$K$23 -> 44.623009 | T15: =R15*(P15*'Salinity Corrections'!$I$22+'Salinity Corrections'!$I$23)/'Salinity Corrections'!$K$23 -> 2.1110049 | U15: =S15/T15 -> 21.138278 | V15: diluted reference solution
A16: 501 | B16: 111 | C16: B | D16: 39 | E16: R | F16: 1 | G16: 4 | H16: =CONCATENATE("M0",B16,"-",C16, "-",D16, "-",F16) -> M0111-B-39-1 | I16: =VLOOKUP(H16,'Depth vlookup'!G15:I1062,2,FALSE)+G16/100 -> 131.71 | J16: 1 | K16: 43.27 | L16: 20.9 | M16: =N16*1000 -> 4313 | N16: 4.313 | O16: 20.5 | P16: 12 | Q16: =K16*('Temperature Corrections'!$D$9+'Temperature Corrections'!$D$10*'Data Entry'!$L16+('Temperature Corrections'!$D$11*('Data Entry'!$L16^2))+('Temperature Corrections'!$D$12*('Data Entry'!$L16^3))+('Temperature Corrections'!$D$13*('Data Entry'!$L16^4))+('Temperature Corrections'!$D$14*('Data Entry'!$L16^5)))/'Temperature Corrections'!$G$6 -> 44.100216 | R16: =N16*('Temperature Corrections'!$D$9+'Temperature Corrections'!$D$10*'Data Entry'!$O16+('Temperature Corrections'!$D$11*('Data Entry'!$O16^2))+('Temperature Corrections'!$D$12*('Data Entry'!$O16^3))+('Temperature Corrections'!$D$13*('Data Entry'!$O16^4))+('Temperature Corrections'!$D$14*('Data Entry'!$O16^5)))/'Temperature Corrections'!$G$6 -> 4.3589226 | S16: =Q16*(34.9994*'Salinity Corrections'!$I$22+'Salinity Corrections'!$I$23)/'Salinity Corrections'!$K$23 -> 44.100216 | T16: =R16*(P16*'Salinity Corrections'!$I$22+'Salinity Corrections'!$I$23)/'Salinity Corrections'!$K$23 -> 1.622308 | U16: =S16/T16 -> 27.183627 | V16: diluted reference solution
A17: 501 | B17: 111 | C17: B | D17: 39 | E17: R | F17: 1 | G17: 9 | H17: =CONCATENATE("M0",B17,"-",C17, "-",D17, "-",F17) -> M0111-B-39-1 | I17: =VLOOKUP(H17,'Depth vlookup'!G16:I1063,2,FALSE)+G17/100 -> 131.76 | J17: 1 | K17: 43.27 | L17: 20.9 | M17: =N17*1000 -> 4790 | N17: 4.79 | O17: 20.4 | P17: 12 | Q17: =K17*('Temperature Corrections'!$D$9+'Temperature Corrections'!$D$10*'Data Entry'!$L17+('Temperature Corrections'!$D$11*('Data Entry'!$L17^2))+('Temperature Corrections'!$D$12*('Data Entry'!$L17^3))+('Temperature Corrections'!$D$13*('Data Entry'!$L17^4))+('Temperature Corrections'!$D$14*('Data Entry'!$L17^5)))/'Temperature Corrections'!$G$6 -> 44.100216 | R17: =N17*('Temperature Corrections'!$D$9+'Temperature Corrections'!$D$10*'Data Entry'!$O17+('Temperature Corrections'!$D$11*('Data Entry'!$O17^2))+('Temperature Corrections'!$D$12*('Data Entry'!$O17^3))+('Temperature Corrections'!$D$13*('Data Entry'!$O17^4))+('Temperature Corrections'!$D$14*('Data Entry'!$O17^5)))/'Temperature Corrections'!$G$6 -> 4.8307896 | S17: =Q17*(34.9994*'Salinity Corrections'!$I$22+'Salinity Corrections'!$I$23)/'Salinity Corrections'!$K$23 -> 44.100216 | T17: =R17*(P17*'Salinity Corrections'!$I$22+'Salinity Corrections'!$I$23)/'Salinity Corrections'!$K$23 -> 1.7979279 | U17: =S17/T17 -> 24.528356 | V17: diluted reference solution
A18: 501 | B18: 111 | C18: B | D18: 44 | E18: R | F18: 1 | G18: 70 | H18: =CONCATENATE("M0",B18,"-",C18, "-",D18, "-",F18) -> M0111-B-44-1 | I18: =VLOOKUP(H18,'Depth vlookup'!G17:I1064,2,FALSE)+G18/100 -> 146.81 | J18: 1 | K18: 41.92 | L18: 20.3 | M18: =N18*1000 -> 7216 | N18: 7.216 | O18: 18.4 | P18: 6 | Q18: =K18*('Temperature Corrections'!$D$9+'Temperature Corrections'!$D$10*'Data Entry'!$L18+('Temperature Corrections'!$D$11*('Data Entry'!$L18^2))+('Temperature Corrections'!$D$12*('Data Entry'!$L18^3))+('Temperature Corrections'!$D$13*('Data Entry'!$L18^4))+('Temperature Corrections'!$D$14*('Data Entry'!$L18^5)))/'Temperature Corrections'!$G$6 -> 42.187653 | R18: =N18*('Temperature Corrections'!$D$9+'Temperature Corrections'!$D$10*'Data Entry'!$O18+('Temperature Corrections'!$D$11*('Data Entry'!$O18^2))+('Temperature Corrections'!$D$12*('Data Entry'!$O18^3))+('Temperature Corrections'!$D$13*('Data Entry'!$O18^4))+('Temperature Corrections'!$D$14*('Data Entry'!$O18^5)))/'Temperature Corrections'!$G$6 -> 6.9716786 | S18: =Q18*(34.9994*'Salinity Corrections'!$I$22+'Salinity Corrections'!$I$23)/'Salinity Corrections'!$K$23 -> 42.187653 | T18: =R18*(P18*'Salinity Corrections'!$I$22+'Salinity Corrections'!$I$23)/'Salinity Corrections'!$K$23 -> 1.4528826 | U18: =S18/T18 -> 29.037207 | V18: sandy sediment, poorly consolidated
A19: 501 | B19: 111 | C19: B | D19: 44 | E19: R | F19: 1 | G19: 74 | H19: =CONCATENATE("M0",B19,"-",C19, "-",D19, "-",F19) -> M0111-B-44-1 | I19: =VLOOKUP(H19,'Depth vlookup'!G18:I1065,2,FALSE)+G19/100 -> 146.85 | J19: 1 | K19: 41.92 | L19: 20.3 | M19: =N19*1000 -> 5710 | N19: 5.71 | O19: 18.4 | P19: 6 | Q19: =K19*('Temperature Corrections'!$D$9+'Temperature Corrections'!$D$10*'Data Entry'!$L19+('Temperature Corrections'!$D$11*('Data Entry'!$L19^2))+('Temperature Corrections'!$D$12*('Data Entry'!$L19^3))+('Temperature Corrections'!$D$13*('Data Entry'!$L19^4))+('Temperature Corrections'!$D$14*('Data Entry'!$L19^5)))/'Temperature Corrections'!$G$6 -> 42.187653 | R19: =N19*('Temperature Corrections'!$D$9+'Temperature Corrections'!$D$10*'Data Entry'!$O19+('Temperature Corrections'!$D$11*('Data Entry'!$O19^2))+('Temperature Corrections'!$D$12*('Data Entry'!$O19^3))+('Temperature Corrections'!$D$13*('Data Entry'!$O19^4))+('Temperature Corrections'!$D$14*('Data Entry'!$O19^5)))/'Temperature Corrections'!$G$6 -> 5.5166692 | S19: =Q19*(34.9994*'Salinity Corrections'!$I$22+'Salinity Corrections'!$I$23)/'Salinity Corrections'!$K$23 -> 42.187653 | T19: =R19*(P19*'Salinity Corrections'!$I$22+'Salinity Corrections'!$I$23)/'Salinity Corrections'!$K$23 -> 1.1496618 | U19: =S19/T19 -> 36.695707 | V19: sandy sediment, poorly consolidated
A20: 501 | B20: 111 | C20: B | D20: 61 | E20: R | F20: 1 | G20: 34 | H20: =CONCATENATE("M0",B20,"-",C20, "-",D20, "-",F20) -> M0111-B-61-1 | I20: =VLOOKUP(H20,'Depth vlookup'!G19:I1066,2,FALSE)+G20/100 -> 175.95 | J20: 1 | K20: 43.5 | L20: 21.3 | M20: =N20*1000 -> 3548 | N20: 3.548 | O20: 20.9 | P20: 6 | Q20: =K20*('Temperature Corrections'!$D$9+'Temperature Corrections'!$D$10*'Data Entry'!$L20+('Temperature Corrections'!$D$11*('Data Entry'!$L20^2))+('Temperature Corrections'!$D$12*('Data Entry'!$L20^3))+('Temperature Corrections'!$D$13*('Data Entry'!$L20^4))+('Temperature Corrections'!$D$14*('Data Entry'!$L20^5)))/'Temperature Corrections'!$G$6 -> 44.706893 | R20: =N20*('Temperature Corrections'!$D$9+'Temperature Corrections'!$D$10*'Data Entry'!$O20+('Temperature Corrections'!$D$11*('Data Entry'!$O20^2))+('Temperature Corrections'!$D$12*('Data Entry'!$O20^3))+('Temperature Corrections'!$D$13*('Data Entry'!$O20^4))+('Temperature Corrections'!$D$14*('Data Entry'!$O20^5)))/'Temperature Corrections'!$G$6 -> 3.6160751 | S20: =Q20*(34.9994*'Salinity Corrections'!$I$22+'Salinity Corrections'!$I$23)/'Salinity Corrections'!$K$23 -> 44.706893 | T20: =R20*(P20*'Salinity Corrections'!$I$22+'Salinity Corrections'!$I$23)/'Salinity Corrections'!$K$23 -> 0.75358215 | U20: =S20/T20 -> 59.325838
A21: 501 | B21: 111 | C21: B | D21: 61 | E21: R | F21: 1 | G21: 37 | H21: =CONCATENATE("M0",B21,"-",C21, "-",D21, "-",F21) -> M0111-B-61-1 | I21: =VLOOKUP(H21,'Depth vlookup'!G20:I1067,2,FALSE)+G21/100 -> 175.98 | J21: 1 | K21: 43.5 | L21: 21.3 | M21: =N21*1000 -> 3382 | N21: 3.382 | O21: 20.9 | P21: 6 | Q21: =K21*('Temperature Corrections'!$D$9+'Temperature Corrections'!$D$10*'Data Entry'!$L21+('Temperature Corrections'!$D$11*('Data Entry'!$L21^2))+('Temperature Corrections'!$D$12*('Data Entry'!$L21^3))+('Temperature Corrections'!$D$13*('Data Entry'!$L21^4))+('Temperature Corrections'!$D$14*('Data Entry'!$L21^5)))/'Temperature Corrections'!$G$6 -> 44.706893 | R21: =N21*('Temperature Corrections'!$D$9+'Temperature Corrections'!$D$10*'Data Entry'!$O21+('Temperature Corrections'!$D$11*('Data Entry'!$O21^2))+('Temperature Corrections'!$D$12*('Data Entry'!$O21^3))+('Temperature Corrections'!$D$13*('Data Entry'!$O21^4))+('Temperature Corrections'!$D$14*('Data Entry'!$O21^5)))/'Temperature Corrections'!$G$6 -> 3.44689 | S21: =Q21*(34.9994*'Salinity Corrections'!$I$22+'Salinity Corrections'!$I$23)/'Salinity Corrections'!$K$23 -> 44.706893 | T21: =R21*(P21*'Salinity Corrections'!$I$22+'Salinity Corrections'!$I$23)/'Salinity Corrections'!$K$23 -> 0.71832437 | U21: =S21/T21 -> 62.237751
A22: 501 | B22: 111 | C22: B | D22: 64 | E22: R | F22: 1 | G22: 43 | H22: =CONCATENATE("M0",B22,"-",C22, "-",D22, "-",F22) -> M0111-B-64-1 | I22: =VLOOKUP(H22,'Depth vlookup'!G21:I1068,2,FALSE)+G22/100 -> 185.19 | J22: 1 | K22: 43.24 | L22: 21.2 | M22: =N22*1000 -> 2344 | N22: 2.344 | O22: 20.1 | P22: 6 | Q22: =K22*('Temperature Corrections'!$D$9+'Temperature Corrections'!$D$10*'Data Entry'!$L22+('Temperature Corrections'!$D$11*('Data Entry'!$L22^2))+('Temperature Corrections'!$D$12*('Data Entry'!$L22^3))+('Temperature Corrections'!$D$13*('Data Entry'!$L22^4))+('Temperature Corrections'!$D$14*('Data Entry'!$L22^5)))/'Temperature Corrections'!$G$6 -> 44.347097 | R22: =N22*('Temperature Corrections'!$D$9+'Temperature Corrections'!$D$10*'Data Entry'!$O22+('Temperature Corrections'!$D$11*('Data Entry'!$O22^2))+('Temperature Corrections'!$D$12*('Data Entry'!$O22^3))+('Temperature Corrections'!$D$13*('Data Entry'!$O22^4))+('Temperature Corrections'!$D$14*('Data Entry'!$O22^5)))/'Temperature Corrections'!$G$6 -> 2.3489858 | S22: =Q22*(34.9994*'Salinity Corrections'!$I$22+'Salinity Corrections'!$I$23)/'Salinity Corrections'!$K$23 -> 44.347097 | T22: =R22*(P22*'Salinity Corrections'!$I$22+'Salinity Corrections'!$I$23)/'Salinity Corrections'!$K$23 -> 0.48952353 | U22: =S22/T22 -> 90.59237
A23: 501 | B23: 111 | C23: B | D23: 64 | E23: R | F23: 1 | G23: 45 | H23: =CONCATENATE("M0",B23,"-",C23, "-",D23, "-",F23) -> M0111-B-64-1 | I23: =VLOOKUP(H23,'Depth vlookup'!G22:I1069,2,FALSE)+G23/100 -> 185.21 | J23: 1 | K23: 43.23 | L23: 21.2 | M23: =N23*1000 -> 2320 | N23: 2.32 | O23: 20.2 | P23: 6 | Q23: =K23*('Temperature Corrections'!$D$9+'Temperature Corrections'!$D$10*'Data Entry'!$L23+('Temperature Corrections'!$D$11*('Data Entry'!$L23^2))+('Temperature Corrections'!$D$12*('Data Entry'!$L23^3))+('Temperature Corrections'!$D$13*('Data Entry'!$L23^4))+('Temperature Corrections'!$D$14*('Data Entry'!$L23^5)))/'Temperature Corrections'!$G$6 -> 44.33684 | R23: =N23*('Temperature Corrections'!$D$9+'Temperature Corrections'!$D$10*'Data Entry'!$O23+('Temperature Corrections'!$D$11*('Data Entry'!$O23^2))+('Temperature Corrections'!$D$12*('Data Entry'!$O23^3))+('Temperature Corrections'!$D$13*('Data Entry'!$O23^4))+('Temperature Corrections'!$D$14*('Data Entry'!$O23^5)))/'Temperature Corrections'!$G$6 -> 2.3298724 | S23: =Q23*(34.9994*'Salinity Corrections'!$I$22+'Salinity Corrections'!$I$23)/'Salinity Corrections'!$K$23 -> 44.33684 | T23: =R23*(P23*'Salinity Corrections'!$I$22+'Salinity Corrections'!$I$23)/'Salinity Corrections'!$K$23 -> 0.48554033 | U23: =S23/T23 -> 91.314434
A24: 501 | B24: 111 | C24: B | D24: 67 | E24: R | F24: 1 | G24: 29 | H24: =CONCATENATE("M0",B24,"-",C24, "-",D24, "-",F24) -> M0111-B-67-1 | I24: =VLOOKUP(H24,'Depth vlookup'!G23:I1070,2,FALSE)+G24/100 -> 194.2 | J24: 1 | K24: 42.84 | L24: 20.8 | M24: =N24*1000 -> 3002 | N24: 3.002 | O24: 19.9 | P24: 6 | Q24: =K24*('Temperature Corrections'!$D$9+'Temperature Corrections'!$D$10*'Data Entry'!$L24+('Temperature Corrections'!$D$11*('Data Entry'!$L24^2))+('Temperature Corrections'!$D$12*('Data Entry'!$L24^3))+('Temperature Corrections'!$D$13*('Data Entry'!$L24^4))+('Temperature Corrections'!$D$14*('Data Entry'!$L24^5)))/'Temperature Corrections'!$G$6 -> 43.570434 | R24: =N24*('Temperature Corrections'!$D$9+'Temperature Corrections'!$D$10*'Data Entry'!$O24+('Temperature Corrections'!$D$11*('Data Entry'!$O24^2))+('Temperature Corrections'!$D$12*('Data Entry'!$O24^3))+('Temperature Corrections'!$D$13*('Data Entry'!$O24^4))+('Temperature Corrections'!$D$14*('Data Entry'!$O24^5)))/'Temperature Corrections'!$G$6 -> 2.9956183 | S24: =Q24*(34.9994*'Salinity Corrections'!$I$22+'Salinity Corrections'!$I$23)/'Salinity Corrections'!$K$23 -> 43.570434 | T24: =R24*(P24*'Salinity Corrections'!$I$22+'Salinity Corrections'!$I$23)/'Salinity Corrections'!$K$23 -> 0.62428031 | U24: =S24/T24 -> 69.793062
A25: 501 | B25: 111 | C25: B | D25: 67 | E25: R | F25: 1 | G25: 32 | H25: =CONCATENATE("M0",B25,"-",C25, "-",D25, "-",F25) -> M0111-B-67-1 | I25: =VLOOKUP(H25,'Depth vlookup'!G24:I1071,2,FALSE)+G25/100 -> 194.23 | J25: 1 | K25: 42.8 | L25: 20.8 | M25: =N25*1000 -> 2990 | N25: 2.99 | O25: 19.7 | P25: 6 | Q25: =K25*('Temperature Corrections'!$D$9+'Temperature Corrections'!$D$10*'Data Entry'!$L25+('Temperature Corrections'!$D$11*('Data Entry'!$L25^2))+('Temperature Corrections'!$D$12*('Data Entry'!$L25^3))+('Temperature Corrections'!$D$13*('Data Entry'!$L25^4))+('Temperature Corrections'!$D$14*('Data Entry'!$L25^5)))/'Temperature Corrections'!$G$6 -> 43.529752 | R25: =N25*('Temperature Corrections'!$D$9+'Temperature Corrections'!$D$10*'Data Entry'!$O25+('Temperature Corrections'!$D$11*('Data Entry'!$O25^2))+('Temperature Corrections'!$D$12*('Data Entry'!$O25^3))+('Temperature Corrections'!$D$13*('Data Entry'!$O25^4))+('Temperature Corrections'!$D$14*('Data Entry'!$O25^5)))/'Temperature Corrections'!$G$6 -> 2.9709425 | S25: =Q25*(34.9994*'Salinity Corrections'!$I$22+'Salinity Corrections'!$I$23)/'Salinity Corrections'!$K$23 -> 43.529752 | T25: =R25*(P25*'Salinity Corrections'!$I$22+'Salinity Corrections'!$I$23)/'Salinity Corrections'!$K$23 -> 0.61913794 | U25: =S25/T25 -> 70.307034
A26: 501 | B26: 111 | C26: B | D26: 71 | E26: R | F26: 1 | G26: 3 | H26: =CONCATENATE("M0",B26,"-",C26, "-",D26, "-",F26) -> M0111-B-71-1 | I26: =VLOOKUP(H26,'Depth vlookup'!G25:I1072,2,FALSE)+G26/100 -> 206.14 | J26: 1 | K26: 43.03 | L26: 21.1 | M26: =N26*1000 -> 4100 | N26: 4.1 | O26: 21.8 | P26: 6 | Q26: =K26*('Temperature Corrections'!$D$9+'Temperature Corrections'!$D$10*'Data Entry'!$L26+('Temperature Corrections'!$D$11*('Data Entry'!$L26^2))+('Temperature Corrections'!$D$12*('Data Entry'!$L26^3))+('Temperature Corrections'!$D$13*('Data Entry'!$L26^4))+('Temperature Corrections'!$D$14*('Data Entry'!$L26^5)))/'Temperature Corrections'!$G$6 -> 44.039635 | R26: =N26*('Temperature Corrections'!$D$9+'Temperature Corrections'!$D$10*'Data Entry'!$O26+('Temperature Corrections'!$D$11*('Data Entry'!$O26^2))+('Temperature Corrections'!$D$12*('Data Entry'!$O26^3))+('Temperature Corrections'!$D$13*('Data Entry'!$O26^4))+('Temperature Corrections'!$D$14*('Data Entry'!$O26^5)))/'Temperature Corrections'!$G$6 -> 4.2577139 | S26: =Q26*(34.9994*'Salinity Corrections'!$I$22+'Salinity Corrections'!$I$23)/'Salinity Corrections'!$K$23 -> 44.039635 | T26: =R26*(P26*'Salinity Corrections'!$I$22+'Salinity Corrections'!$I$23)/'Salinity Corrections'!$K$23 -> 0.8872983 | U26: =S26/T26 -> 49.633404
A27: 501 | B27: 111 | C27: B | D27: 71 | E27: R | F27: 1 | G27: 7 | H27: =CONCATENATE("M0",B27,"-",C27, "-",D27, "-",F27) -> M0111-B-71-1 | I27: =VLOOKUP(H27,'Depth vlookup'!G26:I1073,2,FALSE)+G27/100 -> 206.18 | J27: 1 | K27: 43 | L27: 21.1 | M27: =N27*1000 -> 4015 | N27: 4.015 | O27: 21.7 | P27: 6 | Q27: =K27*('Temperature Corrections'!$D$9+'Temperature Corrections'!$D$10*'Data Entry'!$L27+('Temperature Corrections'!$D$11*('Data Entry'!$L27^2))+('Temperature Corrections'!$D$12*('Data Entry'!$L27^3))+('Temperature Corrections'!$D$13*('Data Entry'!$L27^4))+('Temperature Corrections'!$D$14*('Data Entry'!$L27^5)))/'Temperature Corrections'!$G$6 -> 44.008931 | R27: =N27*('Temperature Corrections'!$D$9+'Temperature Corrections'!$D$10*'Data Entry'!$O27+('Temperature Corrections'!$D$11*('Data Entry'!$O27^2))+('Temperature Corrections'!$D$12*('Data Entry'!$O27^3))+('Temperature Corrections'!$D$13*('Data Entry'!$O27^4))+('Temperature Corrections'!$D$14*('Data Entry'!$O27^5)))/'Temperature Corrections'!$G$6 -> 4.1608257 | S27: =Q27*(34.9994*'Salinity Corrections'!$I$22+'Salinity Corrections'!$I$23)/'Salinity Corrections'!$K$23 -> 44.008931 | T27: =R27*(P27*'Salinity Corrections'!$I$22+'Salinity Corrections'!$I$23)/'Salinity Corrections'!$K$23 -> 0.86710699 | U27: =S27/T27 -> 50.753749
A28: 501 | B28: 111 | C28: B | D28: 87 | E28: R | F28: 1 | G28: 41 | H28: =CONCATENATE("M0",B28,"-",C28, "-",D28, "-",F28) -> M0111-B-87-1 | I28: =VLOOKUP(H28,'Depth vlookup'!G27:I1074,2,FALSE)+G28/100 -> 234.14 | J28: 1 | K28: 43 | L28: 21.2 | M28: =N28*1000 -> 3383 | N28: 3.383 | O28: 20.5 | P28: 6 | Q28: =K28*('Temperature Corrections'!$D$9+'Temperature Corrections'!$D$10*'Data Entry'!$L28+('Temperature Corrections'!$D$11*('Data Entry'!$L28^2))+('Temperature Corrections'!$D$12*('Data Entry'!$L28^3))+('Temperature Corrections'!$D$13*('Data Entry'!$L28^4))+('Temperature Corrections'!$D$14*('Data Entry'!$L28^5)))/'Temperature Corrections'!$G$6 -> 44.100952 | R28: =N28*('Temperature Corrections'!$D$9+'Temperature Corrections'!$D$10*'Data Entry'!$O28+('Temperature Corrections'!$D$11*('Data Entry'!$O28^2))+('Temperature Corrections'!$D$12*('Data Entry'!$O28^3))+('Temperature Corrections'!$D$13*('Data Entry'!$O28^4))+('Temperature Corrections'!$D$14*('Data Entry'!$O28^5)))/'Temperature Corrections'!$G$6 -> 3.4190204 | S28: =Q28*(34.9994*'Salinity Corrections'!$I$22+'Salinity Corrections'!$I$23)/'Salinity Corrections'!$K$23 -> 44.100952 | T28: =R28*(P28*'Salinity Corrections'!$I$22+'Salinity Corrections'!$I$23)/'Salinity Corrections'!$K$23 -> 0.7125164 | U28: =S28/T28 -> 61.894648
A29: 501 | B29: 111 | C29: B | D29: 87 | E29: R | F29: 1 | G29: 43 | H29: =CONCATENATE("M0",B29,"-",C29, "-",D29, "-",F29) -> M0111-B-87-1 | I29: =VLOOKUP(H29,'Depth vlookup'!G28:I1075,2,FALSE)+G29/100 -> 234.16 | J29: 1 | K29: 43 | L29: 21.2 | M29: =N29*1000 -> 3524 | N29: 3.524 | O29: 20.4 | P29: 6 | Q29: =K29*('Temperature Corrections'!$D$9+'Temperature Corrections'!$D$10*'Data Entry'!$L29+('Temperature Corrections'!$D$11*('Data Entry'!$L29^2))+('Temperature Corrections'!$D$12*('Data Entry'!$L29^3))+('Temperature Corrections'!$D$13*('Data Entry'!$L29^4))+('Temperature Corrections'!$D$14*('Data Entry'!$L29^5)))/'Temperature Corrections'!$G$6 -> 44.100952 | R29: =N29*('Temperature Corrections'!$D$9+'Temperature Corrections'!$D$10*'Data Entry'!$O29+('Temperature Corrections'!$D$11*('Data Entry'!$O29^2))+('Temperature Corrections'!$D$12*('Data Entry'!$O29^3))+('Temperature Corrections'!$D$13*('Data Entry'!$O29^4))+('Temperature Corrections'!$D$14*('Data Entry'!$O29^5)))/'Temperature Corrections'!$G$6 -> 3.5540089 | S29: =Q29*(34.9994*'Salinity Corrections'!$I$22+'Salinity Corrections'!$I$23)/'Salinity Corrections'!$K$23 -> 44.100952 | T29: =R29*(P29*'Salinity Corrections'!$I$22+'Salinity Corrections'!$I$23)/'Salinity Corrections'!$K$23 -> 0.7406477 | U29: =S29/T29 -> 59.543764
A30: 501 | B30: 111 | C30: B | D30: 93 | E30: R | F30: 1 | G30: 41 | H30: =CONCATENATE("M0",B30,"-",C30, "-",D30, "-",F30) -> M0111-B-93-1 | I30: =VLOOKUP(H30,'Depth vlookup'!G29:I1076,2,FALSE)+G30/100 -> 245.69 | J30: 1 | K30: 42.75 | L30: 21.1 | M30: =N30*1000 -> 2463 | N30: 2.463 | O30: 18.9 | P30: 6 | Q30: =K30*('Temperature Corrections'!$D$9+'Temperature Corrections'!$D$10*'Data Entry'!$L30+('Temperature Corrections'!$D$11*('Data Entry'!$L30^2))+('Temperature Corrections'!$D$12*('Data Entry'!$L30^3))+('Temperature Corrections'!$D$13*('Data Entry'!$L30^4))+('Temperature Corrections'!$D$14*('Data Entry'!$L30^5)))/'Temperature Corrections'!$G$6 -> 43.753065 | R30: =N30*('Temperature Corrections'!$D$9+'Temperature Corrections'!$D$10*'Data Entry'!$O30+('Temperature Corrections'!$D$11*('Data Entry'!$O30^2))+('Temperature Corrections'!$D$12*('Data Entry'!$O30^3))+('Temperature Corrections'!$D$13*('Data Entry'!$O30^4))+('Temperature Corrections'!$D$14*('Data Entry'!$O30^5)))/'Temperature Corrections'!$G$6 -> 2.4055776 | S30: =Q30*(34.9994*'Salinity Corrections'!$I$22+'Salinity Corrections'!$I$23)/'Salinity Corrections'!$K$23 -> 43.753065 | T30: =R30*(P30*'Salinity Corrections'!$I$22+'Salinity Corrections'!$I$23)/'Salinity Corrections'!$K$23 -> 0.50131713 | U30: =S30/T30 -> 87.276222
A31: 501 | B31: 111 | C31: B | D31: 93 | E31: R | F31: 1 | G31: 43 | H31: =CONCATENATE("M0",B31,"-",C31, "-",D31, "-",F31) -> M0111-B-93-1 | I31: =VLOOKUP(H31,'Depth vlookup'!G30:I1077,2,FALSE)+G31/100 -> 245.71 | J31: 1 | K31: 42.75 | L31: 21.1 | M31: =N31*1000 -> 2319 | N31: 2.319 | O31: 19 | P31: 6 | Q31: =K31*('Temperature Corrections'!$D$9+'Temperature Corrections'!$D$10*'Data Entry'!$L31+('Temperature Corrections'!$D$11*('Data Entry'!$L31^2))+('Temperature Corrections'!$D$12*('Data Entry'!$L31^3))+('Temperature Corrections'!$D$13*('Data Entry'!$L31^4))+('Temperature Corrections'!$D$14*('Data Entry'!$L31^5)))/'Temperature Corrections'!$G$6 -> 43.753065 | R31: =N31*('Temperature Corrections'!$D$9+'Temperature Corrections'!$D$10*'Data Entry'!$O31+('Temperature Corrections'!$D$11*('Data Entry'!$O31^2))+('Temperature Corrections'!$D$12*('Data Entry'!$O31^3))+('Temperature Corrections'!$D$13*('Data Entry'!$O31^4))+('Temperature Corrections'!$D$14*('Data Entry'!$O31^5)))/'Temperature Corrections'!$G$6 -> 2.2698347 | S31: =Q31*(34.9994*'Salinity Corrections'!$I$22+'Salinity Corrections'!$I$23)/'Salinity Corrections'!$K$23 -> 43.753065 | T31: =R31*(P31*'Salinity Corrections'!$I$22+'Salinity Corrections'!$I$23)/'Salinity Corrections'!$K$23 -> 0.47302861 | U31: =S31/T31 -> 92.4956
... A51: 501 | B51: 111 | C51: C | D51: 11 | E51: R | F51: 1 | G51: 33 | H51: =CONCATENATE("M0",B51,"-",C51, "-",D51, "-",F51) -> M0111-C-11-1 | I51: =VLOOKUP(H51,'Depth vlookup'!G50:I1097,2,FALSE)+G51/100 -> 153.33 | J51: 1 | K51: 40.38 | L51: 20.4 | M51: =N51*1000 -> 3340 | N51: 3.34 | O51: 9.7 | P51: 6 | Q51: =K51*('Temperature Corrections'!$D$9+'Temperature Corrections'!$D$10*'Data Entry'!$L51+('Temperature Corrections'!$D$11*('Data Entry'!$L51^2))+('Temperature Corrections'!$D$12*('Data Entry'!$L51^3))+('Temperature Corrections'!$D$13*('Data Entry'!$L51^4))+('Temperature Corrections'!$D$14*('Data Entry'!$L51^5)))/'Temperature Corrections'!$G$6 -> 40.723859 | R51: =N51*('Temperature Corrections'!$D$9+'Temperature Corrections'!$D$10*'Data Entry'!$O51+('Temperature Corrections'!$D$11*('Data Entry'!$O51^2))+('Temperature Corrections'!$D$12*('Data Entry'!$O51^3))+('Temperature Corrections'!$D$13*('Data Entry'!$O51^4))+('Temperature Corrections'!$D$14*('Data Entry'!$O51^5)))/'Temperature Corrections'!$G$6 -> 2.6357848 | S51: =Q51*(34.9994*'Salinity Corrections'!$I$22+'Salinity Corrections'!$I$23)/'Salinity Corrections'!$K$23 -> 40.723859 | T51: =R51*(P51*'Salinity Corrections'!$I$22+'Salinity Corrections'!$I$23)/'Salinity Corrections'!$K$23 -> 0.5492918 | U51: =S51/T51 -> 74.138843
A52: Pure Reference Liquid (Electrode 1) | H52: =CONCATENATE("M0",B52,"-",C52, "-",D52, "-",F52) -> M0--- | J52: 1 | M52: =N52*1000 -> 44040 | N52: 44.04 | O52: 20.6
A53: Pure Reference Liquid (Electrode 2) | H53: =CONCATENATE("M0",B53,"-",C53, "-",D53, "-",F53) -> M0--- | J53: 2 | M53: =N53*1000 -> 50090 | N53: 50.09 | O53: 20.6
A54: 501 | B54: 111 | C54: C | D54: 20 | E54: R | F54: 1 | G54: 61 | H54: =CONCATENATE("M0",B54,"-",C54, "-",D54, "-",F54) -> M0111-C-20-1 | I54: =VLOOKUP(H54,'Depth vlookup'!G53:I1100,2,FALSE)+G54/100 -> 171.97 | J54: 2 | K54: 45.26 | L54: 20.6 | M54: =N54*1000 -> 5114 | N54: 5.114 | O54: 20.1 | P54: 6 | Q54: =K54*('Temperature Corrections'!$D$9+'Temperature Corrections'!$D$10*'Data Entry'!$L54+('Temperature Corrections'!$D$11*('Data Entry'!$L54^2))+('Temperature Corrections'!$D$12*('Data Entry'!$L54^3))+('Temperature Corrections'!$D$13*('Data Entry'!$L54^4))+('Temperature Corrections'!$D$14*('Data Entry'!$L54^5)))/'Temperature Corrections'!$G$6 -> 45.838449 | R54: =N54*('Temperature Corrections'!$D$9+'Temperature Corrections'!$D$10*'Data Entry'!$O54+('Temperature Corrections'!$D$11*('Data Entry'!$O54^2))+('Temperature Corrections'!$D$12*('Data Entry'!$O54^3))+('Temperature Corrections'!$D$13*('Data Entry'!$O54^4))+('Temperature Corrections'!$D$14*('Data Entry'!$O54^5)))/'Temperature Corrections'!$G$6 -> 5.1248778 | S54: =Q54*(34.9994*'Salinity Corrections'!$I$22+'Salinity Corrections'!$I$23)/'Salinity Corrections'!$K$23 -> 45.838449 | T54: =R54*(P54*'Salinity Corrections'!$I$22+'Salinity Corrections'!$I$23)/'Salinity Corrections'!$K$23 -> 1.0680134 | U54: =S54/T54 -> 42.919359
A55: 501 | B55: 111 | C55: C | D55: 20 | E55: R | F55: 1 | G55: 62 | H55: =CONCATENATE("M0",B55,"-",C55, "-",D55, "-",F55) -> M0111-C-20-1 | I55: =VLOOKUP(H55,'Depth vlookup'!G54:I1101,2,FALSE)+G55/100 -> 171.98 | J55: 2 | K55: 45.26 | L55: 20.6 | M55: =N55*1000 -> 4512 | N55: 4.512 | O55: 20.1 | P55: 6 | Q55: =K55*('Temperature Corrections'!$D$9+'Temperature Corrections'!$D$10*'Data Entry'!$L55+('Temperature Corrections'!$D$11*('Data Entry'!$L55^2))+('Temperature Corrections'!$D$12*('Data Entry'!$L55^3))+('Temperature Corrections'!$D$13*('Data Entry'!$L55^4))+('Temperature Corrections'!$D$14*('Data Entry'!$L55^5)))/'Temperature Corrections'!$G$6 -> 45.838449 | R55: =N55*('Temperature Corrections'!$D$9+'Temperature Corrections'!$D$10*'Data Entry'!$O55+('Temperature Corrections'!$D$11*('Data Entry'!$O55^2))+('Temperature Corrections'!$D$12*('Data Entry'!$O55^3))+('Temperature Corrections'!$D$13*('Data Entry'!$O55^4))+('Temperature Corrections'!$D$14*('Data Entry'!$O55^5)))/'Temperature Corrections'!$G$6 -> 4.5215973 | S55: =Q55*(34.9994*'Salinity Corrections'!$I$22+'Salinity Corrections'!$I$23)/'Salinity Corrections'!$K$23 -> 45.838449 | T55: =R55*(P55*'Salinity Corrections'!$I$22+'Salinity Corrections'!$I$23)/'Salinity Corrections'!$K$23 -> 0.94229102 | U55: =S55/T55 -> 48.645745
A56: 501 | B56: 111 | C56: C | D56: 21 | E56: R | F56: 2 | G56: 147.5 | H56: =CONCATENATE("M0",B56,"-",C56, "-",D56, "-",F56) -> M0111-C-21-2 | I56: =VLOOKUP(H56,'Depth vlookup'!G55:I1102,2,FALSE)+G56/100 -> 180.355 | J56: 2 | K56: 45.25 | L56: 20.7 | M56: =N56*1000 -> 4442 | N56: 4.442 | O56: 20 | P56: 6 | Q56: =K56*('Temperature Corrections'!$D$9+'Temperature Corrections'!$D$10*'Data Entry'!$L56+('Temperature Corrections'!$D$11*('Data Entry'!$L56^2))+('Temperature Corrections'!$D$12*('Data Entry'!$L56^3))+('Temperature Corrections'!$D$13*('Data Entry'!$L56^4))+('Temperature Corrections'!$D$14*('Data Entry'!$L56^5)))/'Temperature Corrections'!$G$6 -> 45.924897 | R56: =N56*('Temperature Corrections'!$D$9+'Temperature Corrections'!$D$10*'Data Entry'!$O56+('Temperature Corrections'!$D$11*('Data Entry'!$O56^2))+('Temperature Corrections'!$D$12*('Data Entry'!$O56^3))+('Temperature Corrections'!$D$13*('Data Entry'!$O56^4))+('Temperature Corrections'!$D$14*('Data Entry'!$O56^5)))/'Temperature Corrections'!$G$6 -> 4.442 | S56: =Q56*(34.9994*'Salinity Corrections'!$I$22+'Salinity Corrections'!$I$23)/'Salinity Corrections'!$K$23 -> 45.924897 | T56: =R56*(P56*'Salinity Corrections'!$I$22+'Salinity Corrections'!$I$23)/'Salinity Corrections'!$K$23 -> 0.92570311 | U56: =S56/T56 -> 49.610827
A57: 501 | B57: 111 | C57: C | D57: 21 | E57: R | F57: 2 | G57: 150 | H57: =CONCATENATE("M0",B57,"-",C57, "-",D57, "-",F57) -> M0111-C-21-2 | I57: =VLOOKUP(H57,'Depth vlookup'!G56:I1103,2,FALSE)+G57/100 -> 180.38 | J57: 2 | K57: 45.25 | L57: 20.7 | M57: =N57*1000 -> 4182 | N57: 4.182 | O57: 19.8 | P57: 6 | Q57: =K57*('Temperature Corrections'!$D$9+'Temperature Corrections'!$D$10*'Data Entry'!$L57+('Temperature Corrections'!$D$11*('Data Entry'!$L57^2))+('Temperature Corrections'!$D$12*('Data Entry'!$L57^3))+('Temperature Corrections'!$D$13*('Data Entry'!$L57^4))+('Temperature Corrections'!$D$14*('Data Entry'!$L57^5)))/'Temperature Corrections'!$G$6 -> 45.924897 | R57: =N57*('Temperature Corrections'!$D$9+'Temperature Corrections'!$D$10*'Data Entry'!$O57+('Temperature Corrections'!$D$11*('Data Entry'!$O57^2))+('Temperature Corrections'!$D$12*('Data Entry'!$O57^3))+('Temperature Corrections'!$D$13*('Data Entry'!$O57^4))+('Temperature Corrections'!$D$14*('Data Entry'!$O57^5)))/'Temperature Corrections'!$G$6 -> 4.1642248 | S57: =Q57*(34.9994*'Salinity Corrections'!$I$22+'Salinity Corrections'!$I$23)/'Salinity Corrections'!$K$23 -> 45.924897 | T57: =R57*(P57*'Salinity Corrections'!$I$22+'Salinity Corrections'!$I$23)/'Salinity Corrections'!$K$23 -> 0.86781536 | U57: =S57/T57 -> 52.920124
A58: 501 | B58: 111 | C58: C | D58: 26 | E58: R | F58: 1 | G58: 41 | H58: =CONCATENATE("M0",B58,"-",C58, "-",D58, "-",F58) -> M0111-C-26-1 | I58: =VLOOKUP(H58,'Depth vlookup'!G57:I1104,2,FALSE)+G58/100 -> 195.77 | J58: 2 | K58: 44.93 | L58: 21 | M58: =N58*1000 -> 3800 | N58: 3.8 | O58: 20 | P58: 6 | Q58: =K58*('Temperature Corrections'!$D$9+'Temperature Corrections'!$D$10*'Data Entry'!$L58+('Temperature Corrections'!$D$11*('Data Entry'!$L58^2))+('Temperature Corrections'!$D$12*('Data Entry'!$L58^3))+('Temperature Corrections'!$D$13*('Data Entry'!$L58^4))+('Temperature Corrections'!$D$14*('Data Entry'!$L58^5)))/'Temperature Corrections'!$G$6 -> 45.888116 | R58: =N58*('Temperature Corrections'!$D$9+'Temperature Corrections'!$D$10*'Data Entry'!$O58+('Temperature Corrections'!$D$11*('Data Entry'!$O58^2))+('Temperature Corrections'!$D$12*('Data Entry'!$O58^3))+('Temperature Corrections'!$D$13*('Data Entry'!$O58^4))+('Temperature Corrections'!$D$14*('Data Entry'!$O58^5)))/'Temperature Corrections'!$G$6 -> 3.8 | S58: =Q58*(34.9994*'Salinity Corrections'!$I$22+'Salinity Corrections'!$I$23)/'Salinity Corrections'!$K$23 -> 45.888116 | T58: =R58*(P58*'Salinity Corrections'!$I$22+'Salinity Corrections'!$I$23)/'Salinity Corrections'!$K$23 -> 0.79191171 | U58: =S58/T58 -> 57.945999
A59: 501 | B59: 111 | C59: C | D59: 26 | E59: R | F59: 1 | G59: 41 | H59: =CONCATENATE("M0",B59,"-",C59, "-",D59, "-",F59) -> M0111-C-26-1 | I59: =VLOOKUP(H59,'Depth vlookup'!G58:I1105,2,FALSE)+G59/100 -> 195.77 | J59: 2 | K59: 44.93 | L59: 21 | M59: =N59*1000 -> 3607 | N59: 3.607 | O59: 19.9 | P59: 6 | Q59: =K59*('Temperature Corrections'!$D$9+'Temperature Corrections'!$D$10*'Data Entry'!$L59+('Temperature Corrections'!$D$11*('Data Entry'!$L59^2))+('Temperature Corrections'!$D$12*('Data Entry'!$L59^3))+('Temperature Corrections'!$D$13*('Data Entry'!$L59^4))+('Temperature Corrections'!$D$14*('Data Entry'!$L59^5)))/'Temperature Corrections'!$G$6 -> 45.888116 | R59: =N59*('Temperature Corrections'!$D$9+'Temperature Corrections'!$D$10*'Data Entry'!$O59+('Temperature Corrections'!$D$11*('Data Entry'!$O59^2))+('Temperature Corrections'!$D$12*('Data Entry'!$O59^3))+('Temperature Corrections'!$D$13*('Data Entry'!$O59^4))+('Temperature Corrections'!$D$14*('Data Entry'!$O59^5)))/'Temperature Corrections'!$G$6 -> 3.5993321 | S59: =Q59*(34.9994*'Salinity Corrections'!$I$22+'Salinity Corrections'!$I$23)/'Salinity Corrections'!$K$23 -> 45.888116 | T59: =R59*(P59*'Salinity Corrections'!$I$22+'Salinity Corrections'!$I$23)/'Salinity Corrections'!$K$23 -> 0.75009297 | U59: =S59/T59 -> 61.176571
...

Sheet Depth vlookup
A1: Expedition | B1: Site | C1: Hole | D1: Core | E1: Type | F1: Section | G1: Combined | H1: top_depth | I1: bottom_depth
A2: 501 | B2: M0111 | C2: A | D2: 1 | E2: H | F2: 1 | G2: =CONCATENATE(B2, "-",C2, "-", D2, "-", F2) -> M0111-A-1-1 | H2: 0 | I2: 1.5
A3: 501 | B3: M0111 | C3: A | D3: 1 | E3: H | F3: 2 | G3: =CONCATENATE(B3, "-",C3, "-", D3, "-", F3) -> M0111-A-1-2 | H3: 1.5 | I3: 2.9
A4: 501 | B4: M0111 | C4: A | D4: 2 | E4: H | F4: 1 | G4: =CONCATENATE(B4, "-",C4, "-", D4, "-", F4) -> M0111-A-2-1 | H4: 2.4 | I4: 3.91
A5: 501 | B5: M0111 | C5: A | D5: 2 | E5: H | F5: 2 | G5: =CONCATENATE(B5, "-",C5, "-", D5, "-", F5) -> M0111-A-2-2 | H5: 3.91 | I5: 4.99
A6: 501 | B6: M0111 | C6: A | D6: 3 | E6: H | F6: 1 | G6: =CONCATENATE(B6, "-",C6, "-", D6, "-", F6) -> M0111-A-3-1 | H6: 4.46 | I6: 5.97
A7: 501 | B7: M0111 | C7: A | D7: 3 | E7: H | F7: 2 | G7: =CONCATENATE(B7, "-",C7, "-", D7, "-", F7) -> M0111-A-3-2 | H7: 5.97 | I7: 7.1
A8: 501 | B8: M0111 | C8: A | D8: 4 | E8: H | F8: 1 | G8: =CONCATENATE(B8, "-",C8, "-", D8, "-", F8) -> M0111-A-4-1 | H8: 6.89 | I8: 8.4
A9: 501 | B9: M0111 | C9: A | D9: 4 | E9: H | F9: 2 | G9: =CONCATENATE(B9, "-",C9, "-", D9, "-", F9) -> M0111-A-4-2 | H9: 8.4 | I9: 9.6
A10: 501 | B10: M0111 | C10: A | D10: 5 | E10: H | F10: 1 | G10: =CONCATENATE(B10, "-",C10, "-", D10, "-", F10) -> M0111-A-5-1 | H10: 9.6 | I10: 11.1
A11: 501 | B11: M0111 | C11: A | D11: 5 | E11: H | F11: 2 | G11: =CONCATENATE(B11, "-",C11, "-", D11, "-", F11) -> M0111-A-5-2 | H11: 11.1 | I11: 12.05
A12: 501 | B12: M0111 | C12: A | D12: 6 | E12: H | F12: 1 | G12: =CONCATENATE(B12, "-",C12, "-", D12, "-", F12) -> M0111-A-6-1 | H12: 11.7 | I12: 13.2
A13: 501 | B13: M0111 | C13: A | D13: 6 | E13: H | F13: 2 | G13: =CONCATENATE(B13, "-",C13, "-", D13, "-", F13) -> M0111-A-6-2 | H13: 13.2 | I13: 13.94
... A259: 501 | B259: M0111 | C259: B | D259: 139 | E259: R | F259: 1 | G259: =CONCATENATE(B259, "-",C259, "-", D259, "-", F259) -> M0111-B-139-1 | H259: 336.33 | I259: 337.24
A260: 501 | B260: M0111 | C260: B | D260: 140 | E260: R | F260: 1 | G260: =CONCATENATE(B260, "-",C260, "-", D260, "-", F260) -> M0111-B-140-1 | H260: 338.03 | I260: 338.65 | T260: 368.83
A261: 501 | B261: M0111 | C261: B | D261: 141 | E261: R | F261: 1 | G261: =CONCATENATE(B261, "-",C261, "-", D261, "-", F261) -> M0111-B-141-1 | H261: 339.68 | I261: 339.81 | T261: 371.23
A262: 501 | B262: M0111 | C262: B | D262: 144 | E262: R | F262: 1 | G262: =CONCATENATE(B262, "-",C262, "-", D262, "-", F262) -> M0111-B-144-1 | H262: 344.43 | I262: 344.89 | T262: 373.93
A263: 501 | B263: M0111 | C263: B | D263: 146 | E263: R | F263: 1 | G263: =CONCATENATE(B263, "-",C263, "-", D263, "-", F263) -> M0111-B-146-1 | H263: 345.78 | I263: 345.82 | T263: 374.93
A264: 501 | B264: M0111 | C264: B | D264: 147 | E264: R | F264: 1 | G264: =CONCATENATE(B264, "-",C264, "-", D264, "-", F264) -> M0111-B-147-1 | H264: 346.13 | I264: 346.57
A265: 501 | B265: M0111 | C265: B | D265: 149 | E265: R | F265: 1 | G265: =CONCATENATE(B265, "-",C265, "-", D265, "-", F265) -> M0111-B-149-1 | H265: 348.03 | I265: 349.15
A266: 501 | B266: M0111 | C266: B | D266: 150 | E266: R | F266: 1 | G266: =CONCATENATE(B266, "-",C266, "-", D266, "-", F266) -> M0111-B-150-1 | H266: 349.03 | I266: 349.13
A267: 501 | B267: M0111 | C267: B | D267: 151 | E267: R | F267: 1 | G267: =CONCATENATE(B267, "-",C267, "-", D267, "-", F267) -> M0111-B-151-1 | H267: 350.03 | I267: 350.67
A268: 501 | B268: M0111 | C268: B | D268: 152 | E268: R | F268: 1 | G268: =CONCATENATE(B268, "-",C268, "-", D268, "-", F268) -> M0111-B-152-1 | H268: 351.28 | I268: 351.62
A269: 501 | B269: M0111 | C269: B | D269: 154 | E269: R | F269: 1 | G269: =CONCATENATE(B269, "-",C269, "-", D269, "-", F269) -> M0111-B-154-1 | H269: 353.58 | I269: 353.81
A270: 501 | B270: M0111 | C270: B | D270: 155 | E270: R | F270: 1 | G270: =CONCATENATE(B270, "-",C270, "-", D270, "-", F270) -> M0111-B-155-1 | H270: 355.55 | I270: 356.52
A271: 501 | B271: M0111 | C271: B | D271: 156 | E271: R | F271: 1 | G271: =CONCATENATE(B271, "-",C271, "-", D271, "-", F271) -> M0111-B-156-1 | H271: 358.6 | I271: 358.75
A272: 501 | B272: M0111 | C272: B | D272: 157 | E272: R | F272: 1 | G272: =CONCATENATE(B272, "-",C272, "-", D272, "-", F272) -> M0111-B-157-1 | H272: 360.83 | I272: 361.57
A273: 501 | B273: M0111 | C273: B | D273: 158 | E273: R | F273: 1 | G273: =CONCATENATE(B273, "-",C273, "-", D273, "-", F273) -> M0111-B-158-1 | H273: 361.73 | I273: 362.35
A274: 501 | B274: M0111 | C274: B | D274: 158 | E274: R | F274: 2 | G274: =CONCATENATE(B274, "-",C274, "-", D274, "-", F274) -> M0111-B-158-2 | H274: 362.35 | I274: 362.72
A275: 501 | B275: M0111 | C275: B | D275: 159 | E275: R | F275: 1 | G275: =CONCATENATE(B275, "-",C275, "-", D275, "-", F275) -> M0111-B-159-1 | H275: 364.78 | I275: 365.38
... A281: 501 | B281: M0111 | C281: B | D281: 168 | E281: R | F281: 1 | G281: =CONCATENATE(B281, "-",C281, "-", D281, "-", F281) -> M0111-B-168-1 | H281: 383.08 | I281: 383.25
A282: 501 | B282: M0111 | C282: B | D282: 169 | E282: R | F282: 1 | G282: =CONCATENATE(B282, "-",C282, "-", D282, "-", F282) -> M0111-B-169-1 | H282: 384.08 | I282: 384.26 | T282: 377.98
A283: 501 | B283: M0111 | C283: B | D283: 171 | E283: R | F283: 1 | G283: =CONCATENATE(B283, "-",C283, "-", D283, "-", F283) -> M0111-B-171-1 | H283: 389.18 | I283: 389.3 | T283: 381.03
A284: 501 | B284: M0111 | C284: C | D284: 1 | E284: H | F284: 1 | G284: =CONCATENATE(B284, "-",C284, "-", D284, "-", F284) -> M0111-C-1-1 | H284: 45.56 | I284: 47.06
A285: 501 | B285: M0111 | C285: C | D285: 1 | E285: H | F285: 2 | G285: =CONCATENATE(B285, "-",C285, "-", D285, "-", F285) -> M0111-C-1-2 | H285: 47.06 | I285: 47.67
A286: 501 | B286: M0111 | C286: C | D286: 2 | E286: H | F286: 1 | G286: =CONCATENATE(B286, "-",C286, "-", D286, "-", F286) -> M0111-C-2-1 | H286: 47.67 | I286: 48.24
A287: 501 | B287: M0111 | C287: C | D287: 2 | E287: H | F287: 2 | G287: =CONCATENATE(B287, "-",C287, "-", D287, "-", F287) -> M0111-C-2-2 | H287: 48.24 | I287: 48.56
A288: 501 | B288: M0111 | C288: C | D288: 3 | E288: H | F288: 1 | G288: =CONCATENATE(B288, "-",C288, "-", D288, "-", F288) -> M0111-C-3-1 | H288: 48.56 | I288: 49.77
A289: 501 | B289: M0111 | C289: C | D289: 3 | E289: H | F289: 2 | G289: =CONCATENATE(B289, "-",C289, "-", D289, "-", F289) -> M0111-C-3-2 | H289: 49.77 | I289: 50
A290: 501 | B290: M0111 | C290: C | D290: 4 | E290: H | F290: 1 | G290: =CONCATENATE(B290, "-",C290, "-", D290, "-", F290) -> M0111-C-4-1 | H290: 50 | I290: 51.1
...

Sheet salinity data
A1: Core Start | B1: Core Stop | C1: Salinity
A2: 501_M0111_A_001H | B2: 501_M0111_A_027H | C2: 32
A4: 501_M0111_B_001H | B4: 501_M0111_B_024R | C4: 30
A5: 501_M0111_B_025R | B5: 501_M0111_B_043R | C5: 12
A6: 501_M0111_B_044R | B6: 501_M0111_B_129R | C6: 6
A7: 501_M0111_B_130R | B7: base of core | C7: 25
A9: 501_M0111_C_002H | B9: 501_M0111_C_002H | C9: 32
A10: 501_M0111_C_002H | B10: 501_M0111_C_9R | C10: 12
A11: 501_M0111_C_010R | B11: 501_M0111_C_039R | C11: 6
A13: 501_M0112_A_001H | B13: 501_M0112_A_036R | C13: 32
A14: 501_M0112_A_037R | B14: 501_M0112_A_051R | C14: 12
A15: 501_M0112_A_052R | B15: 501_M0112_A_051R | C15: 4
A17: 501_M0112_B_002H | B17: 501_M0112_B_010R | C17: 27
... A22: 501_M0113_A_186H | B22: base of hole | C22: 29

Sheet Temperature Corrections
A2: Fa = Re/Rf. | C2: Temperature correction
C5: Both seawater and sediment measurements of electrical conductivity were adjusted to a standard temperature of 25°C where the correction factor is given by a fifth-order polynomial (Janz and Singer, 1975), | G5: 20
C6: χ = a + bT + cT2 + dT3 + eT4 + fT5, | F6: χ | G6: =$D9+$D10*G5+($D11*(G5^2))+($D12*(G5^3))+($D13*(G5^4))+($D14*(G5^5)) -> 47.893293
C7: where
C9: a | D9: 29.05128
C10: b | D10: 0.88082
C11: c | D11: -0.000198312
C12: d | D12: 0.00033363
C13: e | D13: -1.0776e-05
C14: f | D14: 1.12518e-07
C16: The temperature corrected measurement, σT, is given by
C17: σT = σ × (χ25/χobs),
C18: where σ is the measurement and χ20 and χobs are the correction factors using 25°C and the observed temperature, respectively. Both seawater and sediment measurements of electrical conductivity are adjusted for the effects of temperature. A linear drift correction based on the seawater measurements is computed and applied to both the sediment and seawater temperature adjusted measurements and the formation factor, F, is computed as,
C19: F = χsw/χsed.

Sheet Salinity Corrections
F2: mix= 0*(1-f)+ 35*f
A3: salinity dilution series for refractometer conductivity relationship | F3: f = mix/35 | H3: Known Salinity | I3: Measured Refraction | L3: Average
D4: 50 | H4: 9.997 | I4: 1.33496 | J4: 1.33498 | K4: 1.33496 | L4: =AVERAGE(I4:K4) -> 1.3349667
B5: 0 | C5: 34.993 | D5: DI | E5: IAPSO | F5: Actual | H5: 30 | I5: 1.3386 | J5: 1.3386 | K5: 1.33863 | L5: =AVERAGE(I5:K5) -> 1.33861
A6: =0 -> 0 | B6: 1 | C6: 0 | D6: =B6*$D$4 -> 50 | E6: =$D$4-D6 -> 0 | F6: 0 | H6: 34.993 | I6: 1.33958 | J6: 1.3396 | K6: 1.33958 | L6: =AVERAGE(I6:K6) -> 1.3395867
A7: 2 | B7: =1-C7 -> 0.94284571 | C7: =A7/$C$5 -> 0.057154288 | D7: =B7*$D$4 -> 47.142286 | E7: =$D$4-D7 -> 2.8577144 | F7: 3 | H7: 37.999 | I7: 1.34015 | J7: 1.34013 | K7: 1.34011 | L7: =AVERAGE(I7:K7) -> 1.34013
A8: 5 | B8: =1-C8 -> 0.85711428 | C8: =A8/$C$5 -> 0.14288572 | D8: =B8*$D$4 -> 42.855714 | E8: =$D$4-D8 -> 7.144286 | F8: 3.57 | H8: 9.997 | I8: 1.33491 | J8: 1.33491 | K8: 1.33491 | L8: =AVERAGE(I8:K8) -> 1.33491
A9: 10 | B9: =1-C9 -> 0.71422856 | C9: =A9/$C$5 -> 0.28577144 | D9: =B9*$D$4 -> 35.711428 | E9: =$D$4-D9 -> 14.288572
A10: 25 | B10: =1-C10 -> 0.2855714 | C10: =A10/$C$5 -> 0.7144286 | D10: =B10*$D$4 -> 14.27857 | E10: =$D$4-D10 -> 35.72143 | H10: slope | I10: =SLOPE(L4:L8,H4:H8) -> 0.00018533043 | J10: reference salinity | K10: 34.993
A11: 35 | B11: =1-C11 -> -0.00020004001 | C11: =A11/$C$5 -> 1.0002 | D11: 0 | E11: =$D$4-D11 -> 50 | H11: intercept | I11: =INTERCEPT(L4:L8,H4:H8) -> 1.3330821
H12: RSQ | I12: =RSQ(L4:L8,H4:H8) -> 0.99988023
D13: TOTAL USED | E13: =SUM(E6:E11) -> 110.012
H14: Refractometer | I14: Refractometer | J14: Refractometer | K14: Average | L14: Salinity | M14: Conductivity | N14: T of conductivity | O14: T corr | P14: conductivity at 25
A15: Drift monitoring | H15: 1.33335 | I15: 1.33337 | J15: 1.33335 | K15: =AVERAGE(H15:J15) -> 1.3333567 | L15: =(K15-I$11)/I$10 -> 1.4817304 | M15: 3.918 | N15: 20.9 | O15: ='Temperature Corrections'!$D$9+'Temperature Corrections'!$D$10*$N15+('Temperature Corrections'!$D$11*($N15^2))+('Temperature Corrections'!$D$12*($N15^3))+('Temperature Corrections'!$D$13*($N15^4))+('Temperature Corrections'!$D$14*$N15^5) -> 48.812216 | P15: =M15*O15/'Temperature Corrections'!$G$6 -> 3.9931742
A16: measure reflectance | H16: 1.33394 | I16: 1.33395 | J16: 1.333976 | K16: =AVERAGE(H16:J16) -> 1.3339553 | L16: =(K16-I$11)/I$10 -> 4.7119968 | M16: 8.899 | N16: 20.9 | O16: ='Temperature Corrections'!$D$9+'Temperature Corrections'!$D$10*$N16+('Temperature Corrections'!$D$11*($N16^2))+('Temperature Corrections'!$D$12*($N16^3))+('Temperature Corrections'!$D$13*($N16^4))+('Temperature Corrections'!$D$14*$N16^5) -> 48.812216 | P16: =M16*O16/'Temperature Corrections'!$G$6 -> 9.0697441
