Workbook

Sheet Calibration
A1: Date | B1: Time | C1: Solution | D1: T, deg | E1: Conductivity | F1: unit | G1: Comment
A2: 01/16/2026 | B2: 0.33680556 | C2: 1.48 | D2: 20.9 | E2: 3.918 | F2: mS | G2: data captured by Vera B.
A3: 01/16/2026 | B3: 0.34513889 | C3: 4.71 | D3: 20.9 | E3: 8.899 | F3: mS | G3: data captured by Vera B.
A4: 01/16/2026 | B4: 0.34722222 | C4: 9.9 | D4: 20.9 | E4: 16.8 | F4: mS | G4: data captured by Vera B.
A5: 01/16/2026 | B5: 0.35 | C5: 24.4 | D5: 20.9 | E5: 38.01 | F5: mS | G5: data captured by Vera B.
A6: 01/16/2026 | B6: 0.35416667 | C6: 34.7 | D6: 21 | E6: 50.85 | F6: mS | G6: data captured by Vera B.

Sheet Data Entry
I1: 0.68 | J1: 2 | K1: 50.6 | L1: 21.3 | M1: 11450 | N1: 11.45 | O1: 19.3 | P1: 32 | Q1: =K1*('Temperature Corrections'!$D$9+'Temperature Corrections'!$D$10*'Data Entry'!$L1+('Temperature Corrections'!$D$11*('Data Entry'!$L1^2))+('Temperature Corrections'!$D$12*('Data Entry'!$L1^3))+('Temperature Corrections'!$D$13*('Data Entry'!$L1^4))+('Temperature Corrections'!$D$14*('Data Entry'!$L1^5)))/'Temperature Corrections'!$G$6 -> 52.00388 | R1: =N1*('Temperature Corrections'!$D$9+'Temperature Corrections'!$D$10*'Data Entry'!$O1+('Temperature Corrections'!$D$11*('Data Entry'!$O1^2))+('Temperature Corrections'!$D$12*('Data Entry'!$O1^3))+('Temperature Corrections'!$D$13*('Data Entry'!$O1^4))+('Temperature Corrections'!$D$14*('Data Entry'!$O1^5)))/'Temperature Corrections'!$G$6 -> 11.279918 | S1: =Q1*('Salinity Corrections'!$K$22*'Salinity Corrections'!$I$22+'Salinity Corrections'!$I$23)/'Salinity Corrections'!$K$23 -> 52.139454 | T1: =R1*(P1*'Salinity Corrections'!$I$22+'Salinity Corrections'!$I$23)/'Salinity Corrections'!$K$23 -> 10.383372 | U1: NA | V1: =S1 -> 52.139454 | W1: =T1 -> 10.383372 | X1: =(AVERAGE(V$1:V$5))/W1 -> 5.0142724 | Y1: F = χsw/χsed.
A2: Expedition | B2: Site | C2: Hole | D2: Core | E2: Type | F2: Sec | G2: Sample [cm] | H2: Combined | I2: 49.01 | J2: 2 | K2: 50.3 | L2: 21.5 | M2: 12250 | N2: 12.25 | O2: 18.7 | P2: 32 | Q2: =K2*('Temperature Corrections'!$D$9+'Temperature Corrections'!$D$10*'Data Entry'!$L2+('Temperature Corrections'!$D$11*('Data Entry'!$L2^2))+('Temperature Corrections'!$D$12*('Data Entry'!$L2^3))+('Temperature Corrections'!$D$13*('Data Entry'!$L2^4))+('Temperature Corrections'!$D$14*('Data Entry'!$L2^5)))/'Temperature Corrections'!$G$6 -> 51.911122 | R2: =N2*('Temperature Corrections'!$D$9+'Temperature Corrections'!$D$10*'Data Entry'!$O2+('Temperature Corrections'!$D$11*('Data Entry'!$O2^2))+('Temperature Corrections'!$D$12*('Data Entry'!$O2^3))+('Temperature Corrections'!$D$13*('Data Entry'!$O2^4))+('Temperature Corrections'!$D$14*('Data Entry'!$O2^5)))/'Temperature Corrections'!$G$6 -> 11.912686 | S2: =Q2*('Salinity Corrections'!$K$22*'Salinity Corrections'!$I$22+'Salinity Corrections'!$I$23)/'Salinity Corrections'!$K$23 -> 52.046454 | T2: =R2*(P2*'Salinity Corrections'!$I$22+'Salinity Corrections'!$I$23)/'Salinity Corrections'!$K$23 -> 10.965846 | U2: NA | V2: =S2 -> 52.046454 | W2: =T2 -> 10.965846 | X2: =(AVERAGE(V$1:V$5))/W2 -> 4.7479284 | Y2: Note
A3: 501 | B3: M0111 | C3: A | D3: 1 | E3: H | F3: 1 | G3: 68 | H3: M0111-A-1-1 | I3: 49.09 | J3: 2 | K3: 50.3 | L3: 21.5 | M3: 10200 | N3: 10.2 | O3: 18.9 | P3: 32 | Q3: =K3*('Temperature Corrections'!$D$9+'Temperature Corrections'!$D$10*'Data Entry'!$L3+('Temperature Corrections'!$D$11*('Data Entry'!$L3^2))+('Temperature Corrections'!$D$12*('Data Entry'!$L3^3))+('Temperature Corrections'!$D$13*('Data Entry'!$L3^4))+('Temperature Corrections'!$D$14*('Data Entry'!$L3^5)))/'Temperature Corrections'!$G$6 -> 51.911122 | R3: =N3*('Temperature Corrections'!$D$9+'Temperature Corrections'!$D$10*'Data Entry'!$O3+('Temperature Corrections'!$D$11*('Data Entry'!$O3^2))+('Temperature Corrections'!$D$12*('Data Entry'!$O3^3))+('Temperature Corrections'!$D$13*('Data Entry'!$O3^4))+('Temperature Corrections'!$D$14*('Data Entry'!$O3^5)))/'Temperature Corrections'!$G$6 -> 9.9621973 | S3: =Q3*('Salinity Corrections'!$K$22*'Salinity Corrections'!$I$22+'Salinity Corrections'!$I$23)/'Salinity Corrections'!$K$23 -> 52.046454 | T3: =R3*(P3*'Salinity Corrections'!$I$22+'Salinity Corrections'!$I$23)/'Salinity Corrections'!$K$23 -> 9.1703854 | U3: NA | V3: =S3 -> 52.046454 | W3: =T3 -> 9.1703854 | X3: =(AVERAGE(V$1:V$5))/W3 -> 5.6775208 | Y3: undiluted reference solution
A4: 501 | B4: M0111 | C4: A | D4: 21 | E4: H | F4: 2 | G4: 24 | H4: M0111-A-21-2 | I4: =VLOOKUP(H6,'Depth vlookup'!G5:I1052,2,FALSE())+G6/100 -> 82.72 | J4: 2 | K4: 50.3 | L4: 21.5 | M4: =N4*1000 -> 6064 | N4: 6.064 | O4: 20.1 | P4: 30 | Q4: =K4*('Temperature Corrections'!$D$9+'Temperature Corrections'!$D$10*'Data Entry'!$L4+('Temperature Corrections'!$D$11*('Data Entry'!$L4^2))+('Temperature Corrections'!$D$12*('Data Entry'!$L4^3))+('Temperature Corrections'!$D$13*('Data Entry'!$L4^4))+('Temperature Corrections'!$D$14*('Data Entry'!$L4^5)))/'Temperature Corrections'!$G$6 -> 51.911122 | R4: =N4*('Temperature Corrections'!$D$9+'Temperature Corrections'!$D$10*'Data Entry'!$O4+('Temperature Corrections'!$D$11*('Data Entry'!$O4^2))+('Temperature Corrections'!$D$12*('Data Entry'!$O4^3))+('Temperature Corrections'!$D$13*('Data Entry'!$O4^4))+('Temperature Corrections'!$D$14*('Data Entry'!$O4^5)))/'Temperature Corrections'!$G$6 -> 6.0768985 | S4: =Q4*('Salinity Corrections'!$K$22*'Salinity Corrections'!$I$22+'Salinity Corrections'!$I$23)/'Salinity Corrections'!$K$23 -> 52.046454 | T4: =R4*('Salinity Corrections'!$K$22*'Salinity Corrections'!$I$22+'Salinity Corrections'!$I$23)/'Salinity Corrections'!$K$23 -> 6.0927409 | U4: NA | V4: =S4 -> 52.046454 | W4: =T4 -> 6.0927409 | X4: =V4/W4 -> 8.542371 | Y4: undiluted reference solution
A5: 501 | B5: M0111 | C5: A | D5: 21 | E5: H | F5: 2 | G5: 32 | H5: M0111-A-21-2 | I5: =VLOOKUP(H7,'Depth vlookup'!G6:I1053,2,FALSE())+G7/100 -> 82.73 | J5: 2 | K5: 50.3 | L5: 21.5 | M5: =N5*1000 -> 6448 | N5: 6.448 | O5: 20.1 | P5: 30 | Q5: =K5*('Temperature Corrections'!$D$9+'Temperature Corrections'!$D$10*'Data Entry'!$L5+('Temperature Corrections'!$D$11*('Data Entry'!$L5^2))+('Temperature Corrections'!$D$12*('Data Entry'!$L5^3))+('Temperature Corrections'!$D$13*('Data Entry'!$L5^4))+('Temperature Corrections'!$D$14*('Data Entry'!$L5^5)))/'Temperature Corrections'!$G$6 -> 51.911122 | R5: =N5*('Temperature Corrections'!$D$9+'Temperature Corrections'!$D$10*'Data Entry'!$O5+('Temperature Corrections'!$D$11*('Data Entry'!$O5^2))+('Temperature Corrections'!$D$12*('Data Entry'!$O5^3))+('Temperature Corrections'!$D$13*('Data Entry'!$O5^4))+('Temperature Corrections'!$D$14*('Data Entry'!$O5^5)))/'Temperature Corrections'!$G$6 -> 6.4617153 | S5: =Q5*('Salinity Corrections'!$K$22*'Salinity Corrections'!$I$22+'Salinity Corrections'!$I$23)/'Salinity Corrections'!$K$23 -> 52.046454 | T5: =R5*('Salinity Corrections'!$K$22*'Salinity Corrections'!$I$22+'Salinity Corrections'!$I$23)/'Salinity Corrections'!$K$23 -> 6.4785609 | U5: NA | V5: =S5 -> 52.046454 | W5: =T5 -> 6.4785609 | X5: =V5/W5 -> 8.0336442 | Y5: undiluted reference solution
A6: 501 | B6: 111 | C6: B | D6: 14 | E6: R | F6: 1 | G6: 12 | H6: =CONCATENATE("M0",B6,"-",C6, "-",D6, "-",F6) -> M0111-B-14-1 | I6: =VLOOKUP(H8,'Depth vlookup'!G7:I1054,2,FALSE())+G8/100 -> 91.285 | J6: 2 | K6: 44.48 | L6: 20.6 | M6: =N6*1000 -> 9250 | N6: 9.25 | O6: 17.2 | P6: 30 | Q6: =K6*('Temperature Corrections'!$D$9+'Temperature Corrections'!$D$10*'Data Entry'!$L6+('Temperature Corrections'!$D$11*('Data Entry'!$L6^2))+('Temperature Corrections'!$D$12*('Data Entry'!$L6^3))+('Temperature Corrections'!$D$13*('Data Entry'!$L6^4))+('Temperature Corrections'!$D$14*('Data Entry'!$L6^5)))/'Temperature Corrections'!$G$6 -> 45.04848 | R6: =N6*('Temperature Corrections'!$D$9+'Temperature Corrections'!$D$10*'Data Entry'!$O6+('Temperature Corrections'!$D$11*('Data Entry'!$O6^2))+('Temperature Corrections'!$D$12*('Data Entry'!$O6^3))+('Temperature Corrections'!$D$13*('Data Entry'!$O6^4))+('Temperature Corrections'!$D$14*('Data Entry'!$O6^5)))/'Temperature Corrections'!$G$6 -> 8.704064 | S6: =Q6*'Salinity Corrections'!$K$23/'Salinity Corrections'!$K$26 -> 51.985619 | T6: =R6*('Salinity Corrections'!$K$22*'Salinity Corrections'!$I$22+'Salinity Corrections'!$I$23)/'Salinity Corrections'!$K$23 -> 8.7267554 | U6: NA | V6: =S6 -> 51.985619 | W6: =T6 -> 8.7267554 | X6: =V6/W6 -> 5.9570386 | Y6: undiluted reference solution
A7: 501 | B7: 111 | C7: B | D7: 14 | E7: R | F7: 1 | G7: 13 | H7: =CONCATENATE("M0",B7,"-",C7, "-",D7, "-",F7) -> M0111-B-14-1 | I7: =VLOOKUP(H9,'Depth vlookup'!G8:I1055,2,FALSE())+G9/100 -> 91.31 | J7: 2 | K7: 43.76 | L7: 20.6 | M7: =N7*1000 -> 9260 | N7: 9.26 | O7: 17.2 | P7: 30 | Q7: =K7*('Temperature Corrections'!$D$9+'Temperature Corrections'!$D$10*'Data Entry'!$L7+('Temperature Corrections'!$D$11*('Data Entry'!$L7^2))+('Temperature Corrections'!$D$12*('Data Entry'!$L7^3))+('Temperature Corrections'!$D$13*('Data Entry'!$L7^4))+('Temperature Corrections'!$D$14*('Data Entry'!$L7^5)))/'Temperature Corrections'!$G$6 -> 44.319278 | R7: =N7*('Temperature Corrections'!$D$9+'Temperature Corrections'!$D$10*'Data Entry'!$O7+('Temperature Corrections'!$D$11*('Data Entry'!$O7^2))+('Temperature Corrections'!$D$12*('Data Entry'!$O7^3))+('Temperature Corrections'!$D$13*('Data Entry'!$O7^4))+('Temperature Corrections'!$D$14*('Data Entry'!$O7^5)))/'Temperature Corrections'!$G$6 -> 8.7134738 | S7: =Q7*'Salinity Corrections'!$K$23/'Salinity Corrections'!$K$26 -> 51.144125 | T7: =R7*('Salinity Corrections'!$K$22*'Salinity Corrections'!$I$22+'Salinity Corrections'!$I$23)/'Salinity Corrections'!$K$23 -> 8.7361898 | U7: NA | V7: =S7 -> 51.144125 | W7: =T7 -> 8.7361898 | X7: =V7/W7 -> 5.8542828 | Y7: undiluted reference solution
A8: 501 | B8: 111 | C8: B | D8: 18 | E8: R | F8: 1 | G8: 18.5 | H8: =CONCATENATE("M0",B8,"-",C8, "-",D8, "-",F8) -> M0111-B-18-1 | I8: =VLOOKUP(H10,'Depth vlookup'!G9:I1056,2,FALSE())+G10/100 -> 103.79 | J8: 2 | K8: 44.8 | L8: 20.9 | M8: =N8*1000 -> 6476 | N8: 6.476 | O8: 20.5 | P8: 30 | Q8: =K8*('Temperature Corrections'!$D$9+'Temperature Corrections'!$D$10*'Data Entry'!$L8+('Temperature Corrections'!$D$11*('Data Entry'!$L8^2))+('Temperature Corrections'!$D$12*('Data Entry'!$L8^3))+('Temperature Corrections'!$D$13*('Data Entry'!$L8^4))+('Temperature Corrections'!$D$14*('Data Entry'!$L8^5)))/'Temperature Corrections'!$G$6 -> 45.659572 | R8: =N8*('Temperature Corrections'!$D$9+'Temperature Corrections'!$D$10*'Data Entry'!$O8+('Temperature Corrections'!$D$11*('Data Entry'!$O8^2))+('Temperature Corrections'!$D$12*('Data Entry'!$O8^3))+('Temperature Corrections'!$D$13*('Data Entry'!$O8^4))+('Temperature Corrections'!$D$14*('Data Entry'!$O8^5)))/'Temperature Corrections'!$G$6 -> 6.5449531 | S8: =Q8*'Salinity Corrections'!$K$23/'Salinity Corrections'!$K$26 -> 52.690815 | T8: =R8*('Salinity Corrections'!$K$22*'Salinity Corrections'!$I$22+'Salinity Corrections'!$I$23)/'Salinity Corrections'!$K$23 -> 6.5620157 | U8: NA | V8: =S8 -> 52.690815 | W8: =T8 -> 6.5620157 | X8: =V8/W8 -> 8.0296691 | Y8: diluted reference solution
A9: 501 | B9: 111 | C9: B | D9: 18 | E9: R | F9: 1 | G9: 21 | H9: =CONCATENATE("M0",B9,"-",C9, "-",D9, "-",F9) -> M0111-B-18-1 | I9: =VLOOKUP(H11,'Depth vlookup'!G10:I1057,2,FALSE())+G11/100 -> 103.765 | J9: 2 | K9: 44.11 | L9: 20.9 | M9: =N9*1000 -> 6125 | N9: 6.125 | O9: 20.5 | P9: 30 | Q9: =K9*('Temperature Corrections'!$D$9+'Temperature Corrections'!$D$10*'Data Entry'!$L9+('Temperature Corrections'!$D$11*('Data Entry'!$L9^2))+('Temperature Corrections'!$D$12*('Data Entry'!$L9^3))+('Temperature Corrections'!$D$13*('Data Entry'!$L9^4))+('Temperature Corrections'!$D$14*('Data Entry'!$L9^5)))/'Temperature Corrections'!$G$6 -> 44.956333 | R9: =N9*('Temperature Corrections'!$D$9+'Temperature Corrections'!$D$10*'Data Entry'!$O9+('Temperature Corrections'!$D$11*('Data Entry'!$O9^2))+('Temperature Corrections'!$D$12*('Data Entry'!$O9^3))+('Temperature Corrections'!$D$13*('Data Entry'!$O9^4))+('Temperature Corrections'!$D$14*('Data Entry'!$O9^5)))/'Temperature Corrections'!$G$6 -> 6.1902158 | S9: =Q9*'Salinity Corrections'!$K$23/'Salinity Corrections'!$K$26 -> 51.879282 | T9: =R9*('Salinity Corrections'!$K$22*'Salinity Corrections'!$I$22+'Salinity Corrections'!$I$23)/'Salinity Corrections'!$K$23 -> 6.2063536 | U9: NA | V9: =S9 -> 51.879282 | W9: =T9 -> 6.2063536 | X9: =V9/W9 -> 8.35906 | Y9: diluted reference solution
A10: 501 | B10: 111 | C10: B | D10: 24 | E10: R | F10: 2 | G10: 88 | H10: =CONCATENATE("M0",B10,"-",C10, "-",D10, "-",F10) -> M0111-B-24-2 | I10: =VLOOKUP(H12,'Depth vlookup'!G11:I1058,2,FALSE())+G12/100 -> 112.375 | J10: 2 | K10: 45.12 | L10: 20.9 | M10: =N10*1000 -> 6757 | N10: 6.757 | O10: 19.6 | P10: 12 | Q10: =K10*('Temperature Corrections'!$D$9+'Temperature Corrections'!$D$10*'Data Entry'!$L10+('Temperature Corrections'!$D$11*('Data Entry'!$L10^2))+('Temperature Corrections'!$D$12*('Data Entry'!$L10^3))+('Temperature Corrections'!$D$13*('Data Entry'!$L10^4))+('Temperature Corrections'!$D$14*('Data Entry'!$L10^5)))/'Temperature Corrections'!$G$6 -> 45.985712 | R10: =N10*('Temperature Corrections'!$D$9+'Temperature Corrections'!$D$10*'Data Entry'!$O10+('Temperature Corrections'!$D$11*('Data Entry'!$O10^2))+('Temperature Corrections'!$D$12*('Data Entry'!$O10^3))+('Temperature Corrections'!$D$13*('Data Entry'!$O10^4))+('Temperature Corrections'!$D$14*('Data Entry'!$O10^5)))/'Temperature Corrections'!$G$6 -> 6.6995939 | S10: =Q10*'Salinity Corrections'!$K$23/'Salinity Corrections'!$K$26 -> 53.067178 | T10: =R10*('Salinity Corrections'!$K$22*'Salinity Corrections'!$I$22+'Salinity Corrections'!$I$23)/'Salinity Corrections'!$K$23 -> 6.7170596 | U10: NA | V10: =S10 -> 53.067178 | W10: =T10 -> 6.7170596 | X10: =V10/W10 -> 7.9003583 | Y10: diluted reference solution
A11: 501 | B11: 111 | C11: B | D11: 24 | E11: R | F11: 2 | G11: 85.5 | H11: =CONCATENATE("M0",B11,"-",C11, "-",D11, "-",F11) -> M0111-B-24-2 | I11: =VLOOKUP(H13,'Depth vlookup'!G12:I1059,2,FALSE())+G13/100 -> 112.4 | J11: 2 | K11: 44.13 | L11: 19.6 | M11: =N11*1000 -> 6694 | N11: 6.694 | O11: 19.6 | P11: 12 | Q11: =K11*('Temperature Corrections'!$D$9+'Temperature Corrections'!$D$10*'Data Entry'!$L11+('Temperature Corrections'!$D$11*('Data Entry'!$L11^2))+('Temperature Corrections'!$D$12*('Data Entry'!$L11^3))+('Temperature Corrections'!$D$13*('Data Entry'!$L11^4))+('Temperature Corrections'!$D$14*('Data Entry'!$L11^5)))/'Temperature Corrections'!$G$6 -> 43.75508 | R11: =N11*('Temperature Corrections'!$D$9+'Temperature Corrections'!$D$10*'Data Entry'!$O11+('Temperature Corrections'!$D$11*('Data Entry'!$O11^2))+('Temperature Corrections'!$D$12*('Data Entry'!$O11^3))+('Temperature Corrections'!$D$13*('Data Entry'!$O11^4))+('Temperature Corrections'!$D$14*('Data Entry'!$O11^5)))/'Temperature Corrections'!$G$6 -> 6.6371291 | S11: =Q11*'Salinity Corrections'!$K$23/'Salinity Corrections'!$K$26 -> 50.493045 | T11: =R11*('Salinity Corrections'!$K$22*'Salinity Corrections'!$I$22+'Salinity Corrections'!$I$23)/'Salinity Corrections'!$K$23 -> 6.654432 | U11: NA | V11: =S11 -> 50.493045 | W11: =T11 -> 6.654432 | X11: =V11/W11 -> 7.587882 | Y11: diluted reference solution | AB11: Reference Solution 30% | AD11: 01/19/26 16:00
A12: 501 | B12: 111 | C12: B | D12: 28 | E12: R | F12: 1 | G12: 7.5 | H12: =CONCATENATE("M0",B12,"-",C12, "-",D12, "-",F12) -> M0111-B-28-1 | I12: =VLOOKUP(H14,'Depth vlookup'!G13:I1060,2,FALSE())+G14/100 -> 121.34 | J12: 1 | K12: 43.63 | L12: 21.1 | M12: =N12*1000 -> 6920 | N12: 6.92 | O12: 20.8 | P12: 12 | Q12: =K12*('Temperature Corrections'!$D$9+'Temperature Corrections'!$D$10*'Data Entry'!$L12+('Temperature Corrections'!$D$11*('Data Entry'!$L12^2))+('Temperature Corrections'!$D$12*('Data Entry'!$L12^3))+('Temperature Corrections'!$D$13*('Data Entry'!$L12^4))+('Temperature Corrections'!$D$14*('Data Entry'!$L12^5)))/'Temperature Corrections'!$G$6 -> 44.653713 | R12: =N12*('Temperature Corrections'!$D$9+'Temperature Corrections'!$D$10*'Data Entry'!$O12+('Temperature Corrections'!$D$11*('Data Entry'!$O12^2))+('Temperature Corrections'!$D$12*('Data Entry'!$O12^3))+('Temperature Corrections'!$D$13*('Data Entry'!$O12^4))+('Temperature Corrections'!$D$14*('Data Entry'!$O12^5)))/'Temperature Corrections'!$G$6 -> 7.037988 | S12: =Q12*'Salinity Corrections'!$K$23/'Salinity Corrections'!$K$26 -> 51.530061 | T12: =R12*('Salinity Corrections'!$K$22*'Salinity Corrections'!$I$22+'Salinity Corrections'!$I$23)/'Salinity Corrections'!$K$23 -> 7.0563359 | U12: 1 | V12: =S12--0.037*$U12 -> 51.567061 | W12: =T12-'Drift correction'!D$4*$U12 -> 7.0992814 | X12: =V12/W12 -> 7.2637015 | Y12: diluted reference solution | AB12: Eletcr 2 | AC12: 44.7 mS/cm | AD12: @21.1 degC
A13: 501 | B13: 111 | C13: B | D13: 28 | E13: R | F13: 1 | G13: 10 | H13: =CONCATENATE("M0",B13,"-",C13, "-",D13, "-",F13) -> M0111-B-28-1 | I13: =VLOOKUP(H15,'Depth vlookup'!G14:I1061,2,FALSE())+G15/100 -> 121.38 | J13: 1 | K13: 43.6 | L13: 21.1 | M13: =N13*1000 -> 5636 | N13: 5.636 | O13: 20.3 | P13: 12 | Q13: =K13*('Temperature Corrections'!$D$9+'Temperature Corrections'!$D$10*'Data Entry'!$L13+('Temperature Corrections'!$D$11*('Data Entry'!$L13^2))+('Temperature Corrections'!$D$12*('Data Entry'!$L13^3))+('Temperature Corrections'!$D$13*('Data Entry'!$L13^4))+('Temperature Corrections'!$D$14*('Data Entry'!$L13^5)))/'Temperature Corrections'!$G$6 -> 44.623009 | R13: =N13*('Temperature Corrections'!$D$9+'Temperature Corrections'!$D$10*'Data Entry'!$O13+('Temperature Corrections'!$D$11*('Data Entry'!$O13^2))+('Temperature Corrections'!$D$12*('Data Entry'!$O13^3))+('Temperature Corrections'!$D$13*('Data Entry'!$O13^4))+('Temperature Corrections'!$D$14*('Data Entry'!$O13^5)))/'Temperature Corrections'!$G$6 -> 5.6719851 | S13: =Q13*'Salinity Corrections'!$K$23/'Salinity Corrections'!$K$26 -> 51.494629 | T13: =R13*('Salinity Corrections'!$K$22*'Salinity Corrections'!$I$22+'Salinity Corrections'!$I$23)/'Salinity Corrections'!$K$23 -> 5.6867719 | U13: 2 | V13: =S13--0.037*$U13 -> 51.568629 | W13: =T13-'Drift correction'!D$4*$U13 -> 5.7726627 | X13: =V13/W13 -> 8.9332482 | Y13: diluted reference solution | AB13: Electr 1 | AC13: 43.9 mS/cm | AD13: @21.1 degC
A14: 501 | B14: 111 | C14: B | D14: 31 | E14: R | F14: 1 | G14: 4 | H14: =CONCATENATE("M0",B14,"-",C14, "-",D14, "-",F14) -> M0111-B-31-1 | I14: =VLOOKUP(H16,'Depth vlookup'!G15:I1062,2,FALSE())+G16/100 -> 131.71 | J14: 1 | K14: 43.27 | L14: 20.9 | M14: =N14*1000 -> 4313 | N14: 4.313 | O14: 20.5 | P14: 12 | Q14: =K14*('Temperature Corrections'!$D$9+'Temperature Corrections'!$D$10*'Data Entry'!$L14+('Temperature Corrections'!$D$11*('Data Entry'!$L14^2))+('Temperature Corrections'!$D$12*('Data Entry'!$L14^3))+('Temperature Corrections'!$D$13*('Data Entry'!$L14^4))+('Temperature Corrections'!$D$14*('Data Entry'!$L14^5)))/'Temperature Corrections'!$G$6 -> 44.100216 | R14: =N14*('Temperature Corrections'!$D$9+'Temperature Corrections'!$D$10*'Data Entry'!$O14+('Temperature Corrections'!$D$11*('Data Entry'!$O14^2))+('Temperature Corrections'!$D$12*('Data Entry'!$O14^3))+('Temperature Corrections'!$D$13*('Data Entry'!$O14^4))+('Temperature Corrections'!$D$14*('Data Entry'!$O14^5)))/'Temperature Corrections'!$G$6 -> 4.3589226 | S14: =Q14*'Salinity Corrections'!$K$23/'Salinity Corrections'!$K$26 -> 50.89133 | T14: =R14*('Salinity Corrections'!$K$22*'Salinity Corrections'!$I$22+'Salinity Corrections'!$I$23)/'Salinity Corrections'!$K$23 -> 4.3702863 | U14: 3 | V14: =S14--0.037*$U14 -> 51.00233 | W14: =T14-'Drift correction'!D$4*$U14 -> 4.4991225 | X14: =V14/W14 -> 11.336062 | Y14: diluted reference solution
A15: 501 | B15: 111 | C15: B | D15: 31 | E15: R | F15: 1 | G15: 8 | H15: =CONCATENATE("M0",B15,"-",C15, "-",D15, "-",F15) -> M0111-B-31-1 | I15: =VLOOKUP(H17,'Depth vlookup'!G16:I1063,2,FALSE())+G17/100 -> 131.76 | J15: 1 | K15: 43.27 | L15: 20.9 | M15: =N15*1000 -> 4790 | N15: 4.79 | O15: 20.4 | P15: 12 | Q15: =K15*('Temperature Corrections'!$D$9+'Temperature Corrections'!$D$10*'Data Entry'!$L15+('Temperature Corrections'!$D$11*('Data Entry'!$L15^2))+('Temperature Corrections'!$D$12*('Data Entry'!$L15^3))+('Temperature Corrections'!$D$13*('Data Entry'!$L15^4))+('Temperature Corrections'!$D$14*('Data Entry'!$L15^5)))/'Temperature Corrections'!$G$6 -> 44.100216 | R15: =N15*('Temperature Corrections'!$D$9+'Temperature Corrections'!$D$10*'Data Entry'!$O15+('Temperature Corrections'!$D$11*('Data Entry'!$O15^2))+('Temperature Corrections'!$D$12*('Data Entry'!$O15^3))+('Temperature Corrections'!$D$13*('Data Entry'!$O15^4))+('Temperature Corrections'!$D$14*('Data Entry'!$O15^5)))/'Temperature Corrections'!$G$6 -> 4.8307896 | S15: =Q15*'Salinity Corrections'!$K$23/'Salinity Corrections'!$K$26 -> 50.89133 | T15: =R15*('Salinity Corrections'!$K$22*'Salinity Corrections'!$I$22+'Salinity Corrections'!$I$23)/'Salinity Corrections'!$K$23 -> 4.8433834 | U15: 4 | V15: =S15--0.037*$U15 -> 51.03933 | W15: =T15-'Drift correction'!D$4*$U15 -> 5.0151651 | X15: =V15/W15 -> 10.176999 | Y15: diluted reference solution
A16: 501 | B16: 111 | C16: B | D16: 39 | E16: R | F16: 1 | G16: 4 | H16: =CONCATENATE("M0",B16,"-",C16, "-",D16, "-",F16) -> M0111-B-39-1 | I16: =VLOOKUP(H18,'Depth vlookup'!G17:I1064,2,FALSE())+G18/100 -> 146.81 | J16: 1 | K16: 41.92 | L16: 20.3 | M16: =N16*1000 -> 7216 | N16: 7.216 | O16: 18.4 | P16: 6 | Q16: =K16*('Temperature Corrections'!$D$9+'Temperature Corrections'!$D$10*'Data Entry'!$L16+('Temperature Corrections'!$D$11*('Data Entry'!$L16^2))+('Temperature Corrections'!$D$12*('Data Entry'!$L16^3))+('Temperature Corrections'!$D$13*('Data Entry'!$L16^4))+('Temperature Corrections'!$D$14*('Data Entry'!$L16^5)))/'Temperature Corrections'!$G$6 -> 42.187653 | R16: =N16*('Temperature Corrections'!$D$9+'Temperature Corrections'!$D$10*'Data Entry'!$O16+('Temperature Corrections'!$D$11*('Data Entry'!$O16^2))+('Temperature Corrections'!$D$12*('Data Entry'!$O16^3))+('Temperature Corrections'!$D$13*('Data Entry'!$O16^4))+('Temperature Corrections'!$D$14*('Data Entry'!$O16^5)))/'Temperature Corrections'!$G$6 -> 6.9716786 | S16: =Q16*'Salinity Corrections'!$K$23/'Salinity Corrections'!$K$26 -> 48.684246 | T16: =R16*('Salinity Corrections'!$K$22*'Salinity Corrections'!$I$22+'Salinity Corrections'!$I$23)/'Salinity Corrections'!$K$23 -> 6.9898537 | U16: 5 | V16: =S16--0.037*$U16 -> 48.869246 | W16: =T16-'Drift correction'!D$4*$U16 -> 7.2045808 | X16: =V16/W16 -> 6.7830797 | Y16: diluted reference solution
A17: 501 | B17: 111 | C17: B | D17: 39 | E17: R | F17: 1 | G17: 9 | H17: =CONCATENATE("M0",B17,"-",C17, "-",D17, "-",F17) -> M0111-B-39-1 | I17: =VLOOKUP(H19,'Depth vlookup'!G18:I1065,2,FALSE())+G19/100 -> 146.85 | J17: 1 | K17: 41.92 | L17: 20.3 | M17: =N17*1000 -> 5710 | N17: 5.71 | O17: 18.4 | P17: 6 | Q17: =K17*('Temperature Corrections'!$D$9+'Temperature Corrections'!$D$10*'Data Entry'!$L17+('Temperature Corrections'!$D$11*('Data Entry'!$L17^2))+('Temperature Corrections'!$D$12*('Data Entry'!$L17^3))+('Temperature Corrections'!$D$13*('Data Entry'!$L17^4))+('Temperature Corrections'!$D$14*('Data Entry'!$L17^5)))/'Temperature Corrections'!$G$6 -> 42.187653 | R17: =N17*('Temperature Corrections'!$D$9+'Temperature Corrections'!$D$10*'Data Entry'!$O17+('Temperature Corrections'!$D$11*('Data Entry'!$O17^2))+('Temperature Corrections'!$D$12*('Data Entry'!$O17^3))+('Temperature Corrections'!$D$13*('Data Entry'!$O17^4))+('Temperature Corrections'!$D$14*('Data Entry'!$O17^5)))/'Temperature Corrections'!$G$6 -> 5.5166692 | S17: =Q17*'Salinity Corrections'!$K$23/'Salinity Corrections'!$K$26 -> 48.684246 | T17: =R17*('Salinity Corrections'!$K$22*'Salinity Corrections'!$I$22+'Salinity Corrections'!$I$23)/'Salinity Corrections'!$K$23 -> 5.5310511 | U17: 6 | V17: =S17--0.037*$U17 -> 48.906246 | W17: =T17-'Drift correction'!D$4*$U17 -> 5.7887236 | X17: =V17/W17 -> 8.448537 | Y17: diluted reference solution
A18: 501 | B18: 111 | C18: B | D18: 44 | E18: R | F18: 1 | G18: 70 | H18: =CONCATENATE("M0",B18,"-",C18, "-",D18, "-",F18) -> M0111-B-44-1 | I18: =VLOOKUP(H20,'Depth vlookup'!G19:I1066,2,FALSE())+G20/100 -> 175.95 | J18: 1 | K18: 43.5 | L18: 21.3 | M18: =N18*1000 -> 3548 | N18: 3.548 | O18: 20.9 | P18: 6 | Q18: =K18*('Temperature Corrections'!$D$9+'Temperature Corrections'!$D$10*'Data Entry'!$L18+('Temperature Corrections'!$D$11*('Data Entry'!$L18^2))+('Temperature Corrections'!$D$12*('Data Entry'!$L18^3))+('Temperature Corrections'!$D$13*('Data Entry'!$L18^4))+('Temperature Corrections'!$D$14*('Data Entry'!$L18^5)))/'Temperature Corrections'!$G$6 -> 44.706893 | R18: =N18*('Temperature Corrections'!$D$9+'Temperature Corrections'!$D$10*'Data Entry'!$O18+('Temperature Corrections'!$D$11*('Data Entry'!$O18^2))+('Temperature Corrections'!$D$12*('Data Entry'!$O18^3))+('Temperature Corrections'!$D$13*('Data Entry'!$O18^4))+('Temperature Corrections'!$D$14*('Data Entry'!$O18^5)))/'Temperature Corrections'!$G$6 -> 3.6160751 | S18: =Q18*'Salinity Corrections'!$K$23/'Salinity Corrections'!$K$26 -> 51.59143 | T18: =R18*('Salinity Corrections'!$K$22*'Salinity Corrections'!$I$22+'Salinity Corrections'!$I$23)/'Salinity Corrections'!$K$23 -> 3.6255021 | U18: 7 | V18: =S18--0.037*$U18 -> 51.85043 | W18: =T18-'Drift correction'!D$4*$U18 -> 3.92612 | X18: =V18/W18 -> 13.206532 | Y18: sandy sediment, poorly consolidated
A19: 501 | B19: 111 | C19: B | D19: 44 | E19: R | F19: 1 | G19: 74 | H19: =CONCATENATE("M0",B19,"-",C19, "-",D19, "-",F19) -> M0111-B-44-1 | I19: =VLOOKUP(H21,'Depth vlookup'!G20:I1067,2,FALSE())+G21/100 -> 175.98 | J19: 1 | K19: 43.5 | L19: 21.3 | M19: =N19*1000 -> 3382 | N19: 3.382 | O19: 20.9 | P19: 6 | Q19: =K19*('Temperature Corrections'!$D$9+'Temperature Corrections'!$D$10*'Data Entry'!$L19+('Temperature Corrections'!$D$11*('Data Entry'!$L19^2))+('Temperature Corrections'!$D$12*('Data Entry'!$L19^3))+('Temperature Corrections'!$D$13*('Data Entry'!$L19^4))+('Temperature Corrections'!$D$14*('Data Entry'!$L19^5)))/'Temperature Corrections'!$G$6 -> 44.706893 | R19: =N19*('Temperature Corrections'!$D$9+'Temperature Corrections'!$D$10*'Data Entry'!$O19+('Temperature Corrections'!$D$11*('Data Entry'!$O19^2))+('Temperature Corrections'!$D$12*('Data Entry'!$O19^3))+('Temperature Corrections'!$D$13*('Data Entry'!$O19^4))+('Temperature Corrections'!$D$14*('Data Entry'!$O19^5)))/'Temperature Corrections'!$G$6 -> 3.44689 | S19: =Q19*'Salinity Corrections'!$K$23/'Salinity Corrections'!$K$26 -> 51.59143 | T19: =R19*('Salinity Corrections'!$K$22*'Salinity Corrections'!$I$22+'Salinity Corrections'!$I$23)/'Salinity Corrections'!$K$23 -> 3.455876 | U19: 8 | V19: =S19--0.037*$U19 -> 51.88743 | W19: =T19-'Drift correction'!D$4*$U19 -> 3.7994394 | X19: =V19/W19 -> 13.656602 | Y19: sandy sediment, poorly consolidated
A20: 501 | B20: 111 | C20: B | D20: 61 | E20: R | F20: 1 | G20: 34 | H20: =CONCATENATE("M0",B20,"-",C20, "-",D20, "-",F20) -> M0111-B-61-1 | I20: =VLOOKUP(H22,'Depth vlookup'!G21:I1068,2,FALSE())+G22/100 -> 185.19 | J20: 1 | K20: 43.24 | L20: 21.2 | M20: =N20*1000 -> 2344 | N20: 2.344 | O20: 20.1 | P20: 6 | Q20: =K20*('Temperature Corrections'!$D$9+'Temperature Corrections'!$D$10*'Data Entry'!$L20+('Temperature Corrections'!$D$11*('Data Entry'!$L20^2))+('Temperature Corrections'!$D$12*('Data Entry'!$L20^3))+('Temperature Corrections'!$D$13*('Data Entry'!$L20^4))+('Temperature Corrections'!$D$14*('Data Entry'!$L20^5)))/'Temperature Corrections'!$G$6 -> 44.347097 | R20: =N20*('Temperature Corrections'!$D$9+'Temperature Corrections'!$D$10*'Data Entry'!$O20+('Temperature Corrections'!$D$11*('Data Entry'!$O20^2))+('Temperature Corrections'!$D$12*('Data Entry'!$O20^3))+('Temperature Corrections'!$D$13*('Data Entry'!$O20^4))+('Temperature Corrections'!$D$14*('Data Entry'!$O20^5)))/'Temperature Corrections'!$G$6 -> 2.3489858 | S20: =Q20*'Salinity Corrections'!$K$23/'Salinity Corrections'!$K$26 -> 51.176227 | T20: =R20*('Salinity Corrections'!$K$22*'Salinity Corrections'!$I$22+'Salinity Corrections'!$I$23)/'Salinity Corrections'!$K$23 -> 2.3551096 | U20: 9 | V20: =S20--0.037*$U20 -> 51.509227 | W20: =T20-'Drift correction'!D$4*$U20 -> 2.7416183 | X20: =V20/W20 -> 18.787891
A21: 501 | B21: 111 | C21: B | D21: 61 | E21: R | F21: 1 | G21: 37 | H21: =CONCATENATE("M0",B21,"-",C21, "-",D21, "-",F21) -> M0111-B-61-1 | I21: =VLOOKUP(H23,'Depth vlookup'!G22:I1069,2,FALSE())+G23/100 -> 185.21 | J21: 1 | K21: 43.23 | L21: 21.2 | M21: =N21*1000 -> 2320 | N21: 2.32 | O21: 20.2 | P21: 6 | Q21: =K21*('Temperature Corrections'!$D$9+'Temperature Corrections'!$D$10*'Data Entry'!$L21+('Temperature Corrections'!$D$11*('Data Entry'!$L21^2))+('Temperature Corrections'!$D$12*('Data Entry'!$L21^3))+('Temperature Corrections'!$D$13*('Data Entry'!$L21^4))+('Temperature Corrections'!$D$14*('Data Entry'!$L21^5)))/'Temperature Corrections'!$G$6 -> 44.33684 | R21: =N21*('Temperature Corrections'!$D$9+'Temperature Corrections'!$D$10*'Data Entry'!$O21+('Temperature Corrections'!$D$11*('Data Entry'!$O21^2))+('Temperature Corrections'!$D$12*('Data Entry'!$O21^3))+('Temperature Corrections'!$D$13*('Data Entry'!$O21^4))+('Temperature Corrections'!$D$14*('Data Entry'!$O21^5)))/'Temperature Corrections'!$G$6 -> 2.3298724 | S21: =Q21*'Salinity Corrections'!$K$23/'Salinity Corrections'!$K$26 -> 51.164392 | T21: =R21*('Salinity Corrections'!$K$22*'Salinity Corrections'!$I$22+'Salinity Corrections'!$I$23)/'Salinity Corrections'!$K$23 -> 2.3359464 | U21: 10 | V21: =S21--0.037*$U21 -> 51.534392 | W21: =T21-'Drift correction'!D$4*$U21 -> 2.7654005 | X21: =V21/W21 -> 18.635417
A22: 501 | B22: 111 | C22: B | D22: 64 | E22: R | F22: 1 | G22: 43 | H22: =CONCATENATE("M0",B22,"-",C22, "-",D22, "-",F22) -> M0111-B-64-1 | I22: =VLOOKUP(H24,'Depth vlookup'!G23:I1070,2,FALSE())+G24/100 -> 194.2 | J22: 1 | K22: 42.84 | L22: 20.8 | M22: =N22*1000 -> 3002 | N22: 3.002 | O22: 19.9 | P22: 6 | Q22: =K22*('Temperature Corrections'!$D$9+'Temperature Corrections'!$D$10*'Data Entry'!$L22+('Temperature Corrections'!$D$11*('Data Entry'!$L22^2))+('Temperature Corrections'!$D$12*('Data Entry'!$L22^3))+('Temperature Corrections'!$D$13*('Data Entry'!$L22^4))+('Temperature Corrections'!$D$14*('Data Entry'!$L22^5)))/'Temperature Corrections'!$G$6 -> 43.570434 | R22: =N22*('Temperature Corrections'!$D$9+'Temperature Corrections'!$D$10*'Data Entry'!$O22+('Temperature Corrections'!$D$11*('Data Entry'!$O22^2))+('Temperature Corrections'!$D$12*('Data Entry'!$O22^3))+('Temperature Corrections'!$D$13*('Data Entry'!$O22^4))+('Temperature Corrections'!$D$14*('Data Entry'!$O22^5)))/'Temperature Corrections'!$G$6 -> 2.9956183 | S22: =Q22*'Salinity Corrections'!$K$23/'Salinity Corrections'!$K$26 -> 50.279965 | T22: =R22*('Salinity Corrections'!$K$22*'Salinity Corrections'!$I$22+'Salinity Corrections'!$I$23)/'Salinity Corrections'!$K$23 -> 3.0034278 | U22: 11 | V22: =S22--0.037*$U22 -> 50.686965 | W22: =T22-'Drift correction'!D$4*$U22 -> 3.4758274 | X22: =V22/W22 -> 14.582705
A23: 501 | B23: 111 | C23: B | D23: 64 | E23: R | F23: 1 | G23: 45 | H23: =CONCATENATE("M0",B23,"-",C23, "-",D23, "-",F23) -> M0111-B-64-1 | I23: =VLOOKUP(H25,'Depth vlookup'!G24:I1071,2,FALSE())+G25/100 -> 194.23 | J23: 1 | K23: 42.8 | L23: 20.8 | M23: =N23*1000 -> 2990 | N23: 2.99 | O23: 19.7 | P23: 6 | Q23: =K23*('Temperature Corrections'!$D$9+'Temperature Corrections'!$D$10*'Data Entry'!$L23+('Temperature Corrections'!$D$11*('Data Entry'!$L23^2))+('Temperature Corrections'!$D$12*('Data Entry'!$L23^3))+('Temperature Corrections'!$D$13*('Data Entry'!$L23^4))+('Temperature Corrections'!$D$14*('Data Entry'!$L23^5)))/'Temperature Corrections'!$G$6 -> 43.529752 | R23: =N23*('Temperature Corrections'!$D$9+'Temperature Corrections'!$D$10*'Data Entry'!$O23+('Temperature Corrections'!$D$11*('Data Entry'!$O23^2))+('Temperature Corrections'!$D$12*('Data Entry'!$O23^3))+('Temperature Corrections'!$D$13*('Data Entry'!$O23^4))+('Temperature Corrections'!$D$14*('Data Entry'!$O23^5)))/'Temperature Corrections'!$G$6 -> 2.9709425 | S23: =Q23*'Salinity Corrections'!$K$23/'Salinity Corrections'!$K$26 -> 50.233018 | T23: =R23*('Salinity Corrections'!$K$22*'Salinity Corrections'!$I$22+'Salinity Corrections'!$I$23)/'Salinity Corrections'!$K$23 -> 2.9786877 | U23: 12 | V23: =S23--0.037*$U23 -> 50.677018 | W23: =T23-'Drift correction'!D$4*$U23 -> 3.4940327 | X23: =V23/W23 -> 14.503876
A24: 501 | B24: 111 | C24: B | D24: 67 | E24: R | F24: 1 | G24: 29 | H24: =CONCATENATE("M0",B24,"-",C24, "-",D24, "-",F24) -> M0111-B-67-1 | I24: =VLOOKUP(H26,'Depth vlookup'!G25:I1072,2,FALSE())+G26/100 -> 206.14 | J24: 1 | K24: 43.03 | L24: 21.1 | M24: =N24*1000 -> 4100 | N24: 4.1 | O24: 21.8 | P24: 6 | Q24: =K24*('Temperature Corrections'!$D$9+'Temperature Corrections'!$D$10*'Data Entry'!$L24+('Temperature Corrections'!$D$11*('Data Entry'!$L24^2))+('Temperature Corrections'!$D$12*('Data Entry'!$L24^3))+('Temperature Corrections'!$D$13*('Data Entry'!$L24^4))+('Temperature Corrections'!$D$14*('Data Entry'!$L24^5)))/'Temperature Corrections'!$G$6 -> 44.039635 | R24: =N24*('Temperature Corrections'!$D$9+'Temperature Corrections'!$D$10*'Data Entry'!$O24+('Temperature Corrections'!$D$11*('Data Entry'!$O24^2))+('Temperature Corrections'!$D$12*('Data Entry'!$O24^3))+('Temperature Corrections'!$D$13*('Data Entry'!$O24^4))+('Temperature Corrections'!$D$14*('Data Entry'!$O24^5)))/'Temperature Corrections'!$G$6 -> 4.2577139 | S24: =Q24*'Salinity Corrections'!$K$23/'Salinity Corrections'!$K$26 -> 50.821419 | T24: =R24*('Salinity Corrections'!$K$22*'Salinity Corrections'!$I$22+'Salinity Corrections'!$I$23)/'Salinity Corrections'!$K$23 -> 4.2688138 | U24: 13 | V24: =S24--0.037*$U24 -> 51.302419 | W24: =T24-'Drift correction'!D$4*$U24 -> 4.8271041 | X24: =V24/W24 -> 10.627991
A25: 501 | B25: 111 | C25: B | D25: 67 | E25: R | F25: 1 | G25: 32 | H25: =CONCATENATE("M0",B25,"-",C25, "-",D25, "-",F25) -> M0111-B-67-1 | I25: =VLOOKUP(H27,'Depth vlookup'!G26:I1073,2,FALSE())+G27/100 -> 206.18 | J25: 1 | K25: 43 | L25: 21.1 | M25: =N25*1000 -> 4015 | N25: 4.015 | O25: 21.7 | P25: 6 | Q25: =K25*('Temperature Corrections'!$D$9+'Temperature Corrections'!$D$10*'Data Entry'!$L25+('Temperature Corrections'!$D$11*('Data Entry'!$L25^2))+('Temperature Corrections'!$D$12*('Data Entry'!$L25^3))+('Temperature Corrections'!$D$13*('Data Entry'!$L25^4))+('Temperature Corrections'!$D$14*('Data Entry'!$L25^5)))/'Temperature Corrections'!$G$6 -> 44.008931 | R25: =N25*('Temperature Corrections'!$D$9+'Temperature Corrections'!$D$10*'Data Entry'!$O25+('Temperature Corrections'!$D$11*('Data Entry'!$O25^2))+('Temperature Corrections'!$D$12*('Data Entry'!$O25^3))+('Temperature Corrections'!$D$13*('Data Entry'!$O25^4))+('Temperature Corrections'!$D$14*('Data Entry'!$O25^5)))/'Temperature Corrections'!$G$6 -> 4.1608257 | S25: =Q25*'Salinity Corrections'!$K$23/'Salinity Corrections'!$K$26 -> 50.785987 | T25: =R25*('Salinity Corrections'!$K$22*'Salinity Corrections'!$I$22+'Salinity Corrections'!$I$23)/'Salinity Corrections'!$K$23 -> 4.1716729 | U25: 14 | V25: =S25--0.037*$U25 -> 51.303987 | W25: =T25-'Drift correction'!D$4*$U25 -> 4.7729087 | X25: =V25/W25 -> 10.748998
A26: 501 | B26: 111 | C26: B | D26: 71 | E26: R | F26: 1 | G26: 3 | H26: =CONCATENATE("M0",B26,"-",C26, "-",D26, "-",F26) -> M0111-B-71-1 | I26: =VLOOKUP(H28,'Depth vlookup'!G27:I1074,2,FALSE())+G28/100 -> 234.14 | J26: 1 | K26: 43 | L26: 21.2 | M26: =N26*1000 -> 3383 | N26: 3.383 | O26: 20.5 | P26: 6 | Q26: =K26*('Temperature Corrections'!$D$9+'Temperature Corrections'!$D$10*'Data Entry'!$L26+('Temperature Corrections'!$D$11*('Data Entry'!$L26^2))+('Temperature Corrections'!$D$12*('Data Entry'!$L26^3))+('Temperature Corrections'!$D$13*('Data Entry'!$L26^4))+('Temperature Corrections'!$D$14*('Data Entry'!$L26^5)))/'Temperature Corrections'!$G$6 -> 44.100952 | R26: =N26*('Temperature Corrections'!$D$9+'Temperature Corrections'!$D$10*'Data Entry'!$O26+('Temperature Corrections'!$D$11*('Data Entry'!$O26^2))+('Temperature Corrections'!$D$12*('Data Entry'!$O26^3))+('Temperature Corrections'!$D$13*('Data Entry'!$O26^4))+('Temperature Corrections'!$D$14*('Data Entry'!$O26^5)))/'Temperature Corrections'!$G$6 -> 3.4190204 | S26: =Q26*'Salinity Corrections'!$K$23/'Salinity Corrections'!$K$26 -> 50.892178 | T26: =R26*('Salinity Corrections'!$K$22*'Salinity Corrections'!$I$22+'Salinity Corrections'!$I$23)/'Salinity Corrections'!$K$23 -> 3.4279338 | U26: 15 | V26: =S26--0.037*$U26 -> 51.447178 | W26: =T26-'Drift correction'!D$4*$U26 -> 4.072115 | X26: =V26/W26 -> 12.634019
A27: 501 | B27: 111 | C27: B | D27: 71 | E27: R | F27: 1 | G27: 7 | H27: =CONCATENATE("M0",B27,"-",C27, "-",D27, "-",F27) -> M0111-B-71-1 | I27: =VLOOKUP(H29,'Depth vlookup'!G28:I1075,2,FALSE())+G29/100 -> 234.16 | J27: 1 | K27: 43 | L27: 21.2 | M27: =N27*1000 -> 3524 | N27: 3.524 | O27: 20.4 | P27: 6 | Q27: =K27*('Temperature Corrections'!$D$9+'Temperature Corrections'!$D$10*'Data Entry'!$L27+('Temperature Corrections'!$D$11*('Data Entry'!$L27^2))+('Temperature Corrections'!$D$12*('Data Entry'!$L27^3))+('Temperature Corrections'!$D$13*('Data Entry'!$L27^4))+('Temperature Corrections'!$D$14*('Data Entry'!$L27^5)))/'Temperature Corrections'!$G$6 -> 44.100952 | R27: =N27*('Temperature Corrections'!$D$9+'Temperature Corrections'!$D$10*'Data Entry'!$O27+('Temperature Corrections'!$D$11*('Data Entry'!$O27^2))+('Temperature Corrections'!$D$12*('Data Entry'!$O27^3))+('Temperature Corrections'!$D$13*('Data Entry'!$O27^4))+('Temperature Corrections'!$D$14*('Data Entry'!$O27^5)))/'Temperature Corrections'!$G$6 -> 3.5540089 | S27: =Q27*'Salinity Corrections'!$K$23/'Salinity Corrections'!$K$26 -> 50.892178 | T27: =R27*('Salinity Corrections'!$K$22*'Salinity Corrections'!$I$22+'Salinity Corrections'!$I$23)/'Salinity Corrections'!$K$23 -> 3.5632741 | U27: 16 | V27: =S27--0.037*$U27 -> 51.484178 | W27: =T27-'Drift correction'!D$4*$U27 -> 4.2504008 | X27: =V27/W27 -> 12.112782
A28: 501 | B28: 111 | C28: B | D28: 87 | E28: R | F28: 1 | G28: 41 | H28: =CONCATENATE("M0",B28,"-",C28, "-",D28, "-",F28) -> M0111-B-87-1 | I28: =VLOOKUP(H30,'Depth vlookup'!G29:I1076,2,FALSE())+G30/100 -> 245.69 | J28: 1 | K28: 42.75 | L28: 21.1 | M28: =N28*1000 -> 2463 | N28: 2.463 | O28: 18.9 | P28: 6 | Q28: =K28*('Temperature Corrections'!$D$9+'Temperature Corrections'!$D$10*'Data Entry'!$L28+('Temperature Corrections'!$D$11*('Data Entry'!$L28^2))+('Temperature Corrections'!$D$12*('Data Entry'!$L28^3))+('Temperature Corrections'!$D$13*('Data Entry'!$L28^4))+('Temperature Corrections'!$D$14*('Data Entry'!$L28^5)))/'Temperature Corrections'!$G$6 -> 43.753065 | R28: =N28*('Temperature Corrections'!$D$9+'Temperature Corrections'!$D$10*'Data Entry'!$O28+('Temperature Corrections'!$D$11*('Data Entry'!$O28^2))+('Temperature Corrections'!$D$12*('Data Entry'!$O28^3))+('Temperature Corrections'!$D$13*('Data Entry'!$O28^4))+('Temperature Corrections'!$D$14*('Data Entry'!$O28^5)))/'Temperature Corrections'!$G$6 -> 2.4055776 | S28: =Q28*'Salinity Corrections'!$K$23/'Salinity Corrections'!$K$26 -> 50.49072 | T28: =R28*('Salinity Corrections'!$K$22*'Salinity Corrections'!$I$22+'Salinity Corrections'!$I$23)/'Salinity Corrections'!$K$23 -> 2.411849 | U28: 17 | V28: =S28--0.037*$U28 -> 51.11972 | W28: =T28-'Drift correction'!D$4*$U28 -> 3.141921 | X28: =V28/W28 -> 16.270212
A29: 501 | B29: 111 | C29: B | D29: 87 | E29: R | F29: 1 | G29: 43 | H29: =CONCATENATE("M0",B29,"-",C29, "-",D29, "-",F29) -> M0111-B-87-1 | I29: =VLOOKUP(H31,'Depth vlookup'!G30:I1077,2,FALSE())+G31/100 -> 245.71 | J29: 1 | K29: 42.75 | L29: 21.1 | M29: =N29*1000 -> 2319 | N29: 2.319 | O29: 19 | P29: 6 | Q29: =K29*('Temperature Corrections'!$D$9+'Temperature Corrections'!$D$10*'Data Entry'!$L29+('Temperature Corrections'!$D$11*('Data Entry'!$L29^2))+('Temperature Corrections'!$D$12*('Data Entry'!$L29^3))+('Temperature Corrections'!$D$13*('Data Entry'!$L29^4))+('Temperature Corrections'!$D$14*('Data Entry'!$L29^5)))/'Temperature Corrections'!$G$6 -> 43.753065 | R29: =N29*('Temperature Corrections'!$D$9+'Temperature Corrections'!$D$10*'Data Entry'!$O29+('Temperature Corrections'!$D$11*('Data Entry'!$O29^2))+('Temperature Corrections'!$D$12*('Data Entry'!$O29^3))+('Temperature Corrections'!$D$13*('Data Entry'!$O29^4))+('Temperature Corrections'!$D$14*('Data Entry'!$O29^5)))/'Temperature Corrections'!$G$6 -> 2.2698347 | S29: =Q29*'Salinity Corrections'!$K$23/'Salinity Corrections'!$K$26 -> 50.49072 | T29: =R29*('Salinity Corrections'!$K$22*'Salinity Corrections'!$I$22+'Salinity Corrections'!$I$23)/'Salinity Corrections'!$K$23 -> 2.2757522 | U29: 18 | V29: =S29--0.037*$U29 -> 51.15672 | W29: =T29-'Drift correction'!D$4*$U29 -> 3.0487696 | X29: =V29/W29 -> 16.779464
A30: 501 | B30: 111 | C30: B | D30: 93 | E30: R | F30: 1 | G30: 41 | H30: =CONCATENATE("M0",B30,"-",C30, "-",D30, "-",F30) -> M0111-B-93-1 | I30: =VLOOKUP(H32,'Depth vlookup'!G31:I1078,2,FALSE())+G32/100 -> 265.16 | J30: 1 | K30: 42.05 | L30: 20.6 | M30: =N30*1000 -> 4183 | N30: 4.183 | O30: 20.6 | P30: 6 | Q30: =K30*('Temperature Corrections'!$D$9+'Temperature Corrections'!$D$10*'Data Entry'!$L30+('Temperature Corrections'!$D$11*('Data Entry'!$L30^2))+('Temperature Corrections'!$D$12*('Data Entry'!$L30^3))+('Temperature Corrections'!$D$13*('Data Entry'!$L30^4))+('Temperature Corrections'!$D$14*('Data Entry'!$L30^5)))/'Temperature Corrections'!$G$6 -> 42.587423 | R30: =N30*('Temperature Corrections'!$D$9+'Temperature Corrections'!$D$10*'Data Entry'!$O30+('Temperature Corrections'!$D$11*('Data Entry'!$O30^2))+('Temperature Corrections'!$D$12*('Data Entry'!$O30^3))+('Temperature Corrections'!$D$13*('Data Entry'!$O30^4))+('Temperature Corrections'!$D$14*('Data Entry'!$O30^5)))/'Temperature Corrections'!$G$6 -> 4.2364611 | S30: =Q30*'Salinity Corrections'!$K$23/'Salinity Corrections'!$K$26 -> 49.145577 | T30: =R30*('Salinity Corrections'!$K$22*'Salinity Corrections'!$I$22+'Salinity Corrections'!$I$23)/'Salinity Corrections'!$K$23 -> 4.2475056 | U30: 19 | V30: =S30--0.037*$U30 -> 49.848577 | W30: =T30-'Drift correction'!D$4*$U30 -> 5.0634684 | X30: =V30/W30 -> 9.8447493
A31: 501 | B31: 111 | C31: B | D31: 93 | E31: R | F31: 1 | G31: 43 | H31: =CONCATENATE("M0",B31,"-",C31, "-",D31, "-",F31) -> M0111-B-93-1 | I31: =VLOOKUP(H33,'Depth vlookup'!G32:I1079,2,FALSE())+G33/100 -> 265.19 | J31: 1 | K31: 42.1 | L31: 20.6 | M31: =N31*1000 -> 3477 | N31: 3.477 | O31: 20.4 | P31: 6 | Q31: =K31*('Temperature Corrections'!$D$9+'Temperature Corrections'!$D$10*'Data Entry'!$L31+('Temperature Corrections'!$D$11*('Data Entry'!$L31^2))+('Temperature Corrections'!$D$12*('Data Entry'!$L31^3))+('Temperature Corrections'!$D$13*('Data Entry'!$L31^4))+('Temperature Corrections'!$D$14*('Data Entry'!$L31^5)))/'Temperature Corrections'!$G$6 -> 42.638062 | R31: =N31*('Temperature Corrections'!$D$9+'Temperature Corrections'!$D$10*'Data Entry'!$O31+('Temperature Corrections'!$D$11*('Data Entry'!$O31^2))+('Temperature Corrections'!$D$12*('Data Entry'!$O31^3))+('Temperature Corrections'!$D$13*('Data Entry'!$O31^4))+('Temperature Corrections'!$D$14*('Data Entry'!$O31^5)))/'Temperature Corrections'!$G$6 -> 3.5066086 | S31: =Q31*'Salinity Corrections'!$K$23/'Salinity Corrections'!$K$26 -> 49.204014 | T31: =R31*('Salinity Corrections'!$K$22*'Salinity Corrections'!$I$22+'Salinity Corrections'!$I$23)/'Salinity Corrections'!$K$23 -> 3.5157503 | U31: 20 | V31: =S31--0.037*$U31 -> 49.944014 | W31: =T31-'Drift correction'!D$4*$U31 -> 4.3746586 | X31: =V31/W31 -> 11.416666
... A41: 501 | B41: 111 | C41: B | D41: 155 | E41: R | F41: 1 | G41: 37 | H41: =CONCATENATE("M0",B41,"-",C41, "-",D41, "-",F41) -> M0111-B-155-1 | I41: =VLOOKUP(H43,'Depth vlookup'!G42:I1089,2,FALSE())+G43/100 -> 381.44 | J41: 1 | K41: 42.06 | L41: 21.3 | M41: =N41*1000 -> 7298 | N41: 7.298 | O41: 20.6 | P41: 25 | Q41: =K41*('Temperature Corrections'!$D$9+'Temperature Corrections'!$D$10*'Data Entry'!$L41+('Temperature Corrections'!$D$11*('Data Entry'!$L41^2))+('Temperature Corrections'!$D$12*('Data Entry'!$L41^3))+('Temperature Corrections'!$D$13*('Data Entry'!$L41^4))+('Temperature Corrections'!$D$14*('Data Entry'!$L41^5)))/'Temperature Corrections'!$G$6 -> 43.22694 | R41: =N41*('Temperature Corrections'!$D$9+'Temperature Corrections'!$D$10*'Data Entry'!$O41+('Temperature Corrections'!$D$11*('Data Entry'!$O41^2))+('Temperature Corrections'!$D$12*('Data Entry'!$O41^3))+('Temperature Corrections'!$D$13*('Data Entry'!$O41^4))+('Temperature Corrections'!$D$14*('Data Entry'!$O41^5)))/'Temperature Corrections'!$G$6 -> 7.3912726 | S41: =Q41*'Salinity Corrections'!$K$23/'Salinity Corrections'!$K$26 -> 49.883576 | T41: =R41*('Salinity Corrections'!$K$22*'Salinity Corrections'!$I$22+'Salinity Corrections'!$I$23)/'Salinity Corrections'!$K$23 -> 7.4105416 | U41: 30 | V41: =S41--0.037*$U41 -> 50.993576 | W41: =T41-'Drift correction'!D$4*$U41 -> 8.698904 | X41: =V41/W41 -> 5.862069
A42: 501 | B42: 111 | C42: B | D42: 166 | E42: R | F42: 1 | G42: 40 | H42: =CONCATENATE("M0",B42,"-",C42, "-",D42, "-",F42) -> M0111-B-166-1
A43: 501 | B43: 111 | C43: B | D43: 166 | E43: R | F43: 1 | G43: 41 | H43: =CONCATENATE("M0",B43,"-",C43, "-",D43, "-",F43) -> M0111-B-166-1

Sheet Drift correction
A3: sample number | B3: T and S corrected reference | C3: removed | D3: USE THIS SLOPE
A4: ='Data Entry'!U12 -> 1 | B4: ='Data Entry'!S12 -> 51.530061 | D4: =SLOPE(B4:B33,A4:A33) -> -0.042945413
A5: ='Data Entry'!U13 -> 2 | B5: ='Data Entry'!S13 -> 51.494629
A6: ='Data Entry'!U14 -> 3 | B6: ='Data Entry'!S14 -> 50.89133
A7: ='Data Entry'!U15 -> 4 | B7: ='Data Entry'!S15 -> 50.89133
A8: ='Data Entry'!U16 -> 5 | C8: ='Data Entry'!S16 -> 48.684246
A9: ='Data Entry'!U17 -> 6 | C9: ='Data Entry'!S17 -> 48.684246
A10: ='Data Entry'!U18 -> 7 | B10: ='Data Entry'!S18 -> 51.59143
A11: ='Data Entry'!U19 -> 8 | B11: ='Data Entry'!S19 -> 51.59143
A12: ='Data Entry'!U20 -> 9 | B12: ='Data Entry'!S20 -> 51.176227
A13: ='Data Entry'!U21 -> 10 | B13: ='Data Entry'!S21 -> 51.164392
A14: ='Data Entry'!U22 -> 11 | B14: ='Data Entry'!S22 -> 50.279965
A15: ='Data Entry'!U23 -> 12 | B15: ='Data Entry'!S23 -> 50.233018
A16: ='Data Entry'!U24 -> 13 | B16: ='Data Entry'!S24 -> 50.821419
A17: ='Data Entry'!U25 -> 14 | B17: ='Data Entry'!S25 -> 50.785987
A18: ='Data Entry'!U26 -> 15 | B18: ='Data Entry'!S26 -> 50.892178
A19: ='Data Entry'!U27 -> 16 | B19: ='Data Entry'!S27 -> 50.892178
A20: ='Data Entry'!U28 -> 17 | B20: ='Data Entry'!S28 -> 50.49072
A21: ='Data Entry'!U29 -> 18 | B21: ='Data Entry'!S29 -> 50.49072
A22: ='Data Entry'!U30 -> 19 | C22: ='Data Entry'!S30 -> 49.145577
A23: ='Data Entry'!U31 -> 20 | C23: ='Data Entry'!S31 -> 49.204014
A24: ='Data Entry'!U32 -> 21 | B24: ='Data Entry'!S32 -> 50.939144
A25: ='Data Entry'!U33 -> 22 | B25: ='Data Entry'!S33 -> 50.939144
A26: ='Data Entry'!U34 -> 23 | B26: ='Data Entry'!S34 -> 50.100967
A27: ='Data Entry'!U35 -> 24 | B27: ='Data Entry'!S35 -> 50.100967
A28: ='Data Entry'!U36 -> 25 | C28: ='Data Entry'!S36 -> 49.026615
A29: ='Data Entry'!U37 -> 26 | C29: ='Data Entry'!S37 -> 49.026615
A30: ='Data Entry'!U38 -> 27 | B30: ='Data Entry'!S38 -> 50.547741
A31: ='Data Entry'!U39 -> 28 | B31: ='Data Entry'!S39 -> 50.547741
A32: ='Data Entry'!U40 -> 29 | B32: ='Data Entry'!S40 -> 49.883576
A33: ='Data Entry'!U41 -> 30 | B33: ='Data Entry'!S41 -> 49.883576

Sheet Depth vlookup
A1: Expedition | B1: Site | C1: Hole | D1: Core | E1: Type | F1: Section | G1: Combined | H1: top_depth | I1: bottom_depth
A2: 501 | B2: M0111 | C2: A | D2: 1 | E2: H | F2: 1 | G2: =CONCATENATE(B2, "-",C2, "-", D2, "-", F2) -> M0111-A-1-1 | H2: 0 | I2: 1.5
A3: 501 | B3: M0111 | C3: A | D3: 1 | E3: H | F3: 2 | G3: =CONCATENATE(B3, "-",C3, "-", D3, "-", F3) -> M0111-A-1-2 | H3: 1.5 | I3: 2.9
A4: 501 | B4: M0111 | C4: A | D4: 2 | E4: H | F4: 1 | G4: =CONCATENATE(B4, "-",C4, "-", D4, "-", F4) -> M0111-A-2-1 | H4: 2.4 | I4: 3.91
A5: 501 | B5: M0111 | C5: A | D5: 2 | E5: H | F5: 2 | G5: =CONCATENATE(B5, "-",C5, "-", D5, "-", F5) -> M0111-A-2-2 | H5: 3.91 | I5: 4.99
A6: 501 | B6: M0111 | C6: A | D6: 3 | E6: H | F6: 1 | G6: =CONCATENATE(B6, "-",C6, "-", D6, "-", F6) -> M0111-A-3-1 | H6: 4.46 | I6: 5.97
A7: 501 | B7: M0111 | C7: A | D7: 3 | E7: H | F7: 2 | G7: =CONCATENATE(B7, "-",C7, "-", D7, "-", F7) -> M0111-A-3-2 | H7: 5.97 | I7: 7.1
A8: 501 | B8: M0111 | C8: A | D8: 4 | E8: H | F8: 1 | G8: =CONCATENATE(B8, "-",C8, "-", D8, "-", F8) -> M0111-A-4-1 | H8: 6.89 | I8: 8.4
A9: 501 | B9: M0111 | C9: A | D9: 4 | E9: H | F9: 2 | G9: =CONCATENATE(B9, "-",C9, "-", D9, "-", F9) -> M0111-A-4-2 | H9: 8.4 | I9: 9.6
A10: 501 | B10: M0111 | C10: A | D10: 5 | E10: H | F10: 1 | G10: =CONCATENATE(B10, "-",C10, "-", D10, "-", F10) -> M0111-A-5-1 | H10: 9.6 | I10: 11.1
A11: 501 | B11: M0111 | C11: A | D11: 5 | E11: H | F11: 2 | G11: =CONCATENATE(B11, "-",C11, "-", D11, "-", F11) -> M0111-A-5-2 | H11: 11.1 | I11: 12.05
A12: 501 | B12: M0111 | C12: A | D12: 6 | E12: H | F12: 1 | G12: =CONCATENATE(B12, "-",C12, "-", D12, "-", F12) -> M0111-A-6-1 | H12: 11.7 | I12: 13.2
A13: 501 | B13: M0111 | C13: A | D13: 6 | E13: H | F13: 2 | G13: =CONCATENATE(B13, "-",C13, "-", D13, "-", F13) -> M0111-A-6-2 | H13: 13.2 | I13: 13.94
... A259: 501 | B259: M0111 | C259: B | D259: 139 | E259: R | F259: 1 | G259: =CONCATENATE(B259, "-",C259, "-", D259, "-", F259) -> M0111-B-139-1 | H259: 336.33 | I259: 337.24
A260: 501 | B260: M0111 | C260: B | D260: 140 | E260: R | F260: 1 | G260: =CONCATENATE(B260, "-",C260, "-", D260, "-", F260) -> M0111-B-140-1 | H260: 338.03 | I260: 338.65 | T260: 368.83
A261: 501 | B261: M0111 | C261: B | D261: 141 | E261: R | F261: 1 | G261: =CONCATENATE(B261, "-",C261, "-", D261, "-", F261) -> M0111-B-141-1 | H261: 339.68 | I261: 339.81 | T261: 371.23
A262: 501 | B262: M0111 | C262: B | D262: 144 | E262: R | F262: 1 | G262: =CONCATENATE(B262, "-",C262, "-", D262, "-", F262) -> M0111-B-144-1 | H262: 344.43 | I262: 344.89 | T262: 373.93
A263: 501 | B263: M0111 | C263: B | D263: 146 | E263: R | F263: 1 | G263: =CONCATENATE(B263, "-",C263, "-", D263, "-", F263) -> M0111-B-146-1 | H263: 345.78 | I263: 345.82 | T263: 374.93
A264: 501 | B264: M0111 | C264: B | D264: 147 | E264: R | F264: 1 | G264: =CONCATENATE(B264, "-",C264, "-", D264, "-", F264) -> M0111-B-147-1 | H264: 346.13 | I264: 346.57
A265: 501 | B265: M0111 | C265: B | D265: 149 | E265: R | F265: 1 | G265: =CONCATENATE(B265, "-",C265, "-", D265, "-", F265) -> M0111-B-149-1 | H265: 348.03 | I265: 349.15
A266: 501 | B266: M0111 | C266: B | D266: 150 | E266: R | F266: 1 | G266: =CONCATENATE(B266, "-",C266, "-", D266, "-", F266) -> M0111-B-150-1 | H266: 349.03 | I266: 349.13
A267: 501 | B267: M0111 | C267: B | D267: 151 | E267: R | F267: 1 | G267: =CONCATENATE(B267, "-",C267, "-", D267, "-", F267) -> M0111-B-151-1 | H267: 350.03 | I267: 350.67
A268: 501 | B268: M0111 | C268: B | D268: 152 | E268: R | F268: 1 | G268: =CONCATENATE(B268, "-",C268, "-", D268, "-", F268) -> M0111-B-152-1 | H268: 351.28 | I268: 351.62
A269: 501 | B269: M0111 | C269: B | D269: 154 | E269: R | F269: 1 | G269: =CONCATENATE(B269, "-",C269, "-", D269, "-", F269) -> M0111-B-154-1 | H269: 353.58 | I269: 353.81
A270: 501 | B270: M0111 | C270: B | D270: 155 | E270: R | F270: 1 | G270: =CONCATENATE(B270, "-",C270, "-", D270, "-", F270) -> M0111-B-155-1 | H270: 355.55 | I270: 356.52
A271: 501 | B271: M0111 | C271: B | D271: 156 | E271: R | F271: 1 | G271: =CONCATENATE(B271, "-",C271, "-", D271, "-", F271) -> M0111-B-156-1 | H271: 358.6 | I271: 358.75
A272: 501 | B272: M0111 | C272: B | D272: 157 | E272: R | F272: 1 | G272: =CONCATENATE(B272, "-",C272, "-", D272, "-", F272) -> M0111-B-157-1 | H272: 360.83 | I272: 361.57
A273: 501 | B273: M0111 | C273: B | D273: 158 | E273: R | F273: 1 | G273: =CONCATENATE(B273, "-",C273, "-", D273, "-", F273) -> M0111-B-158-1 | H273: 361.73 | I273: 362.35
A274: 501 | B274: M0111 | C274: B | D274: 158 | E274: R | F274: 2 | G274: =CONCATENATE(B274, "-",C274, "-", D274, "-", F274) -> M0111-B-158-2 | H274: 362.35 | I274: 362.72
A275: 501 | B275: M0111 | C275: B | D275: 159 | E275: R | F275: 1 | G275: =CONCATENATE(B275, "-",C275, "-", D275, "-", F275) -> M0111-B-159-1 | H275: 364.78 | I275: 365.38
... A281: 501 | B281: M0111 | C281: B | D281: 168 | E281: R | F281: 1 | G281: =CONCATENATE(B281, "-",C281, "-", D281, "-", F281) -> M0111-B-168-1 | H281: 383.08 | I281: 383.25
A282: 501 | B282: M0111 | C282: B | D282: 169 | E282: R | F282: 1 | G282: =CONCATENATE(B282, "-",C282, "-", D282, "-", F282) -> M0111-B-169-1 | H282: 384.08 | I282: 384.26 | T282: 377.98
A283: 501 | B283: M0111 | C283: B | D283: 171 | E283: R | F283: 1 | G283: =CONCATENATE(B283, "-",C283, "-", D283, "-", F283) -> M0111-B-171-1 | H283: 389.18 | I283: 389.3 | T283: 381.03
A284: 501 | B284: M0111 | C284: C | D284: 1 | E284: H | F284: 1 | G284: =CONCATENATE(B284, "-",C284, "-", D284, "-", F284) -> M0111-C-1-1 | H284: 45.56 | I284: 47.06
A285: 501 | B285: M0111 | C285: C | D285: 1 | E285: H | F285: 2 | G285: =CONCATENATE(B285, "-",C285, "-", D285, "-", F285) -> M0111-C-1-2 | H285: 47.06 | I285: 47.67
A286: 501 | B286: M0111 | C286: C | D286: 2 | E286: H | F286: 1 | G286: =CONCATENATE(B286, "-",C286, "-", D286, "-", F286) -> M0111-C-2-1 | H286: 47.67 | I286: 48.24
A287: 501 | B287: M0111 | C287: C | D287: 2 | E287: H | F287: 2 | G287: =CONCATENATE(B287, "-",C287, "-", D287, "-", F287) -> M0111-C-2-2 | H287: 48.24 | I287: 48.56
A288: 501 | B288: M0111 | C288: C | D288: 3 | E288: H | F288: 1 | G288: =CONCATENATE(B288, "-",C288, "-", D288, "-", F288) -> M0111-C-3-1 | H288: 48.56 | I288: 49.77
A289: 501 | B289: M0111 | C289: C | D289: 3 | E289: H | F289: 2 | G289: =CONCATENATE(B289, "-",C289, "-", D289, "-", F289) -> M0111-C-3-2 | H289: 49.77 | I289: 50
A290: 501 | B290: M0111 | C290: C | D290: 4 | E290: H | F290: 1 | G290: =CONCATENATE(B290, "-",C290, "-", D290, "-", F290) -> M0111-C-4-1 | H290: 50 | I290: 51.1
...

Sheet salinity data
A1: Core Start | B1: Core Stop | C1: Salinity
A2: 501_M0111_A_001H | B2: 501_M0111_A_027H | C2: 32
A4: 501_M0111_B_001H | B4: 501_M0111_B_024R | C4: 30
A5: 501_M0111_B_025R | B5: 501_M0111_B_043R | C5: 12
A6: 501_M0111_B_044R | B6: 501_M0111_B_129R | C6: 6
A7: 501_M0111_B_130R | B7: base of core | C7: 25
A9: 501_M0111_C_002H | B9: 501_M0111_C_002H | C9: 32
A10: 501_M0111_C_002H | B10: 501_M0111_C_9R | C10: 12
A11: 501_M0111_C_010R | B11: 501_M0111_C_039R | C11: 6
A13: 501_M0112_A_001H | B13: 501_M0112_A_036R | C13: 32
A14: 501_M0112_A_037R | B14: 501_M0112_A_051R | C14: 12
A15: 501_M0112_A_052R | B15: 501_M0112_A_051R | C15: 4
A17: 501_M0112_B_002H | B17: 501_M0112_B_010R | C17: 27
... A22: 501_M0113_A_186H | B22: base of hole | C22: 29

Sheet Temperature Corrections
A2: Fa = Re/Rf. | C2: Temperature correction
C5: Both seawater and sediment measurements of electrical conductivity were adjusted to a standard temperature of 25°C where the correction factor is given by a fifth-order polynomial (Janz and Singer, 1975), | G5: 20
C6: χ = a + bT + cT2 + dT3 + eT4 + fT5, | F6: χ | G6: =$D9+$D10*G5+($D11*(G5^2))+($D12*(G5^3))+($D13*(G5^4))+($D14*(G5^5)) -> 47.893293
C7: where
C9: a | D9: 29.05128
C10: b | D10: 0.88082
C11: c | D11: -0.000198312
C12: d | D12: 0.00033363
C13: e | D13: -1.0776e-05
C14: f | D14: 1.12518e-07
C16: The temperature corrected measurement, σT, is given by
C17: σT = σ × (χ25/χobs),
C18: where σ is the measurement and χ20 and χobs are the correction factors using 25°C and the observed temperature, respectively. Both seawater and sediment measurements of electrical conductivity are adjusted for the effects of temperature. A linear drift correction based on the seawater measurements is computed and applied to both the sediment and seawater temperature adjusted measurements and the formation factor, F, is computed as,
C19: F = χsw/χsed.

Sheet Salinity Corrections
F2: mix= 0*(1-f)+ 35*f
A3: salinity dilution series for refractometer conductivity relationship | F3: f = mix/35 | H3: Known Salinity | I3: Measured Refraction | L3: Average
D4: 50 | H4: 9.997 | I4: 1.33496 | J4: 1.33498 | K4: 1.33496 | L4: =AVERAGE(I4:K4) -> 1.3349667
B5: 0 | C5: 34.993 | D5: DI | E5: IAPSO | F5: Actual | H5: 30 | I5: 1.3386 | J5: 1.3386 | K5: 1.33863 | L5: =AVERAGE(I5:K5) -> 1.33861
A6: =0 -> 0 | B6: 1 | C6: 0 | D6: =B6*$D$4 -> 50 | E6: =$D$4-D6 -> 0 | F6: 0 | H6: 34.993 | I6: 1.33958 | J6: 1.3396 | K6: 1.33958 | L6: =AVERAGE(I6:K6) -> 1.3395867
A7: 2 | B7: =1-C7 -> 0.94284571 | C7: =A7/$C$5 -> 0.057154288 | D7: =B7*$D$4 -> 47.142286 | E7: =$D$4-D7 -> 2.8577144 | F7: 3 | H7: 37.999 | I7: 1.34015 | J7: 1.34013 | K7: 1.34011 | L7: =AVERAGE(I7:K7) -> 1.34013
A8: 5 | B8: =1-C8 -> 0.85711428 | C8: =A8/$C$5 -> 0.14288572 | D8: =B8*$D$4 -> 42.855714 | E8: =$D$4-D8 -> 7.144286 | F8: 3.57 | H8: 9.997 | I8: 1.33491 | J8: 1.33491 | K8: 1.33491 | L8: =AVERAGE(I8:K8) -> 1.33491
A9: 10 | B9: =1-C9 -> 0.71422856 | C9: =A9/$C$5 -> 0.28577144 | D9: =B9*$D$4 -> 35.711428 | E9: =$D$4-D9 -> 14.288572
A10: 25 | B10: =1-C10 -> 0.2855714 | C10: =A10/$C$5 -> 0.7144286 | D10: =B10*$D$4 -> 14.27857 | E10: =$D$4-D10 -> 35.72143 | H10: slope | I10: =SLOPE(L4:L8,H4:H8) -> 0.00018533043 | J10: reference salinity | K10: 34.993
A11: 35 | B11: =1-C11 -> -0.00020004001 | C11: =A11/$C$5 -> 1.0002 | D11: 0 | E11: =$D$4-D11 -> 50 | H11: intercept | I11: =INTERCEPT(L4:L8,H4:H8) -> 1.3330821
H12: RSQ | I12: =RSQ(L4:L8,H4:H8) -> 0.99988023
D13: TOTAL USED | E13: =SUM(E6:E11) -> 110.012
H14: Refractometer | I14: Refractometer | J14: Refractometer | K14: Average | L14: Salinity | M14: Conductivity | N14: T of conductivity | O14: T corr | P14: conductivity at 25
A15: Drift monitoring | H15: 1.33335 | I15: 1.33337 | J15: 1.33335 | K15: =AVERAGE(H15:J15) -> 1.3333567 | L15: =(K15-I$11)/I$10 -> 1.4817304 | M15: 3.918 | N15: 20.9 | O15: ='Temperature Corrections'!$D$9+'Temperature Corrections'!$D$10*$N15+('Temperature Corrections'!$D$11*($N15^2))+('Temperature Corrections'!$D$12*($N15^3))+('Temperature Corrections'!$D$13*($N15^4))+('Temperature Corrections'!$D$14*$N15^5) -> 48.812216 | P15: =M15*O15/'Temperature Corrections'!$G$6 -> 3.9931742
A16: measure reflectance | H16: 1.33394 | I16: 1.33395 | J16: 1.333976 | K16: =AVERAGE(H16:J16) -> 1.3339553 | L16: =(K16-I$11)/I$10 -> 4.7119968 | M16: 8.899 | N16: 20.9 | O16: ='Temperature Corrections'!$D$9+'Temperature Corrections'!$D$10*$N16+('Temperature Corrections'!$D$11*($N16^2))+('Temperature Corrections'!$D$12*($N16^3))+('Temperature Corrections'!$D$13*($N16^4))+('Temperature Corrections'!$D$14*$N16^5) -> 48.812216 | P16: =M16*O16/'Temperature Corrections'!$G$6 -> 9.0697441
A17: measure conductivity | H17: 1.33492 | I17: 1.33492 | J17: 1.33491 | K17: =AVERAGE(H17:J17) -> 1.3349167 | L17: =(K17-I$11)/I$10 -> 9.8991283 | M17: 16.8 | N17: 20.9 | O17: ='Temperature Corrections'!$D$9+'Temperature Corrections'!$D$10*$N17+('Temperature Corrections'!$D$11*($N17^2))+('Temperature Corrections'!$D$12*($N17^3))+('Temperature Corrections'!$D$13*($N17^4))+('Temperature Corrections'!$D$14*$N17^5) -> 48.812216 | P17: =M17*O17/'Temperature Corrections'!$G$6 -> 17.12234
H18: 1.33761 | I18: 1.33761 | J18: 1.33759 | K18: =AVERAGE(H18:J18) -> 1.3376033 | L18: =(K18-I$11)/I$10 -> 24.395758 | M18: 38.01 | N18: 20.9 | O18: ='Temperature Corrections'!$D$9+'Temperature Corrections'!$D$10*$N18+('Temperature Corrections'!$D$11*($N18^2))+('Temperature Corrections'!$D$12*($N18^3))+('Temperature Corrections'!$D$13*($N18^4))+('Temperature Corrections'!$D$14*$N18^5) -> 48.812216 | P18: =M18*O18/'Temperature Corrections'!$G$6 -> 38.739293
H19: 1.33952 | I19: 1.33952 | J19: 1.3395 | K19: =AVERAGE(H19:J19) -> 1.3395133 | L19: =(K19-I$11)/I$10 -> 34.701675 | M19: 50.85 | N19: 21 | O19: ='Temperature Corrections'!$D$9+'Temperature Corrections'!$D$10*$N19+('Temperature Corrections'!$D$11*($N19^2))+('Temperature Corrections'!$D$12*($N19^3))+('Temperature Corrections'!$D$13*($N19^4))+('Temperature Corrections'!$D$14*$N19^5) -> 48.914599 | P19: =M19*O19/'Temperature Corrections'!$G$6 -> 51.934357
H22: slope | I22: =SLOPE(M15:M19,L15:L19) -> 1.4212297 | J22: reference salinity | K22: 34.9994
H23: intercept | I23: =INTERCEPT(M15:M19,L15:L19) -> 2.3228651 | K23: =AVERAGE('Data Entry'!Q1:Q5) -> 51.929673
H24: RSQ | I24: =RSQ(M15:M19,L15:L19) -> 0.99868759
