Workbook

Sheet MAD
A1: Exp | B1: Site | C1: Hole | D1: Core | E1: Type | F1: Section | G1: Sample Top, cm | H1: Sample Bottom, cm | I1: Combined id | J1: Sample Label | K1: Sample Top Depth, mbsf | L1: Sample Bot Depth, mbsf | M1: Beaker Number | N1: Beaker Weight, g | O1: WET Weight (Sample + Beaker), g | P1: OVEN Date/Time IN | Q1: DRY Weight (Sample + Beaker), g | R1: Scientist | S1: Pycnometer Cell | T1: DRY Volume, cc | V1: WEIGHT WET Sample, g | W1: WEIGHT DRY Sample, g | X1: WEIGHT Pore Water, g | Y1: WEIGHT Salt, g | Z1: WEIGHT Grains, g | AA1: VOLUME Pore Water, cc | AB1: VOLUME Salt, cc | AC1: VOLUME Dry Sample, cc | AD1: VOLUME Wet Sample, cc | AE1: VOLUME Grains, cc | AF1: Water Content, (wet) v/v | AG1: Water Content (dry), v/v | AH1: Bulk Density, g/cc | AI1: Dry Density, g/cc | AJ1: Grain Density, g/cc | AK1: Porosity, v/v | AL1: Void Ratio, v/v | AM1: Lithology
A2: 501 | B2: M0111 | C2: C | D2: 1 | E2: H | F2: 1 | G2: 38 | H2: 40 | I2: =_xlfn.CONCAT(B2, "-", C2,"-", D2,"-", F2) -> M0111-C-1-1 | J2: =_xlfn.CONCAT(A2, "-", I2, ",",G2, "-",H2) -> 501-M0111-C-1-1,38-40 | K2: =VLOOKUP(I2, 'Depth vlookup'!$G$2:$I$997,2,FALSE)+(G2/100) -> 45.94 | L2: =K2+2/100 -> 45.96 | M2: 277 | N2: =VLOOKUP(M2, Beakers!$A$2:$B$151, 2, 0) -> 9.8652 | O2: 19.2447 | P2: 46045.821 | Q2: 17.9158 | R2: MS | S2: 1 | T2: 7.4896 | V2: =O2-N2 -> 9.3795 | W2: =Q5-N2 -> 8.5069 | X2: =(V2-W2)/(1-35/1000) -> 0.9042487 | Y2: =X2-(V2-W2) -> 0.031648705 | Z2: =W2-Y2 -> 8.4752513 | AA2: =X2/1.024 -> 0.88305538 | AB2: =Y2/2.22 -> 0.014256173 | AC2: =T2-VLOOKUP(M2, Beakers!$A$2:$C$151, 3, 0) -> 3.0657435 | AD2: =AC2-AB2+AA2 -> 3.9345427 | AE2: =AC2-AB2 -> 3.0514873 | AF2: =X2/V2 -> 0.09640692 | AG2: =X2/Z2 -> 0.10669285 | AH2: =V2/AD2 -> 2.3838857 | AI2: =Z2/AD2 -> 2.1540626 | AJ2: =Z2/AE2 -> 2.7774165 | AK2: =AA2/AD2 -> 0.2244366 | AL2: =AA2/AE2 -> 0.28938523 | AM2: sand
A3: 501 | B3: M0111 | C3: C | D3: 2 | E3: H | F3: 1 | G3: 38 | H3: 40 | I3: =_xlfn.CONCAT(B3, "-", C3,"-", D3,"-", F3) -> M0111-C-2-1 | J3: =_xlfn.CONCAT(A3, "-", I3, ",",G3, "-",H3) -> 501-M0111-C-2-1,38-40 | K3: =VLOOKUP(I3, 'Depth vlookup'!$G$2:$I$997,2,FALSE)+(G3/100) -> 48.05 | L3: =K3+2/100 -> 48.07 | M3: 278 | N3: =VLOOKUP(M3, Beakers!$A$2:$B$151, 2, 0) -> 10.157 | O3: 20.0211 | P3: 46045.839 | Q3: 16.9872 | R3: TS | S3: 1 | T3: 7.1081 | V3: =O3-N3 -> 9.8641 | W3: =Q3-N3 -> 6.8302 | X3: =(V3-W3)/(1-35/1000) -> 3.1439378 | Y3: =X3-(V3-W3) -> 0.11003782 | Z3: =W3-Y3 -> 6.7201622 | AA3: =X3/1.024 -> 3.0702518 | AB3: =Y3/2.22 -> 0.049566587 | AC3: =T3-VLOOKUP(M3, Beakers!$A$2:$C$151, 3, 0) -> 2.5533915 | AD3: =AC3-AB3+AA3 -> 5.5740767 | AE3: =AC3-AB3 -> 2.5038249 | AF3: =X3/V3 -> 0.31872526 | AG3: =X3/Z3 -> 0.4678366 | AH3: =V3/AD3 -> 1.7696384 | AI3: =Z3/AD3 -> 1.2056099 | AJ3: =Z3/AE3 -> 2.6839585 | AK3: =AA3/AD3 -> 0.55080903 | AL3: =AA3/AE3 -> 1.2262246 | AM3: clay
A4: 501 | B4: M0111 | C4: C | D4: 3 | E4: H | F4: 2 | G4: 2 | H4: 4 | I4: =_xlfn.CONCAT(B4, "-", C4,"-", D4,"-", F4) -> M0111-C-3-2 | J4: =_xlfn.CONCAT(A4, "-", I4, ",",G4, "-",H4) -> 501-M0111-C-3-2,2-4 | K4: =VLOOKUP(I4, 'Depth vlookup'!$G$2:$I$997,2,FALSE)+(G4/100) -> 49.79 | L4: =K4+2/100 -> 49.81 | M4: 279 | N4: =VLOOKUP(M4, Beakers!$A$2:$B$151, 2, 0) -> 9.9806 | O4: 19.7421 | P4: 46045.839 | Q4: 16.7874 | R4: TS | S4: 2 | T4: 7.0131 | V4: =O4-N4 -> 9.7615 | W4: =Q4-N4 -> 6.8068 | X4: =(V4-W4)/(1-35/1000) -> 3.0618653 | Y4: =X4-(V4-W4) -> 0.10716528 | Z4: =W4-Y4 -> 6.6996347 | AA4: =X4/1.024 -> 2.9901028 | AB4: =Y4/2.22 -> 0.048272651 | AC4: =T4-VLOOKUP(M4, Beakers!$A$2:$C$151, 3, 0) -> 2.5374946 | AD4: =AC4-AB4+AA4 -> 5.4793248 | AE4: =AC4-AB4 -> 2.489222 | AF4: =X4/V4 -> 0.3136675 | AG4: =X4/Z4 -> 0.45701974 | AH4: =V4/AD4 -> 1.7815151 | AI4: =Z4/AD4 -> 1.2227117 | AJ4: =Z4/AE4 -> 2.6914573 | AK4: =AA4/AD4 -> 0.54570644 | AL4: =AA4/AE4 -> 1.2012198 | AM4: clay
A5: 501 | B5: M0111 | C5: C | D5: 6 | E5: H | F5: 1 | G5: 17 | H5: 19 | I5: =_xlfn.CONCAT(B5, "-", C5,"-", D5,"-", F5) -> M0111-C-6-1 | J5: =_xlfn.CONCAT(A5, "-", I5, ",",G5, "-",H5) -> 501-M0111-C-6-1,17-19 | K5: =VLOOKUP(I5, 'Depth vlookup'!$G$2:$I$997,2,FALSE)+(G5/100) -> 111.53 | L5: =K5+2/100 -> 111.55 | M5: 161 | N5: =VLOOKUP(M5, Beakers!$A$2:$B$151, 2, 0) -> 9.7497 | O5: 20.4795 | P5: 46045.839 | Q5: 18.3721 | R5: TS | S5: 3 | T5: 7.5574 | V5: =O5-N5 -> 10.7298 | W5: =Q5-N5 -> 8.6224 | X5: =(V5-W5)/(1-35/1000) -> 2.1838342 | Y5: =X5-(V5-W5) -> 0.076434197 | Z5: =W5-Y5 -> 8.5459658 | AA5: =X5/1.024 -> 2.1326506 | AB5: =Y5/2.22 -> 0.034429818 | AC5: =T5-VLOOKUP(M5, Beakers!$A$2:$C$151, 3, 0) -> 3.1853372 | AD5: =AC5-AB5+AA5 -> 5.283558 | AE5: =AC5-AB5 -> 3.1509074 | AF5: =X5/V5 -> 0.20352981 | AG5: =X5/Z5 -> 0.25553978 | AH5: =V5/AD5 -> 2.0307906 | AI5: =Z5/AD5 -> 1.6174642 | AJ5: =Z5/AE5 -> 2.7122237 | AK5: =AA5/AD5 -> 0.4036391 | AL5: =AA5/AE5 -> 0.67683696 | AM5: clay
A6: 501 | B6: M0111 | C6: C | D6: 7 | E6: R | F6: 1 | G6: 38 | H6: 40 | I6: =_xlfn.CONCAT(B6, "-", C6,"-", D6,"-", F6) -> M0111-C-7-1 | J6: =_xlfn.CONCAT(A6, "-", I6, ",",G6, "-",H6) -> 501-M0111-C-7-1,38-40 | K6: =VLOOKUP(I6, 'Depth vlookup'!$G$2:$I$997,2,FALSE)+(G6/100) -> 120.74 | L6: =K6+2/100 -> 120.76 | M6: 168 | N6: =VLOOKUP(M6, Beakers!$A$2:$B$151, 2, 0) -> 9.8671 | O6: 19.9446 | P6: 46045.927 | Q6: 17.1862 | R6: TS | S6: 2 | T6: 7.1178 | V6: =O6-N6 -> 10.0775 | W6: =Q6-N6 -> 7.3191 | X6: =(V6-W6)/(1-35/1000) -> 2.8584456 | Y6: =X6-(V6-W6) -> 0.1000456 | Z6: =W6-Y6 -> 7.2190544 | AA6: =X6/1.024 -> 2.7914508 | AB6: =Y6/2.22 -> 0.045065584 | AC6: =T6-VLOOKUP(M6, Beakers!$A$2:$C$151, 3, 0) -> 2.6930915 | AD6: =AC6-AB6+AA6 -> 5.4394767 | AE6: =AC6-AB6 -> 2.6480259 | AF6: =X6/V6 -> 0.2836463 | AG6: =X6/Z6 -> 0.39595845 | AH6: =V6/AD6 -> 1.8526598 | AI6: =Z6/AD6 -> 1.3271597 | AJ6: =Z6/AE6 -> 2.7262023 | AK6: =AA6/AD6 -> 0.5131837 | AL6: =AA6/AE6 -> 1.0541629 | AM6: clay
A7: 501 | B7: M0111 | C7: C | D7: 8 | E7: R | F7: 2 | G7: 40 | H7: 42 | I7: =_xlfn.CONCAT(B7, "-", C7,"-", D7,"-", F7) -> M0111-C-8-2 | J7: =_xlfn.CONCAT(A7, "-", I7, ",",G7, "-",H7) -> 501-M0111-C-8-2,40-42 | K7: =VLOOKUP(I7, 'Depth vlookup'!$G$2:$I$997,2,FALSE)+(G7/100) -> 126.41 | L7: =K7+2/100 -> 126.43 | M7: 169 | N7: =VLOOKUP(M7, Beakers!$A$2:$B$151, 2, 0) -> 9.4825 | O7: 19.1778 | P7: 46045.927 | Q7: 17.1659 | R7: TS | S7: 3 | T7: 7.0971 | V7: =O7-N7 -> 9.6953 | W7: =Q7-N7 -> 7.6834 | X7: =(V7-W7)/(1-35/1000) -> 2.0848705 | Y7: =X7-(V7-W7) -> 0.072970466 | Z7: =W7-Y7 -> 7.6104295 | AA7: =X7/1.024 -> 2.0360063 | AB7: =Y7/2.22 -> 0.032869579 | AC7: =T7-VLOOKUP(M7, Beakers!$A$2:$C$151, 3, 0) -> 2.8448578 | AD7: =AC7-AB7+AA7 -> 4.8479946 | AE7: =AC7-AB7 -> 2.8119883 | AF7: =X7/V7 -> 0.21503929 | AG7: =X7/Z7 -> 0.27394912 | AH7: =V7/AD7 -> 1.9998578 | AI7: =Z7/AD7 -> 1.5698098 | AJ7: =Z7/AE7 -> 2.7064229 | AK7: =AA7/AD7 -> 0.41996877 | AL7: =AA7/AE7 -> 0.7240451 | AM7: clay
A8: 501 | B8: M0111 | C8: C | D8: 5 | E8: H | F8: 1 | G8: 41 | H8: 43 | I8: =_xlfn.CONCAT(B8, "-", C8,"-", D8,"-", F8) -> M0111-C-5-1 | J8: =_xlfn.CONCAT(A8, "-", I8, ",",G8, "-",H8) -> 501-M0111-C-5-1,41-43 | K8: =VLOOKUP(I8, 'Depth vlookup'!$G$2:$I$997,2,FALSE)+(G8/100) -> 110.41 | L8: =K8+2/100 -> 110.43 | M8: 170 | N8: =VLOOKUP(M8, Beakers!$A$2:$B$151, 2, 0) -> 9.595 | O8: 20.9839 | P8: 46045.927 | Q8: 18.612 | R8: TS | S8: 5 | T8: 7.5971 | V8: =O8-N8 -> 11.3889 | W8: =Q8-N8 -> 9.017 | X8: =(V8-W8)/(1-35/1000) -> 2.4579275 | Y8: =X8-(V8-W8) -> 0.086027461 | Z8: =W8-Y8 -> 8.9309725 | AA8: =X8/1.024 -> 2.4003198 | AB8: =Y8/2.22 -> 0.038751109 | AC8: =T8-VLOOKUP(M8, Beakers!$A$2:$C$151, 3, 0) -> 3.2944094 | AD8: =AC8-AB8+AA8 -> 5.6559781 | AE8: =AC8-AB8 -> 3.2556583 | AF8: =X8/V8 -> 0.21581781 | AG8: =X8/Z8 -> 0.27521386 | AH8: =V8/AD8 -> 2.013604 | AI8: =Z8/AD8 -> 1.5790324 | AJ8: =Z8/AE8 -> 2.7432156 | AK8: =AA8/AD8 -> 0.42438633 | AL8: =AA8/AE8 -> 0.73727632 | AM8: clay
A9: 501 | B9: M0111 | C9: C | D9: 9 | E9: R | F9: 1 | G9: 38 | H9: 40 | I9: =_xlfn.CONCAT(B9, "-", C9,"-", D9,"-", F9) -> M0111-C-9-1 | J9: =_xlfn.CONCAT(A9, "-", I9, ",",G9, "-",H9) -> 501-M0111-C-9-1,38-40 | K9: =VLOOKUP(I9, 'Depth vlookup'!$G$2:$I$997,2,FALSE)+(G9/100) -> 126.74 | L9: =K9+2/100 -> 126.76 | M9: 181 | N9: =VLOOKUP(M9, Beakers!$A$2:$B$151, 2, 0) -> 9.5058 | O9: 20.6961 | P9: 46046.45 | Q9: 18.2391 | R9: TS | S9: 3 | T9: 7.4826 | V9: =O9-N9 -> 11.1903 | W9: =Q9-N9 -> 8.7333 | X9: =(V9-W9)/(1-35/1000) -> 2.546114 | Y9: =X9-(V9-W9) -> 0.08911399 | Z9: =W9-Y9 -> 8.644186 | AA9: =X9/1.024 -> 2.4864394 | AB9: =Y9/2.22 -> 0.040141437 | AC9: =T9-VLOOKUP(M9, Beakers!$A$2:$C$151, 3, 0) -> 3.2199094 | AD9: =AC9-AB9+AA9 -> 5.6662074 | AE9: =AC9-AB9 -> 3.179768 | AF9: =X9/V9 -> 0.22752866 | AG9: =X9/Z9 -> 0.29454641 | AH9: =V9/AD9 -> 1.9749189 | AI9: =Z9/AD9 -> 1.5255682 | AJ9: =Z9/AE9 -> 2.7184958 | AK9: =AA9/AD9 -> 0.43881899 | AL9: =AA9/AE9 -> 0.78195625 | AM9: clay
A10: 501 | B10: M0111 | C10: C | D10: 10 | E10: R | F10: 1 | G10: 38 | H10: 40 | I10: =_xlfn.CONCAT(B10, "-", C10,"-", D10,"-", F10) -> M0111-C-10-1 | J10: =_xlfn.CONCAT(A10, "-", I10, ",",G10, "-",H10) -> 501-M0111-C-10-1,38-40 | K10: =VLOOKUP(I10, 'Depth vlookup'!$G$2:$I$997,2,FALSE)+(G10/100) -> 150.38 | L10: =K10+2/100 -> 150.4 | M10: 182 | N10: =VLOOKUP(M10, Beakers!$A$2:$B$151, 2, 0) -> 9.7033 | O10: 19.3204 | P10: 46046.451 | Q10: 16.2983 | R10: TS | S10: 5 | T10: 6.8409 | V10: =O10-N10 -> 9.6171 | W10: =Q10-N10 -> 6.595 | X10: =(V10-W10)/(1-35/1000) -> 3.1317098 | Y10: =X10-(V10-W10) -> 0.10960984 | Z10: =W10-Y10 -> 6.4853902 | AA10: =X10/1.024 -> 3.0583104 | AB10: =Y10/2.22 -> 0.049373804 | AC10: =T10-VLOOKUP(M10, Beakers!$A$2:$C$151, 3, 0) -> 2.4896444 | AD10: =AC10-AB10+AA10 -> 5.498581 | AE10: =AC10-AB10 -> 2.4402706 | AF10: =X10/V10 -> 0.32563973 | AG10: =X10/Z10 -> 0.48288688 | AH10: =V10/AD10 -> 1.7490149 | AI10: =Z10/AD10 -> 1.1794662 | AJ10: =Z10/AE10 -> 2.6576521 | AK10: =AA10/AD10 -> 0.55619994 | AL10: =AA10/AE10 -> 1.2532669 | AM10: clay
A11: 501 | B11: M0111 | C11: C | D11: 11 | E11: R | F11: 1 | G11: 49 | H11: 51 | I11: =_xlfn.CONCAT(B11, "-", C11,"-", D11,"-", F11) -> M0111-C-11-1 | J11: =_xlfn.CONCAT(A11, "-", I11, ",",G11, "-",H11) -> 501-M0111-C-11-1,49-51 | K11: =VLOOKUP(I11, 'Depth vlookup'!$G$2:$I$997,2,FALSE)+(G11/100) -> 153.49 | L11: =K11+2/100 -> 153.51 | M11: 183 | N11: =VLOOKUP(M11, Beakers!$A$2:$B$151, 2, 0) -> 9.6636 | O11: 19.5759 | P11: 46046.452 | Q11: 16.3548 | R11: TS | S11: 1 | T11: 6.9204 | V11: =O11-N11 -> 9.9123 | W11: =Q11-N11 -> 6.6912 | X11: =(V11-W11)/(1-35/1000) -> 3.3379275 | Y11: =X11-(V11-W11) -> 0.11682746 | Z11: =W11-Y11 -> 6.5743725 | AA11: =X11/1.024 -> 3.2596948 | AB11: =Y11/2.22 -> 0.052624982 | AC11: =T11-VLOOKUP(M11, Beakers!$A$2:$C$151, 3, 0) -> 2.5869471 | AD11: =AC11-AB11+AA11 -> 5.7940169 | AE11: =AC11-AB11 -> 2.5343221 | AF11: =X11/V11 -> 0.33674601 | AG11: =X11/Z11 -> 0.50771803 | AH11: =V11/AD11 -> 1.710782 | AI11: =Z11/AD11 -> 1.134683 | AJ11: =Z11/AE11 -> 2.5941346 | AK11: =AA11/AD11 -> 0.5625967 | AL11: =AA11/AE11 -> 1.2862196 | AM11: sand
A12: 501 | B12: M0111 | C12: C | D12: 12 | E12: R | F12: 1 | G12: 38 | H12: 40 | I12: =_xlfn.CONCAT(B12, "-", C12,"-", D12,"-", F12) -> M0111-C-12-1 | J12: =_xlfn.CONCAT(A12, "-", I12, ",",G12, "-",H12) -> 501-M0111-C-12-1,38-40 | K12: =VLOOKUP(I12, 'Depth vlookup'!$G$2:$I$997,2,FALSE)+(G12/100) -> 156.38 | L12: =K12+2/100 -> 156.4 | M12: 184 | N12: =VLOOKUP(M12, Beakers!$A$2:$B$151, 2, 0) -> 9.8976 | O12: 17.8937 | P12: 46046.49 | Q12: 15.8869 | R12: TS | S12: 5 | T12: 6.6776 | V12: =O12-N12 -> 7.9961 | W12: =Q12-N12 -> 5.9893 | X12: =(V12-W12)/(1-35/1000) -> 2.0795855 | Y12: =X12-(V12-W12) -> 0.072785492 | Z12: =W12-Y12 -> 5.9165145 | AA12: =X12/1.024 -> 2.0308452 | AB12: =Y12/2.22 -> 0.032786258 | AC12: =T12-VLOOKUP(M12, Beakers!$A$2:$C$151, 3, 0) -> 2.2392143 | AD12: =AC12-AB12+AA12 -> 4.2372733 | AE12: =AC12-AB12 -> 2.2064281 | AF12: =X12/V12 -> 0.26007497 | AG12: =X12/Z12 -> 0.35148828 | AH12: =V12/AD12 -> 1.8870862 | AI12: =Z12/AD12 -> 1.3963023 | AJ12: =Z12/AE12 -> 2.6814898 | AK12: =AA12/AD12 -> 0.47928115 | AL12: =AA12/AE12 -> 0.92042211 | AM12: sand
A13: 501 | B13: M0111 | C13: C | D13: 13 | E13: R | F13: 1 | G13: 38 | H13: 40 | I13: =_xlfn.CONCAT(B13, "-", C13,"-", D13,"-", F13) -> M0111-C-13-1 | J13: =_xlfn.CONCAT(A13, "-", I13, ",",G13, "-",H13) -> 501-M0111-C-13-1,38-40 | K13: =VLOOKUP(I13, 'Depth vlookup'!$G$2:$I$997,2,FALSE)+(G13/100) -> 159.38 | L13: =K13+2/100 -> 159.4 | M13: 185 | N13: =VLOOKUP(M13, Beakers!$A$2:$B$151, 2, 0) -> 9.8465 | O13: 19.5679 | P13: 46046.49 | Q13: 17.3764 | R13: TS | S13: 1 | T13: 7.2502 | V13: =O13-N13 -> 9.7214 | W13: =Q13-N13 -> 7.5299 | X13: =(V13-W13)/(1-35/1000) -> 2.2709845 | Y13: =X13-(V13-W13) -> 0.079484456 | Z13: =W13-Y13 -> 7.4504155 | AA13: =X13/1.024 -> 2.2177583 | AB13: =Y13/2.22 -> 0.035803809 | AC13: =T13-VLOOKUP(M13, Beakers!$A$2:$C$151, 3, 0) -> 2.8347291 | AD13: =AC13-AB13+AA13 -> 5.0166836 | AE13: =AC13-AB13 -> 2.7989253 | AF13: =X13/V13 -> 0.23360673 | AG13: =X13/Z13 -> 0.30481313 | AH13: =V13/AD13 -> 1.9378141 | AI13: =Z13/AD13 -> 1.4851277 | AJ13: =Z13/AE13 -> 2.6618843 | AK13: =AA13/AD13 -> 0.44207657 | AL13: =AA13/AE13 -> 0.79236063 | AM13: sand
A14: 501 | B14: M0111 | C14: C | D14: 14 | E14: R | F14: 1 | G14: 38 | H14: 40 | I14: =_xlfn.CONCAT(B14, "-", C14,"-", D14,"-", F14) -> M0111-C-14-1 | J14: =_xlfn.CONCAT(A14, "-", I14, ",",G14, "-",H14) -> 501-M0111-C-14-1,38-40 | K14: =VLOOKUP(I14, 'Depth vlookup'!$G$2:$I$997,2,FALSE)+(G14/100) -> 161.54 | L14: =K14+2/100 -> 161.56 | M14: 186 | N14: =VLOOKUP(M14, Beakers!$A$2:$B$151, 2, 0) -> 9.8185 | O14: 17.6805 | P14: 46046.49 | Q14: 16.0946 | R14: TS | S14: 2 | T14: 6.7417 | V14: =O14-N14 -> 7.862 | W14: =Q14-N14 -> 6.2761 | X14: =(V14-W14)/(1-35/1000) -> 1.6434197 | Y14: =X14-(V14-W14) -> 0.057519689 | Z14: =W14-Y14 -> 6.2185803 | AA14: =X14/1.024 -> 1.604902 | AB14: =Y14/2.22 -> 0.02590977 | AC14: =T14-VLOOKUP(M14, Beakers!$A$2:$C$151, 3, 0) -> 2.3387852 | AD14: =AC14-AB14+AA14 -> 3.9177775 | AE14: =AC14-AB14 -> 2.3128754 | AF14: =X14/V14 -> 0.20903329 | AG14: =X14/Z14 -> 0.2642757 | AH14: =V14/AD14 -> 2.00675 | AI14: =Z14/AD14 -> 1.5872725 | AJ14: =Z14/AE14 -> 2.6886793 | AK14: =AA14/AD14 -> 0.40964604 | AL14: =AA14/AE14 -> 0.69389904 | AM14: sand
... A27: 501 | B27: M0111 | C27: C | D27: 28 | E27: R | F27: 1 | G27: 38 | H27: 40 | I27: =_xlfn.CONCAT(B27, "-", C27,"-", D27,"-", F27) -> M0111-C-28-1 | J27: =_xlfn.CONCAT(A27, "-", I27, ",",G27, "-",H27) -> 501-M0111-C-28-1,38-40 | K27: =VLOOKUP(I27, 'Depth vlookup'!$G$2:$I$997,2,FALSE)+(G27/100) -> 201.74 | L27: =K27+2/100 -> 201.76 | M27: 214 | N27: =VLOOKUP(M27, Beakers!$A$2:$B$151, 2, 0) -> 9.996 | O27: 21.1278 | P27: 46046.872 | Q27: 18.7494 | R27: MS | S27: 1 | T27: 7.5959 | V27: =O27-N27 -> 11.1318 | W27: =Q27-N27 -> 8.7534 | X27: =(V27-W27)/(1-35/1000) -> 2.4646632 | Y27: =X27-(V27-W27) -> 0.086263212 | Z27: =W27-Y27 -> 8.6671368 | AA27: =X27/1.024 -> 2.4068977 | AB27: =Y27/2.22 -> 0.038857303 | AC27: =T27-VLOOKUP(M27, Beakers!$A$2:$C$151, 3, 0) -> 3.1133888 | AD27: =AC27-AB27+AA27 -> 5.4814292 | AE27: =AC27-AB27 -> 3.0745315 | AF27: =X27/V27 -> 0.22140743 | AG27: =X27/Z27 -> 0.28436879 | AH27: =V27/AD27 -> 2.0308207 | AI27: =Z27/AD27 -> 1.5811819 | AJ27: =Z27/AE27 -> 2.8190106 | AK27: =AA27/AD27 -> 0.43910039 | AL27: =AA27/AE27 -> 0.78285023 | AM27: sand
A28: 501 | B28: M0111 | C28: C | D28: 29 | E28: R | F28: 1 | G28: 30 | H28: 32 | I28: =_xlfn.CONCAT(B28, "-", C28,"-", D28,"-", F28) -> M0111-C-29-1 | J28: =_xlfn.CONCAT(A28, "-", I28, ",",G28, "-",H28) -> 501-M0111-C-29-1,30-32 | K28: =VLOOKUP(I28, 'Depth vlookup'!$G$2:$I$997,2,FALSE)+(G28/100) -> 204.66 | L28: =K28+2/100 -> 204.68 | M28: 215 | N28: =VLOOKUP(M28, Beakers!$A$2:$B$151, 2, 0) -> 10.084 | O28: 20.5497 | P28: 46046.872 | Q28: 18.6983 | R28: MS | S28: 2 | T28: 7.5382 | V28: =O28-N28 -> 10.4657 | W28: =Q28-N28 -> 8.6143 | X28: =(V28-W28)/(1-35/1000) -> 1.9185492 | Y28: =X28-(V28-W28) -> 0.067149223 | Z28: =W28-Y28 -> 8.5471508 | AA28: =X28/1.024 -> 1.8735832 | AB28: =Y28/2.22 -> 0.030247398 | AC28: =T28-VLOOKUP(M28, Beakers!$A$2:$C$151, 3, 0) -> 3.0162269 | AD28: =AC28-AB28+AA28 -> 4.8595627 | AE28: =AC28-AB28 -> 2.9859795 | AF28: =X28/V28 -> 0.18331781 | AG28: =X28/Z28 -> 0.22446652 | AH28: =V28/AD28 -> 2.15363 | AI28: =Z28/AD28 -> 1.7588312 | AJ28: =Z28/AE28 -> 2.8624278 | AK28: =AA28/AD28 -> 0.38554564 | AL28: =AA28/AE28 -> 0.62746018 | AM28: sand | AN28: was inittially requested at 38-40(extra sample)
A29: 501 | B29: M0111 | C29: C | D29: 30 | E29: R | F29: 1 | G29: 48 | H29: 50 | I29: =_xlfn.CONCAT(B29, "-", C29,"-", D29,"-", F29) -> M0111-C-30-1 | J29: =_xlfn.CONCAT(A29, "-", I29, ",",G29, "-",H29) -> 501-M0111-C-30-1,48-50 | K29: =VLOOKUP(I29, 'Depth vlookup'!$G$2:$I$997,2,FALSE)+(G29/100) -> 207.84 | L29: =K29+2/100 -> 207.86 | M29: 216 | N29: =VLOOKUP(M29, Beakers!$A$2:$B$151, 2, 0) -> 10.0795 | O29: 20.2514 | P29: 46046.872 | Q29: 17.4343 | R29: MS | S29: 3 | T29: 7.4657 | V29: =O29-N29 -> 10.1719 | W29: =Q29-N29 -> 7.3548 | X29: =(V29-W29)/(1-35/1000) -> 2.9192746 | Y29: =X29-(V29-W29) -> 0.10217461 | Z29: =W29-Y29 -> 7.2526254 | AA29: =X29/1.024 -> 2.8508541 | AB29: =Y29/2.22 -> 0.0460246 | AC29: =T29-VLOOKUP(M29, Beakers!$A$2:$C$151, 3, 0) -> 2.9457448 | AD29: =AC29-AB29+AA29 -> 5.7505744 | AE29: =AC29-AB29 -> 2.8997202 | AF29: =X29/V29 -> 0.28699403 | AG29: =X29/Z29 -> 0.40251281 | AH29: =V29/AD29 -> 1.7688494 | AI29: =Z29/AD29 -> 1.2612002 | AJ29: =Z29/AE29 -> 2.5011466 | AK29: =AA29/AD29 -> 0.4957512 | AL29: =AA29/AE29 -> 0.98314798 | AM29: clay
A30: 501 | B30: M0111 | C30: C | D30: 31 | E30: R | F30: 1 | G30: 38 | H30: 40 | I30: =_xlfn.CONCAT(B30, "-", C30,"-", D30,"-", F30) -> M0111-C-31-1 | J30: =_xlfn.CONCAT(A30, "-", I30, ",",G30, "-",H30) -> 501-M0111-C-31-1,38-40 | K30: =VLOOKUP(I30, 'Depth vlookup'!$G$2:$I$997,2,FALSE)+(G30/100) -> 210.74 | L30: =K30+2/100 -> 210.76 | M30: 217 | N30: =VLOOKUP(M30, Beakers!$A$2:$B$151, 2, 0) -> 9.6671 | O30: 20.0573 | P30: 46048.326 | Q30: 17.9662 | R30: TS | S30: 2 | T30: 7.4806 | V30: =O30-N30 -> 10.3902 | W30: =Q30-N30 -> 8.2991 | X30: =(V30-W30)/(1-35/1000) -> 2.166943 | Y30: =X30-(V30-W30) -> 0.075843005 | Z30: =W30-Y30 -> 8.223257 | AA30: =X30/1.024 -> 2.1161553 | AB30: =Y30/2.22 -> 0.034163516 | AC30: =T30-VLOOKUP(M30, Beakers!$A$2:$C$151, 3, 0) -> 3.1455776 | AD30: =AC30-AB30+AA30 -> 5.2275693 | AE30: =AC30-AB30 -> 3.1114141 | AF30: =X30/V30 -> 0.20855643 | AG30: =X30/Z30 -> 0.26351396 | AH30: =V30/AD30 -> 1.9875777 | AI30: =Z30/AD30 -> 1.5730556 | AJ30: =Z30/AE30 -> 2.6429324 | AK30: =AA30/AD30 -> 0.40480674 | AL30: =AA30/AE30 -> 0.68012654 | AM30: sand
A31: 501 | B31: M0111 | C31: C | D31: 32 | E31: R | F31: 1 | G31: 38 | H31: 40 | I31: =_xlfn.CONCAT(B31, "-", C31,"-", D31,"-", F31) -> M0111-C-32-1 | J31: =_xlfn.CONCAT(A31, "-", I31, ",",G31, "-",H31) -> 501-M0111-C-32-1,38-40 | K31: =VLOOKUP(I31, 'Depth vlookup'!$G$2:$I$997,2,FALSE)+(G31/100) -> 213.74 | L31: =K31+2/100 -> 213.76 | M31: 218 | N31: =VLOOKUP(M31, Beakers!$A$2:$B$151, 2, 0) -> 10.0969 | O31: 20.6925 | P31: 46048.326 | Q31: 19.1013 | R31: TS | S31: 3 | T31: 7.9034 | V31: =O31-N31 -> 10.5956 | W31: =Q31-N31 -> 9.0044 | X31: =(V31-W31)/(1-35/1000) -> 1.6489119 | Y31: =X31-(V31-W31) -> 0.057711917 | Z31: =W31-Y31 -> 8.9466881 | AA31: =X31/1.024 -> 1.6102655 | AB31: =Y31/2.22 -> 0.025996359 | AC31: =T31-VLOOKUP(M31, Beakers!$A$2:$C$151, 3, 0) -> 3.3756422 | AD31: =AC31-AB31+AA31 -> 4.9599113 | AE31: =AC31-AB31 -> 3.3496458 | AF31: =X31/V31 -> 0.15562233 | AG31: =X31/Z31 -> 0.18430417 | AH31: =V31/AD31 -> 2.1362479 | AI31: =Z31/AD31 -> 1.8038 | AJ31: =Z31/AE31 -> 2.6709356 | AK31: =AA31/AD31 -> 0.32465611 | AL31: =AA31/AE31 -> 0.48072711 | AM31: sand
A32: 501 | B32: M0111 | C32: C | D32: 33 | E32: R | F32: 1 | G32: 38 | H32: 40 | I32: =_xlfn.CONCAT(B32, "-", C32,"-", D32,"-", F32) -> M0111-C-33-1 | J32: =_xlfn.CONCAT(A32, "-", I32, ",",G32, "-",H32) -> 501-M0111-C-33-1,38-40 | K32: =VLOOKUP(I32, 'Depth vlookup'!$G$2:$I$997,2,FALSE)+(G32/100) -> 216.74 | L32: =K32+2/100 -> 216.76 | M32: 219 | N32: =VLOOKUP(M32, Beakers!$A$2:$B$151, 2, 0) -> 9.6617 | O32: 20.8082 | P32: 46048.326 | Q32: 18.5063 | R32: TS | S32: 5 | T32: 7.6558 | V32: =O32-N32 -> 11.1465 | W32: =Q32-N32 -> 8.8446 | X32: =(V32-W32)/(1-35/1000) -> 2.3853886 | Y32: =X32-(V32-W32) -> 0.083488601 | Z32: =W32-Y32 -> 8.7611114 | AA32: =X32/1.024 -> 2.3294811 | AB32: =Y32/2.22 -> 0.037607478 | AC32: =T32-VLOOKUP(M32, Beakers!$A$2:$C$151, 3, 0) -> 3.3231991 | AD32: =AC32-AB32+AA32 -> 5.6150727 | AE32: =AC32-AB32 -> 3.2855916 | AF32: =X32/V32 -> 0.21400337 | AG32: =X32/Z32 -> 0.27227009 | AH32: =V32/AD32 -> 1.9851034 | AI32: =Z32/AD32 -> 1.5602846 | AJ32: =Z32/AE32 -> 2.6665248 | AK32: =AA32/AD32 -> 0.41486214 | AL32: =AA32/AE32 -> 0.70899896 | AM32: sand
A33: 501 | B33: M0111 | C33: C | D33: 34 | E33: R | F33: 1 | G33: 38 | H33: 40 | I33: =_xlfn.CONCAT(B33, "-", C33,"-", D33,"-", F33) -> M0111-C-34-1 | J33: =_xlfn.CONCAT(A33, "-", I33, ",",G33, "-",H33) -> 501-M0111-C-34-1,38-40 | K33: =VLOOKUP(I33, 'Depth vlookup'!$G$2:$I$997,2,FALSE)+(G33/100) -> 219.74 | L33: =K33+2/100 -> 219.76 | M33: 162 | N33: =VLOOKUP(M33, Beakers!$A$2:$B$151, 2, 0) -> 9.8842 | O33: 21.0256 | P33: 46048.399 | Q33: 19.3107 | R33: TS | S33: 3 | T33: 7.9508 | V33: =O33-N33 -> 11.1414 | W33: =Q33-N33 -> 9.4265 | X33: =(V33-W33)/(1-35/1000) -> 1.7770984 | Y33: =X33-(V33-W33) -> 0.062198446 | Z33: =W33-Y33 -> 9.3643016 | AA33: =X33/1.024 -> 1.7354477 | AB33: =Y33/2.22 -> 0.028017318 | AC33: =T33-VLOOKUP(M33, Beakers!$A$2:$C$151, 3, 0) -> 3.5184233 | AD33: =AC33-AB33+AA33 -> 5.2258537 | AE33: =AC33-AB33 -> 3.490406 | AF33: =X33/V33 -> 0.15950405 | AG33: =X33/Z33 -> 0.18977373 | AH33: =V33/AD33 -> 2.131977 | AI33: =Z33/AD33 -> 1.791918 | AJ33: =Z33/AE33 -> 2.6828689 | AK33: =AA33/AD33 -> 0.33208884 | AL33: =AA33/AE33 -> 0.49720511 | AM33: sand
A34: 501 | B34: M0111 | C34: C | D34: 35 | E34: R | F34: 1 | G34: 48 | H34: 50 | I34: =_xlfn.CONCAT(B34, "-", C34,"-", D34,"-", F34) -> M0111-C-35-1 | J34: =_xlfn.CONCAT(A34, "-", I34, ",",G34, "-",H34) -> 501-M0111-C-35-1,48-50 | K34: =VLOOKUP(I34, 'Depth vlookup'!$G$2:$I$997,2,FALSE)+(G34/100) -> 222.84 | L34: =K34+2/100 -> 222.86 | M34: 163 | N34: =VLOOKUP(M34, Beakers!$A$2:$B$151, 2, 0) -> 9.5631 | O34: 19.8404 | P34: 46048.399 | Q34: 18.2723 | R34: TS | S34: 5 | T34: 7.5656 | V34: =O34-N34 -> 10.2773 | W34: =Q34-N34 -> 8.7092 | X34: =(V34-W34)/(1-35/1000) -> 1.6249741 | Y34: =X34-(V34-W34) -> 0.056874093 | Z34: =W34-Y34 -> 8.6523259 | AA34: =X34/1.024 -> 1.5868888 | AB34: =Y34/2.22 -> 0.025618961 | AC34: =T34-VLOOKUP(M34, Beakers!$A$2:$C$151, 3, 0) -> 3.2772143 | AD34: =AC34-AB34+AA34 -> 4.8384842 | AE34: =AC34-AB34 -> 3.2515954 | AF34: =X34/V34 -> 0.15811294 | AG34: =X34/Z34 -> 0.18780778 | AH34: =V34/AD34 -> 2.1240743 | AI34: =Z34/AD34 -> 1.7882307 | AJ34: =Z34/AE34 -> 2.6609479 | AK34: =AA34/AD34 -> 0.3279723 | AL34: =AA34/AE34 -> 0.4880339 | AM34: sand
A35: 501 | B35: M0111 | C35: C | D35: 36 | E35: R | F35: 1 | G35: 37.5 | H35: 39.5 | I35: =_xlfn.CONCAT(B35, "-", C35,"-", D35,"-", F35) -> M0111-C-36-1 | J35: =_xlfn.CONCAT(A35, "-", I35, ",",G35, "-",H35) -> 501-M0111-C-36-1,37.5-39.5 | K35: =VLOOKUP(I35, 'Depth vlookup'!$G$2:$I$997,2,FALSE)+(G35/100) -> 223.535 | L35: =K35+2/100 -> 223.555 | M35: 164 | N35: =VLOOKUP(M35, Beakers!$A$2:$B$151, 2, 0) -> 9.9097 | O35: 17.7898 | P35: 46048.399 | Q35: 16.9749 | R35: TS | S35: 1 | T35: 7.1132 | V35: =O35-N35 -> 7.8801 | W35: =Q35-N35 -> 7.0652 | X35: =(V35-W35)/(1-35/1000) -> 0.84445596 | Y35: =X35-(V35-W35) -> 0.029555959 | Z35: =W35-Y35 -> 7.035644 | AA35: =X35/1.024 -> 0.82466402 | AB35: =Y35/2.22 -> 0.013313495 | AC35: =T35-VLOOKUP(M35, Beakers!$A$2:$C$151, 3, 0) -> 2.6693883 | AD35: =AC35-AB35+AA35 -> 3.4807389 | AE35: =AC35-AB35 -> 2.6560748 | AF35: =X35/V35 -> 0.1071631 | AG35: =X35/Z35 -> 0.1200254 | AH35: =V35/AD35 -> 2.2639159 | AI35: =Z35/AD35 -> 2.0213076 | AJ35: =Z35/AE35 -> 2.6488877 | AK35: =AA35/AD35 -> 0.23692212 | AL35: =AA35/AE35 -> 0.31048222 | AM35: sand
A36: 501 | B36: M0111 | C36: C | D36: 39 | E36: R | F36: 1 | G36: 30 | H36: 32 | I36: =_xlfn.CONCAT(B36, "-", C36,"-", D36,"-", F36) -> M0111-C-39-1 | J36: =_xlfn.CONCAT(A36, "-", I36, ",",G36, "-",H36) -> 501-M0111-C-39-1,30-32 | K36: =VLOOKUP(I36, 'Depth vlookup'!$G$2:$I$997,2,FALSE)+(G36/100) -> 229.66 | L36: =K36+2/100 -> 229.68 | M36: 165 | N36: =VLOOKUP(M36, Beakers!$A$2:$B$151, 2, 0) -> 9.8137 | O36: 20.1268 | P36: 46048.417 | Q36: 17.4302 | R36: TS | S36: 5 | T36: 7.2897 | V36: =O36-N36 -> 10.3131 | W36: =Q36-N36 -> 7.6165 | X36: =(V36-W36)/(1-35/1000) -> 2.7944041 | Y36: =X36-(V36-W36) -> 0.097804145 | Z36: =W36-Y36 -> 7.5186959 | AA36: =X36/1.024 -> 2.7289103 | AB36: =Y36/2.22 -> 0.044055921 | AC36: =T36-VLOOKUP(M36, Beakers!$A$2:$C$151, 3, 0) -> 2.8889377 | AD36: =AC36-AB36+AA36 -> 5.573792 | AE36: =AC36-AB36 -> 2.8448817 | AF36: =X36/V36 -> 0.27095676 | AG36: =X36/Z36 -> 0.37166075 | AH36: =V36/AD36 -> 1.8502843 | AI36: =Z36/AD36 -> 1.3489373 | AJ36: =Z36/AE36 -> 2.6428852 | AK36: =AA36/AD36 -> 0.48959672 | AL36: =AA36/AE36 -> 0.95923505 | AM36: clay
V113: =O113-N113 -> 0 | W113: =Q113-N113 -> 0 | X113: =(V113-W113)/(1-35/1000) -> 0 | Y113: =X113-(V113-W113) -> 0 | Z113: =W113-Y113 -> 0 | AA113: =X113/1.024 -> 0 | AB113: =Y113/2.22 -> 0 | AC113: =T113-VLOOKUP(M113, Beakers!$A$2:$C$151, 3, 0) -> #N/A | AD113: =AC113-AB113+AA113 -> #N/A | AE113: =AC113-AB113 -> #N/A | AF113: =X113/V113 -> #DIV/0! | AG113: =X113/Z113 -> #DIV/0! | AH113: =V113/AD113 -> #N/A | AI113: =Z113/AD113 -> #N/A | AJ113: =Z113/AE113 -> #N/A | AK113: =AA113/AD113 -> #N/A | AL113: =AA113/AE113 -> #N/A
V114: =O114-N114 -> 0 | W114: =Q114-N114 -> 0 | X114: =(V114-W114)/(1-35/1000) -> 0 | Y114: =X114-(V114-W114) -> 0 | Z114: =W114-Y114 -> 0 | AA114: =X114/1.024 -> 0 | AB114: =Y114/2.22 -> 0 | AC114: =T114-VLOOKUP(M114, Beakers!$A$2:$C$151, 3, 0) -> #N/A | AD114: =AC114-AB114+AA114 -> #N/A | AE114: =AC114-AB114 -> #N/A | AF114: =X114/V114 -> #DIV/0! | AG114: =X114/Z114 -> #DIV/0! | AH114: =V114/AD114 -> #N/A | AI114: =Z114/AD114 -> #N/A | AJ114: =Z114/AE114 -> #N/A | AK114: =AA114/AD114 -> #N/A | AL114: =AA114/AE114 -> #N/A
V115: =O115-N115 -> 0 | W115: =Q115-N115 -> 0 | X115: =(V115-W115)/(1-35/1000) -> 0 | Y115: =X115-(V115-W115) -> 0 | Z115: =W115-Y115 -> 0 | AA115: =X115/1.024 -> 0 | AB115: =Y115/2.22 -> 0 | AC115: =T115-VLOOKUP(M115, Beakers!$A$2:$C$151, 3, 0) -> #N/A | AD115: =AC115-AB115+AA115 -> #N/A | AE115: =AC115-AB115 -> #N/A | AF115: =X115/V115 -> #DIV/0! | AG115: =X115/Z115 -> #DIV/0! | AH115: =V115/AD115 -> #N/A | AI115: =Z115/AD115 -> #N/A | AJ115: =Z115/AE115 -> #N/A | AK115: =AA115/AD115 -> #N/A | AL115: =AA115/AE115 -> #N/A
V116: =O116-N116 -> 0 | W116: =Q116-N116 -> 0 | X116: =(V116-W116)/(1-35/1000) -> 0 | Y116: =X116-(V116-W116) -> 0 | Z116: =W116-Y116 -> 0 | AA116: =X116/1.024 -> 0 | AB116: =Y116/2.22 -> 0 | AC116: =T116-VLOOKUP(M116, Beakers!$A$2:$C$151, 3, 0) -> #N/A | AD116: =AC116-AB116+AA116 -> #N/A | AE116: =AC116-AB116 -> #N/A | AF116: =X116/V116 -> #DIV/0! | AG116: =X116/Z116 -> #DIV/0! | AH116: =V116/AD116 -> #N/A | AI116: =Z116/AD116 -> #N/A | AJ116: =Z116/AE116 -> #N/A | AK116: =AA116/AD116 -> #N/A | AL116: =AA116/AE116 -> #N/A
V117: =O117-N117 -> 0 | W117: =Q117-N117 -> 0 | X117: =(V117-W117)/(1-35/1000) -> 0 | Y117: =X117-(V117-W117) -> 0 | Z117: =W117-Y117 -> 0 | AA117: =X117/1.024 -> 0 | AB117: =Y117/2.22 -> 0 | AC117: =T117-VLOOKUP(M117, Beakers!$A$2:$C$151, 3, 0) -> #N/A | AD117: =AC117-AB117+AA117 -> #N/A | AE117: =AC117-AB117 -> #N/A | AF117: =X117/V117 -> #DIV/0! | AG117: =X117/Z117 -> #DIV/0! | AH117: =V117/AD117 -> #N/A | AI117: =Z117/AD117 -> #N/A | AJ117: =Z117/AE117 -> #N/A | AK117: =AA117/AD117 -> #N/A | AL117: =AA117/AE117 -> #N/A
V118: =O118-N118 -> 0 | W118: =Q118-N118 -> 0 | X118: =(V118-W118)/(1-35/1000) -> 0 | Y118: =X118-(V118-W118) -> 0 | Z118: =W118-Y118 -> 0 | AA118: =X118/1.024 -> 0 | AB118: =Y118/2.22 -> 0 | AC118: =T118-VLOOKUP(M118, Beakers!$A$2:$C$151, 3, 0) -> #N/A | AD118: =AC118-AB118+AA118 -> #N/A | AE118: =AC118-AB118 -> #N/A | AF118: =X118/V118 -> #DIV/0! | AG118: =X118/Z118 -> #DIV/0! | AH118: =V118/AD118 -> #N/A | AI118: =Z118/AD118 -> #N/A | AJ118: =Z118/AE118 -> #N/A | AK118: =AA118/AD118 -> #N/A | AL118: =AA118/AE118 -> #N/A
V119: =O119-N119 -> 0 | W119: =Q119-N119 -> 0 | X119: =(V119-W119)/(1-35/1000) -> 0 | Y119: =X119-(V119-W119) -> 0 | Z119: =W119-Y119 -> 0 | AA119: =X119/1.024 -> 0 | AB119: =Y119/2.22 -> 0 | AC119: =T119-VLOOKUP(M119, Beakers!$A$2:$C$151, 3, 0) -> #N/A | AD119: =AC119-AB119+AA119 -> #N/A | AE119: =AC119-AB119 -> #N/A | AF119: =X119/V119 -> #DIV/0! | AG119: =X119/Z119 -> #DIV/0! | AH119: =V119/AD119 -> #N/A | AI119: =Z119/AD119 -> #N/A | AJ119: =Z119/AE119 -> #N/A | AK119: =AA119/AD119 -> #N/A | AL119: =AA119/AE119 -> #N/A
V120: =O120-N120 -> 0 | W120: =Q120-N120 -> 0 | X120: =(V120-W120)/(1-35/1000) -> 0 | Y120: =X120-(V120-W120) -> 0 | Z120: =W120-Y120 -> 0 | AA120: =X120/1.024 -> 0 | AB120: =Y120/2.22 -> 0 | AC120: =T120-VLOOKUP(M120, Beakers!$A$2:$C$151, 3, 0) -> #N/A | AD120: =AC120-AB120+AA120 -> #N/A | AE120: =AC120-AB120 -> #N/A | AF120: =X120/V120 -> #DIV/0! | AG120: =X120/Z120 -> #DIV/0! | AH120: =V120/AD120 -> #N/A | AI120: =Z120/AD120 -> #N/A | AJ120: =Z120/AE120 -> #N/A | AK120: =AA120/AD120 -> #N/A | AL120: =AA120/AE120 -> #N/A
V121: =O121-N121 -> 0 | W121: =Q121-N121 -> 0 | X121: =(V121-W121)/(1-35/1000) -> 0 | Y121: =X121-(V121-W121) -> 0 | Z121: =W121-Y121 -> 0 | AA121: =X121/1.024 -> 0 | AB121: =Y121/2.22 -> 0 | AC121: =T121-VLOOKUP(M121, Beakers!$A$2:$C$151, 3, 0) -> #N/A | AD121: =AC121-AB121+AA121 -> #N/A | AE121: =AC121-AB121 -> #N/A | AF121: =X121/V121 -> #DIV/0! | AG121: =X121/Z121 -> #DIV/0! | AH121: =V121/AD121 -> #N/A | AI121: =Z121/AD121 -> #N/A | AJ121: =Z121/AE121 -> #N/A | AK121: =AA121/AD121 -> #N/A | AL121: =AA121/AE121 -> #N/A
V122: =O122-N122 -> 0 | W122: =Q122-N122 -> 0 | X122: =(V122-W122)/(1-35/1000) -> 0 | Y122: =X122-(V122-W122) -> 0 | Z122: =W122-Y122 -> 0 | AA122: =X122/1.024 -> 0 | AB122: =Y122/2.22 -> 0 | AC122: =T122-VLOOKUP(M122, Beakers!$A$2:$C$151, 3, 0) -> #N/A | AD122: =AC122-AB122+AA122 -> #N/A | AE122: =AC122-AB122 -> #N/A | AF122: =X122/V122 -> #DIV/0! | AG122: =X122/Z122 -> #DIV/0! | AH122: =V122/AD122 -> #N/A | AI122: =Z122/AD122 -> #N/A | AJ122: =Z122/AE122 -> #N/A | AK122: =AA122/AD122 -> #N/A | AL122: =AA122/AE122 -> #N/A
V123: =O123-N123 -> 0 | W123: =Q123-N123 -> 0 | X123: =(V123-W123)/(1-35/1000) -> 0 | Y123: =X123-(V123-W123) -> 0 | Z123: =W123-Y123 -> 0 | AA123: =X123/1.024 -> 0 | AB123: =Y123/2.22 -> 0 | AC123: =T123-VLOOKUP(M123, Beakers!$A$2:$C$151, 3, 0) -> #N/A | AD123: =AC123-AB123+AA123 -> #N/A | AE123: =AC123-AB123 -> #N/A | AF123: =X123/V123 -> #DIV/0! | AG123: =X123/Z123 -> #DIV/0! | AH123: =V123/AD123 -> #N/A | AI123: =Z123/AD123 -> #N/A | AJ123: =Z123/AE123 -> #N/A | AK123: =AA123/AD123 -> #N/A | AL123: =AA123/AE123 -> #N/A
V124: =O124-N124 -> 0 | W124: =Q124-N124 -> 0 | X124: =(V124-W124)/(1-35/1000) -> 0 | Y124: =X124-(V124-W124) -> 0 | Z124: =W124-Y124 -> 0 | AA124: =X124/1.024 -> 0 | AB124: =Y124/2.22 -> 0 | AC124: =T124-VLOOKUP(M124, Beakers!$A$2:$C$151, 3, 0) -> #N/A | AD124: =AC124-AB124+AA124 -> #N/A | AE124: =AC124-AB124 -> #N/A | AF124: =X124/V124 -> #DIV/0! | AG124: =X124/Z124 -> #DIV/0! | AH124: =V124/AD124 -> #N/A | AI124: =Z124/AD124 -> #N/A | AJ124: =Z124/AE124 -> #N/A | AK124: =AA124/AD124 -> #N/A | AL124: =AA124/AE124 -> #N/A
... V181: =O181-N181 -> 0 | W181: =Q181-N181 -> 0 | X181: =(V181-W181)/(1-35/1000) -> 0 | Y181: =X181-(V181-W181) -> 0 | Z181: =W181-Y181 -> 0 | AA181: =X181/1.024 -> 0 | AB181: =Y181/2.22 -> 0 | AC181: =T181-VLOOKUP(M181, Beakers!$A$2:$C$151, 3, 0) -> #N/A | AD181: =AC181-AB181+AA181 -> #N/A | AE181: =AC181-AB181 -> #N/A | AF181: =X181/V181 -> #DIV/0! | AG181: =X181/Z181 -> #DIV/0! | AH181: =V181/AD181 -> #N/A | AI181: =Z181/AD181 -> #N/A | AJ181: =Z181/AE181 -> #N/A | AK181: =AA181/AD181 -> #N/A | AL181: =AA181/AE181 -> #N/A

Sheet STD
A1: Run Number | B1: Pyc Cell | C1: Volume of Std | D1: Offset | E1: date and time | G1: Comments | H1: Volume of Std | I1: 9.2149
A2: 1 | B2: 5 | C2: 9.2015 | D2: =$I$1-C2 -> 0.0134 | E2: 17.01.2026 | F2: 0.64236111
A3: 2 | B3: 1 | C3: 9.2176 | D3: =$I$1-C3 -> -0.0027 | E3: 17.01.2026 | F3: 0.76041667
A4: 3 | B4: 2 | C4: 9.2133 | D4: =$I$1-C4 -> 0.0016 | E4: 17.01.2026 | F4: 0.875
A5: 4 | B5: 3 | C5: 9.2299 | D5: =$I$1-C5 -> -0.015 | E5: 19.01.2026 | F5: 0.37847222
A6: 5 | B6: 4 | C6: 9.1656 | D6: =$I$1-C6 -> 0.0493 | E6: 19.01.2025 | F6: 0.44236111
A7: Calibration Cell | B7: 4 | C7: 9.2059 | D7: =$I$1-C7 -> 0.009 | E7: 19.01.2026 | F7: 0.50972222 | G7: Cell 4 was recalibrated
A8: 6 | B8: 4 | C8: 9.1879 | D8: =$I$1-C8 -> 0.027 | E8: 19.01.2026 | F8: 0.5875
A9: Calibration Cell | B9: 4 | C9: Unstable Pressure | G9: Cell 4 not to be used - use 3 samples and 1 std
A10: Recalibration of all cells | C10: From 19:17 on 19.01 - the threshold for standard and recalibration is >0.04 | K10: 19.01 | L10: Recalibration of Cells
A11: 7 | B11: 5 | C11: 9.2127 | D11: =$I$1-C11 -> 0.0022 | E11: 19.01.2026 | F11: 0.85138889 | K11: Cell 1 | L11: 9.1835 | M11: =$I$1-L11 -> 0.0314
A12: 8 | B12: 1 | C12: 9.1865 | D12: =$I$1-C12 -> 0.0284 | E12: 20.01.2026 | F12: 0.33888889 | K12: Cell 2 | L12: 9.2368 | M12: =$I$1-L12 -> -0.0219
A13: Calibration Cell | B13: 1 | C13: 9.2188 | D13: =$I$1-C13 -> -0.0039 | E13: 20.01.2026 | F13: 0.40277778 | G13: Cell 1 was recalibrated | K13: Cell 3 | L13: 9.2228 | M13: =$I$1-L13 -> -0.0079
A14: 9 | B14: 1 | C14: 9.2164 | D14: =$I$1-C14 -> -0.0015 | E14: 20.01.2026 | F14: 0.46805556 | K14: Cell 5 | L14: 9.2215 | M14: =$I$1-L14 -> -0.0066
A15: Calibration Cell | B15: 4 | C15: 9.2189 | D15: =$I$1-C15 -> -0.004 | E15: 20.01.2026 | F15: 0.52083333 | G15: Calibration after Stefan repaired Cell 4 (maybe gasket),
A16: 10 | B16: 2 | C16: 9.2397 | D16: =$I$1-C16 -> -0.0248 | E16: 20.01.2026 | F16: 0.53263889 | K16: 20.01 | L16: Cell1 check
A17: Calibration Cell | B17: 2 | C17: 9.2111 | D17: =$I$1-C17 -> 0.0038 | E17: 20.01.2026 | F17: 0.59027778 | G17: Cell 1 was recalibrated | K17: Cell 1 | L17: 9.2189 | M17: =$I$1-L17 -> -0.004
A18: 11 | B18: 3 | C18: 9.2187 | D18: =$I$1-C18 -> -0.0038 | E18: 20.01.2026 | F18: 0.65208333 | L18: 9.2224 | M18: =$I$1-L18 -> -0.0075
A19: 12 | B19: 5 | C19: 9.2231 | D19: =$I$1-C19 -> -0.0082 | E19: 20.01.2026 | F19: 0.70138889 | L19: 9.2199 | M19: =$I$1-L19 -> -0.005
A20: 13 | B20: 1 | C20: 9.2205 | D20: =$I$1-C20 -> -0.0056 | E20: 20.01.2026 | F20: 0.74930556 | L20: 9.2179 | M20: =$I$1-L20 -> -0.003
A21: 14 | B21: 2 | C21: 9.2141 | D21: =$I$1-C21 -> 0.0008 | E21: 20.01.2026 | F21: 0.79027778 | L21: 9.2187 | M21: =$I$1-L21 -> -0.0038
A22: 15 | B22: 3 | C22: 9.1812 | D22: =$I$1-C22 -> 0.0337 | E22: 20.01.2026 | F22: 0.83333333 | L22: Cell4 check
A23: 16 | B23: 5 | C23: 9.2207 | D23: =$I$1-C23 -> -0.0058 | E23: 20.01.2026 | F23: 0.875 | K23: Cell4 | L23: 9.2225 | M23: =$I$1-L23 -> -0.0076
A24: 17 | B24: 1 | C24: 9.2045 | D24: =$I$1-C24 -> 0.0104 | E24: 21.01.2027 | F24: 0.35902778 | L24: 9.2213 | M24: =$I$1-L24 -> -0.0064
A25: 18 | B25: 2 | C25: 9.2031 | D25: =$I$1-C25 -> 0.0118 | E25: 21.01.2027 | F25: 0.40208333 | L25: 9.2135 | M25: =$I$1-L25 -> 0.0014
A26: 19 | B26: 3 | C26: 9.2131 | D26: =$I$1-C26 -> 0.0018 | E26: 21.01.2027 | F26: 0.48472222 | L26: 9.2189 | M26: =$I$1-L26 -> -0.004
A27: 20 | B27: 5 | C27: 9.215 | D27: =$I$1-C27 -> -0.0001 | E27: 21.01.2027 | F27: 0.63333333 | L27: 9.2243 | M27: =$I$1-L27 -> -0.0094
A28: 21 | B28: 1 | C28: 9.2215 | D28: =$I$1-C28 -> -0.0066 | E28: 21.01.2027 | F28: 0.71527778
A29: 22 | B29: 2 | C29: 9.2305 | D29: =$I$1-C29 -> -0.0156 | E29: 21.01.2027 | F29: 0.75763889 | K29: 27.01 | L29: Cell2 check
A30: 23 | B30: 3 | C30: 9.2051 | D30: =$I$1-C30 -> 0.0098 | E30: 21.01.2027 | F30: 0.79583333 | K30: Cell 2 | L30: 9.2134 | M30: =$I$1-L30 -> 0.0015
A31: 24 | B31: 5 | C31: 9.2266 | D31: =$I$1-C31 -> -0.0117 | E31: 21.01.2027 | F31: 0.85833333 | L31: 9.2197 | M31: =$I$1-L31 -> -0.0048
A32: 25 | B32: 1 | C32: 9.2237 | D32: =$I$1-C32 -> -0.0088 | E32: 22.01.2026 | F32: 0.35555556 | L32: 9.2051 | M32: =$I$1-L32 -> 0.0098
A33: 26 | B33: 2 | C33: 9.2153 | D33: =$I$1-C33 -> -0.0004 | E33: 22.01.2026 | F33: 0.51180556 | L33: 9.2089 | M33: =$I$1-L33 -> 0.006
A34: 27 | B34: 3 | C34: 9.226 | D34: =$I$1-C34 -> -0.0111 | E34: 22.01.2026 | F34: 0.65347222 | L34: 9.2163 | M34: =$I$1-L34 -> -0.0014
A35: 28 | B35: 5 | C35: 9.2235 | D35: =$I$1-C35 -> -0.0086 | E35: 22.01.2026 | F35: 0.75763889
A36: 29 | B36: 1 | C36: 9.2304 | D36: =$I$1-C36 -> -0.0155 | E36: 22.01.2026 | F36: 0.80902778
A37: 30 | B37: 2 | C37: 9.1928 | D37: =$I$1-C37 -> 0.0221 | E37: 22.01.2026 | F37: 0.86805556
A38: 31 | B38: 3 | C38: 9.2201 | D38: =$I$1-C38 -> -0.0052 | E38: 22.01.2026 | F38: 0.90694444
A39: 32 | B39: 5 | C39: 9.2217 | D39: =$I$1-C39 -> -0.0068 | E39: 23.01.2026 | F39: 0.36041667
A40: 33 | B40: 1 | C40: 9.2265 | D40: =$I$1-C40 -> -0.0116 | E40: 23.01.2026 | F40: 0.48194444
...

Sheet Depth vlookup
A1: Expedition | B1: Site | C1: Hole | D1: Core | E1: Type | F1: Section | G1: Combined | H1: top_depth | I1: bottom_depth
A2: 501 | B2: M0111 | C2: A | D2: 1 | E2: H | F2: 1 | G2: =CONCATENATE(B2, "-",C2, "-", D2, "-", F2) -> M0111-A-1-1 | H2: 0 | I2: 1.5
A3: 501 | B3: M0111 | C3: A | D3: 1 | E3: H | F3: 2 | G3: =CONCATENATE(B3, "-",C3, "-", D3, "-", F3) -> M0111-A-1-2 | H3: 1.5 | I3: 2.9
A4: 501 | B4: M0111 | C4: A | D4: 2 | E4: H | F4: 1 | G4: =CONCATENATE(B4, "-",C4, "-", D4, "-", F4) -> M0111-A-2-1 | H4: 2.4 | I4: 3.91
A5: 501 | B5: M0111 | C5: A | D5: 2 | E5: H | F5: 2 | G5: =CONCATENATE(B5, "-",C5, "-", D5, "-", F5) -> M0111-A-2-2 | H5: 3.91 | I5: 4.99
A6: 501 | B6: M0111 | C6: A | D6: 3 | E6: H | F6: 1 | G6: =CONCATENATE(B6, "-",C6, "-", D6, "-", F6) -> M0111-A-3-1 | H6: 4.46 | I6: 5.97
A7: 501 | B7: M0111 | C7: A | D7: 3 | E7: H | F7: 2 | G7: =CONCATENATE(B7, "-",C7, "-", D7, "-", F7) -> M0111-A-3-2 | H7: 5.97 | I7: 7.1
A8: 501 | B8: M0111 | C8: A | D8: 4 | E8: H | F8: 1 | G8: =CONCATENATE(B8, "-",C8, "-", D8, "-", F8) -> M0111-A-4-1 | H8: 6.89 | I8: 8.4
A9: 501 | B9: M0111 | C9: A | D9: 4 | E9: H | F9: 2 | G9: =CONCATENATE(B9, "-",C9, "-", D9, "-", F9) -> M0111-A-4-2 | H9: 8.4 | I9: 9.6
A10: 501 | B10: M0111 | C10: A | D10: 5 | E10: H | F10: 1 | G10: =CONCATENATE(B10, "-",C10, "-", D10, "-", F10) -> M0111-A-5-1 | H10: 9.6 | I10: 11.1
A11: 501 | B11: M0111 | C11: A | D11: 5 | E11: H | F11: 2 | G11: =CONCATENATE(B11, "-",C11, "-", D11, "-", F11) -> M0111-A-5-2 | H11: 11.1 | I11: 12.05
A12: 501 | B12: M0111 | C12: A | D12: 6 | E12: H | F12: 1 | G12: =CONCATENATE(B12, "-",C12, "-", D12, "-", F12) -> M0111-A-6-1 | H12: 11.7 | I12: 13.2
A13: 501 | B13: M0111 | C13: A | D13: 6 | E13: H | F13: 2 | G13: =CONCATENATE(B13, "-",C13, "-", D13, "-", F13) -> M0111-A-6-2 | H13: 13.2 | I13: 13.94
... A1049: 501 | B1049: M0113 | C1049: A | D1049: 210 | E1049: R | F1049: 2 | G1049: =CONCATENATE(B1049, "-",C1049, "-", D1049, "-", F1049) -> M0113-A-210-2 | H1049: 324.01 | I1049: 325.1

Sheet Beakers
A1: Number | B1: Weight, g | C1: Volume, cc
A2: 91 | B2: 9.5239 | C2: =B2/2.23 -> 4.2708072 | F2: Need editing with values for X501
A3: 92 | B3: 9.1041 | C3: =B3/2.23 -> 4.0825561
A4: 93 | B4: 9.4765 | C4: =B4/2.23 -> 4.2495516
A5: 94 | B5: 9.6205 | C5: =B5/2.23 -> 4.3141256
A6: 95 | B6: 9.3813 | C6: =B6/2.23 -> 4.206861
A7: 97 | B7: 9.4983 | C7: =B7/2.23 -> 4.2593274
A8: 98 | B8: 9.3954 | C8: =B8/2.23 -> 4.2131839
A9: 99 | B9: 9.327 | C9: =B9/2.23 -> 4.1825112
A10: 100 | B10: 9.6332 | C10: =B10/2.23 -> 4.3198206
A11: 151 | B11: 9.7264 | C11: =B11/2.23 -> 4.3616143
A12: 152 | B12: 9.7155 | C12: =B12/2.23 -> 4.3567265
A13: 153 | B13: 9.6697 | C13: =B13/2.23 -> 4.3361883
A14: 154 | B14: 9.7118 | C14: =B14/2.23 -> 4.3550673
... A138: 10 | B138: 9.9909 | C138: =B138/2.23 -> 4.4802242
